package tdwp_ftw.biomesop.worldgen;

import java.util.Random;

import net.minecraft.block.Block;
import net.minecraft.world.World;
import net.minecraft.world.gen.feature.WorldGenerator;
import tdwp_ftw.biomesop.declarations.BOPBlocks;

public class WorldGenAppleTree1 extends WorldGenerator
{
    public boolean generate(World var1, Random var2, int var3, int var4, int var5)
    {
        while (var1.isAirBlock(var3 + 12, var4, var5 + 16) && var4 > 2)
        {
            --var4;
        }

        int var6 = var1.getBlockId(var3 + 12, var4, var5 + 16);

        if (var6 != Block.grass.blockID)
        {
            return false;
        }
        else
        {
            for (int var7 = -2; var7 <= 2; ++var7)
            {
                for (int var8 = -2; var8 <= 2; ++var8)
                {
                    if (var1.isAirBlock(var3 + var7 + 12, var4 - 1, var5 + var8 + 16) && var1.isAirBlock(var3 + var7 + 12, var4 - 2, var5 + var8 + 16))
                    {
                        return false;
                    }
                }
            }

			var1.setBlock(var3 + 0, var4 + 11, var5 + 9, BOPBlocks.appleLeaves.blockID, 4, 2);
			var1.setBlock(var3 + 0, var4 + 12, var5 + 9, BOPBlocks.appleLeavesFruitless.blockID, 4, 2);
			var1.setBlock(var3 + 1, var4 + 10, var5 + 8, BOPBlocks.appleLeavesFruitless.blockID, 4, 2);
			var1.setBlock(var3 + 1, var4 + 11, var5 + 7, BOPBlocks.appleLeaves.blockID, 4, 2);
			var1.setBlock(var3 + 1, var4 + 12, var5 + 7, BOPBlocks.appleLeaves.blockID, 4, 2);
			var1.setBlock(var3 + 1, var4 + 13, var5 + 7, BOPBlocks.appleLeavesFruitless.blockID, 4, 2);
			var1.setBlock(var3 + 1, var4 + 14, var5 + 7, BOPBlocks.appleLeaves.blockID, 4, 2);
			var1.setBlock(var3 + 1, var4 + 15, var5 + 7, BOPBlocks.appleLeavesFruitless.blockID, 4, 2);
			var1.setBlock(var3 + 1, var4 + 16, var5 + 6, BOPBlocks.appleLeaves.blockID, 4, 2);
			var1.setBlock(var3 + 2, var4 + 4, var5 + 5, BOPBlocks.appleLeavesFruitless.blockID, 4, 2);
			var1.setBlock(var3 + 2, var4 + 5, var5 + 8, BOPBlocks.appleLeavesFruitless.blockID, 4, 2);
			var1.setBlock(var3 + 2, var4 + 6, var5 + 7, BOPBlocks.appleLeavesFruitless.blockID, 4, 2);
			var1.setBlock(var3 + 2, var4 + 11, var5 + 8, BOPBlocks.appleLeavesFruitless.blockID, 4, 2);
			var1.setBlock(var3 + 2, var4 + 12, var5 + 11, BOPBlocks.appleLeaves.blockID, 4, 2);
			var1.setBlock(var3 + 2, var4 + 12, var5 + 12, BOPBlocks.appleLeavesFruitless.blockID, 4, 2);
			var1.setBlock(var3 + 2, var4 + 13, var5 + 6, BOPBlocks.appleLeavesFruitless.blockID, 4, 2);
			var1.setBlock(var3 + 2, var4 + 13, var5 + 7, BOPBlocks.appleLeavesFruitless.blockID, 4, 2);
			var1.setBlock(var3 + 2, var4 + 13, var5 + 8, BOPBlocks.appleLeavesFruitless.blockID, 4, 2);
			var1.setBlock(var3 + 2, var4 + 14, var5 + 8, BOPBlocks.appleLeaves.blockID, 4, 2);
			var1.setBlock(var3 + 2, var4 + 14, var5 + 9, BOPBlocks.appleLeavesFruitless.blockID, 4, 2);
			var1.setBlock(var3 + 2, var4 + 15, var5 + 8, BOPBlocks.appleLeavesFruitless.blockID, 4, 2);
			var1.setBlock(var3 + 3, var4 + 4, var5 + 7, BOPBlocks.appleLeavesFruitless.blockID, 4, 2);
			var1.setBlock(var3 + 3, var4 + 5, var5 + 10, BOPBlocks.appleLeaves.blockID, 4, 2);
			var1.setBlock(var3 + 3, var4 + 6, var5 + 4, BOPBlocks.appleLeavesFruitless.blockID, 4, 2);
			var1.setBlock(var3 + 3, var4 + 8, var5 + 8, BOPBlocks.appleLeavesFruitless.blockID, 4, 2);
			var1.setBlock(var3 + 3, var4 + 9, var5 + 6, BOPBlocks.appleLeavesFruitless.blockID, 4, 2);
			var1.setBlock(var3 + 3, var4 + 10, var5 + 6, BOPBlocks.appleLeaves.blockID, 4, 2);
			var1.setBlock(var3 + 3, var4 + 10, var5 + 10, BOPBlocks.appleLeavesFruitless.blockID, 4, 2);
			var1.setBlock(var3 + 3, var4 + 11, var5 + 6, BOPBlocks.appleLeavesFruitless.blockID, 4, 2);
			var1.setBlock(var3 + 3, var4 + 11, var5 + 7, BOPBlocks.appleLeavesFruitless.blockID, 4, 2);
			var1.setBlock(var3 + 3, var4 + 11, var5 + 8, BOPBlocks.appleLeavesFruitless.blockID, 4, 2);
			var1.setBlock(var3 + 3, var4 + 11, var5 + 9, BOPBlocks.appleLeaves.blockID, 4, 2);
			var1.setBlock(var3 + 3, var4 + 11, var5 + 12, BOPBlocks.appleLeavesFruitless.blockID, 4, 2);
			var1.setBlock(var3 + 3, var4 + 12, var5 + 5, BOPBlocks.appleLeavesFruitless.blockID, 4, 2);
			var1.setBlock(var3 + 3, var4 + 12, var5 + 10, BOPBlocks.appleLeavesFruitless.blockID, 4, 2);
			var1.setBlock(var3 + 3, var4 + 12, var5 + 11, BOPBlocks.appleLeaves.blockID, 4, 2);
			var1.setBlock(var3 + 3, var4 + 13, var5 + 7, BOPBlocks.appleLeavesFruitless.blockID, 4, 2);
			var1.setBlock(var3 + 3, var4 + 13, var5 + 8, BOPBlocks.appleLeavesFruitless.blockID, 4, 2);
			var1.setBlock(var3 + 3, var4 + 14, var5 + 11, BOPBlocks.appleLeaves.blockID, 4, 2);
			var1.setBlock(var3 + 3, var4 + 14, var5 + 12, BOPBlocks.appleLeaves.blockID, 4, 2);
			var1.setBlock(var3 + 3, var4 + 14, var5 + 14, BOPBlocks.appleLeavesFruitless.blockID, 4, 2);
			var1.setBlock(var3 + 3, var4 + 18, var5 + 7, BOPBlocks.appleLeavesFruitless.blockID, 4, 2);
			var1.setBlock(var3 + 4, var4 + 4, var5 + 7, BOPBlocks.appleLeavesFruitless.blockID, 4, 2);
			var1.setBlock(var3 + 4, var4 + 6, var5 + 4, BOPBlocks.appleLeavesFruitless.blockID, 4, 2);
			var1.setBlock(var3 + 4, var4 + 7, var5 + 6, BOPBlocks.appleLeavesFruitless.blockID, 4, 2);
			var1.setBlock(var3 + 4, var4 + 7, var5 + 7, BOPBlocks.appleLeaves.blockID, 4, 2);
			var1.setBlock(var3 + 4, var4 + 8, var5 + 8, BOPBlocks.appleLeavesFruitless.blockID, 4, 2);
			var1.setBlock(var3 + 4, var4 + 9, var5 + 9, BOPBlocks.appleLeavesFruitless.blockID, 4, 2);
			var1.setBlock(var3 + 4, var4 + 11, var5 + 9, BOPBlocks.appleLeavesFruitless.blockID, 4, 2);
			var1.setBlock(var3 + 4, var4 + 11, var5 + 10, BOPBlocks.appleLeaves.blockID, 4, 2);
			var1.setBlock(var3 + 4, var4 + 13, var5 + 8, BOPBlocks.appleLeavesFruitless.blockID, 4, 2);
			var1.setBlock(var3 + 4, var4 + 13, var5 + 10, BOPBlocks.appleLeaves.blockID, 4, 2);
			var1.setBlock(var3 + 4, var4 + 13, var5 + 14, BOPBlocks.appleLeavesFruitless.blockID, 4, 2);
			var1.setBlock(var3 + 4, var4 + 14, var5 + 7, Block.wood.blockID, 12, 2);
			var1.setBlock(var3 + 4, var4 + 14, var5 + 8, Block.wood.blockID, 12, 2);
			var1.setBlock(var3 + 4, var4 + 14, var5 + 10, BOPBlocks.appleLeavesFruitless.blockID, 4, 2);
			var1.setBlock(var3 + 4, var4 + 14, var5 + 12, BOPBlocks.appleLeaves.blockID, 4, 2);
			var1.setBlock(var3 + 4, var4 + 15, var5 + 5, BOPBlocks.appleLeavesFruitless.blockID, 4, 2);
			var1.setBlock(var3 + 4, var4 + 15, var5 + 7, Block.wood.blockID, 12, 2);
			var1.setBlock(var3 + 4, var4 + 16, var5 + 6, BOPBlocks.appleLeavesFruitless.blockID, 4, 2);
			var1.setBlock(var3 + 4, var4 + 16, var5 + 7, BOPBlocks.appleLeavesFruitless.blockID, 4, 2);
			var1.setBlock(var3 + 4, var4 + 16, var5 + 9, BOPBlocks.appleLeavesFruitless.blockID, 4, 2);
			var1.setBlock(var3 + 4, var4 + 18, var5 + 7, BOPBlocks.appleLeaves.blockID, 4, 2);
			var1.setBlock(var3 + 5, var4 + 4, var5 + 8, BOPBlocks.appleLeavesFruitless.blockID, 4, 2);
			var1.setBlock(var3 + 5, var4 + 5, var5 + 7, BOPBlocks.appleLeavesFruitless.blockID, 4, 2);
			var1.setBlock(var3 + 5, var4 + 5, var5 + 10, BOPBlocks.appleLeavesFruitless.blockID, 4, 2);
			var1.setBlock(var3 + 5, var4 + 5, var5 + 11, BOPBlocks.appleLeavesFruitless.blockID, 4, 2);
			var1.setBlock(var3 + 5, var4 + 5, var5 + 13, BOPBlocks.appleLeavesFruitless.blockID, 4, 2);
			var1.setBlock(var3 + 5, var4 + 5, var5 + 20, BOPBlocks.appleLeavesFruitless.blockID, 4, 2);
			var1.setBlock(var3 + 5, var4 + 6, var5 + 9, BOPBlocks.appleLeavesFruitless.blockID, 4, 2);
			var1.setBlock(var3 + 5, var4 + 6, var5 + 20, BOPBlocks.appleLeaves.blockID, 4, 2);
			var1.setBlock(var3 + 5, var4 + 7, var5 + 10, BOPBlocks.appleLeavesFruitless.blockID, 4, 2);
			var1.setBlock(var3 + 5, var4 + 8, var5 + 23, BOPBlocks.appleLeavesFruitless.blockID, 4, 2);
			var1.setBlock(var3 + 5, var4 + 9, var5 + 25, BOPBlocks.appleLeaves.blockID, 4, 2);
			var1.setBlock(var3 + 5, var4 + 10, var5 + 11, BOPBlocks.appleLeavesFruitless.blockID, 4, 2);
			var1.setBlock(var3 + 5, var4 + 10, var5 + 12, BOPBlocks.appleLeavesFruitless.blockID, 4, 2);
			var1.setBlock(var3 + 5, var4 + 11, var5 + 7, BOPBlocks.appleLeavesFruitless.blockID, 4, 2);
			var1.setBlock(var3 + 5, var4 + 11, var5 + 8, BOPBlocks.appleLeavesFruitless.blockID, 4, 2);
			var1.setBlock(var3 + 5, var4 + 11, var5 + 10, BOPBlocks.appleLeaves.blockID, 4, 2);
			var1.setBlock(var3 + 5, var4 + 11, var5 + 13, BOPBlocks.appleLeavesFruitless.blockID, 4, 2);
			var1.setBlock(var3 + 5, var4 + 12, var5 + 8, Block.wood.blockID, 12, 2);
			var1.setBlock(var3 + 5, var4 + 12, var5 + 10, BOPBlocks.appleLeavesFruitless.blockID, 4, 2);
			var1.setBlock(var3 + 5, var4 + 12, var5 + 20, BOPBlocks.appleLeavesFruitless.blockID, 4, 2);
			var1.setBlock(var3 + 5, var4 + 12, var5 + 22, BOPBlocks.appleLeavesFruitless.blockID, 4, 2);
			var1.setBlock(var3 + 5, var4 + 13, var5 + 2, BOPBlocks.appleLeavesFruitless.blockID, 4, 2);
			var1.setBlock(var3 + 5, var4 + 13, var5 + 8, Block.wood.blockID, 12, 2);
			var1.setBlock(var3 + 5, var4 + 13, var5 + 9, BOPBlocks.appleLeavesFruitless.blockID, 4, 2);
			var1.setBlock(var3 + 5, var4 + 13, var5 + 20, BOPBlocks.appleLeavesFruitless.blockID, 4, 2);
			var1.setBlock(var3 + 5, var4 + 14, var5 + 3, BOPBlocks.appleLeavesFruitless.blockID, 4, 2);
			var1.setBlock(var3 + 5, var4 + 14, var5 + 4, BOPBlocks.appleLeaves.blockID, 4, 2);
			var1.setBlock(var3 + 5, var4 + 14, var5 + 12, BOPBlocks.appleLeaves.blockID, 4, 2);
			var1.setBlock(var3 + 5, var4 + 14, var5 + 13, BOPBlocks.appleLeavesFruitless.blockID, 4, 2);
			var1.setBlock(var3 + 5, var4 + 14, var5 + 20, BOPBlocks.appleLeavesFruitless.blockID, 4, 2);
			var1.setBlock(var3 + 5, var4 + 15, var5 + 4, BOPBlocks.appleLeaves.blockID, 4, 2);
			var1.setBlock(var3 + 5, var4 + 15, var5 + 13, BOPBlocks.appleLeavesFruitless.blockID, 4, 2);
			var1.setBlock(var3 + 5, var4 + 15, var5 + 17, BOPBlocks.appleLeavesFruitless.blockID, 12, 2);
			var1.setBlock(var3 + 5, var4 + 17, var5 + 5, BOPBlocks.appleLeavesFruitless.blockID, 4, 2);
			var1.setBlock(var3 + 5, var4 + 17, var5 + 7, BOPBlocks.appleLeavesFruitless.blockID, 4, 2);
			var1.setBlock(var3 + 5, var4 + 17, var5 + 8, BOPBlocks.appleLeavesFruitless.blockID, 4, 2);
			var1.setBlock(var3 + 5, var4 + 17, var5 + 10, BOPBlocks.appleLeavesFruitless.blockID, 4, 2);
			var1.setBlock(var3 + 5, var4 + 17, var5 + 12, BOPBlocks.appleLeavesFruitless.blockID, 4, 2);
			var1.setBlock(var3 + 5, var4 + 18, var5 + 8, BOPBlocks.appleLeavesFruitless.blockID, 4, 2);
			var1.setBlock(var3 + 5, var4 + 19, var5 + 10, BOPBlocks.appleLeaves.blockID, 4, 2);
			var1.setBlock(var3 + 6, var4 + 3, var5 + 11, BOPBlocks.appleLeavesFruitless.blockID, 4, 2);
			var1.setBlock(var3 + 6, var4 + 5, var5 + 7, BOPBlocks.appleLeavesFruitless.blockID, 4, 2);
			var1.setBlock(var3 + 6, var4 + 5, var5 + 10, BOPBlocks.appleLeaves.blockID, 4, 2);
			var1.setBlock(var3 + 6, var4 + 5, var5 + 11, BOPBlocks.appleLeaves.blockID, 4, 2);
			var1.setBlock(var3 + 6, var4 + 6, var5 + 10, BOPBlocks.appleLeavesFruitless.blockID, 4, 2);
			var1.setBlock(var3 + 6, var4 + 7, var5 + 5, BOPBlocks.appleLeaves.blockID, 4, 2);
			var1.setBlock(var3 + 6, var4 + 7, var5 + 6, BOPBlocks.appleLeavesFruitless.blockID, 4, 2);
			var1.setBlock(var3 + 6, var4 + 7, var5 + 7, BOPBlocks.appleLeavesFruitless.blockID, 4, 2);
			var1.setBlock(var3 + 6, var4 + 7, var5 + 19, BOPBlocks.appleLeavesFruitless.blockID, 4, 2);
			var1.setBlock(var3 + 6, var4 + 8, var5 + 17, BOPBlocks.appleLeaves.blockID, 4, 2);
			var1.setBlock(var3 + 6, var4 + 8, var5 + 25, BOPBlocks.appleLeavesFruitless.blockID, 4, 2);
			var1.setBlock(var3 + 6, var4 + 9, var5 + 12, BOPBlocks.appleLeavesFruitless.blockID, 4, 2);
			var1.setBlock(var3 + 6, var4 + 9, var5 + 20, BOPBlocks.appleLeaves.blockID, 4, 2);
			var1.setBlock(var3 + 6, var4 + 9, var5 + 23, BOPBlocks.appleLeaves.blockID, 4, 2);
			var1.setBlock(var3 + 6, var4 + 10, var5 + 10, BOPBlocks.appleLeavesFruitless.blockID, 4, 2);
			var1.setBlock(var3 + 6, var4 + 10, var5 + 22, BOPBlocks.appleLeavesFruitless.blockID, 4, 2);
			var1.setBlock(var3 + 6, var4 + 10, var5 + 23, BOPBlocks.appleLeavesFruitless.blockID, 4, 2);
			var1.setBlock(var3 + 6, var4 + 11, var5 + 8, Block.wood.blockID, 12, 2);
			var1.setBlock(var3 + 6, var4 + 11, var5 + 9, Block.wood.blockID, 12, 2);
			var1.setBlock(var3 + 6, var4 + 11, var5 + 18, BOPBlocks.appleLeavesFruitless.blockID, 4, 2);
			var1.setBlock(var3 + 6, var4 + 12, var5 + 8, BOPBlocks.appleLeavesFruitless.blockID, 4, 2);
			var1.setBlock(var3 + 6, var4 + 12, var5 + 22, BOPBlocks.appleLeaves.blockID, 4, 2);
			var1.setBlock(var3 + 6, var4 + 13, var5 + 1, BOPBlocks.appleLeavesFruitless.blockID, 4, 2);
			var1.setBlock(var3 + 6, var4 + 13, var5 + 2, BOPBlocks.appleLeavesFruitless.blockID, 4, 2);
			var1.setBlock(var3 + 6, var4 + 13, var5 + 3, BOPBlocks.appleLeavesFruitless.blockID, 4, 2);
			var1.setBlock(var3 + 6, var4 + 13, var5 + 19, BOPBlocks.appleLeaves.blockID, 4, 2);
			var1.setBlock(var3 + 6, var4 + 14, var5 + 7, BOPBlocks.appleLeavesFruitless.blockID, 4, 2);
			var1.setBlock(var3 + 6, var4 + 14, var5 + 14, BOPBlocks.appleLeavesFruitless.blockID, 4, 2);
			var1.setBlock(var3 + 6, var4 + 14, var5 + 20, BOPBlocks.appleLeaves.blockID, 4, 2);
			var1.setBlock(var3 + 6, var4 + 14, var5 + 21, BOPBlocks.appleLeaves.blockID, 4, 2);
			var1.setBlock(var3 + 6, var4 + 15, var5 + 5, BOPBlocks.appleLeavesFruitless.blockID, 4, 2);
			var1.setBlock(var3 + 6, var4 + 15, var5 + 7, BOPBlocks.appleLeavesFruitless.blockID, 4, 2);
			var1.setBlock(var3 + 6, var4 + 15, var5 + 11, BOPBlocks.appleLeavesFruitless.blockID, 4, 2);
			var1.setBlock(var3 + 6, var4 + 15, var5 + 15, BOPBlocks.appleLeavesFruitless.blockID, 12, 2);
			var1.setBlock(var3 + 6, var4 + 15, var5 + 20, BOPBlocks.appleLeavesFruitless.blockID, 4, 2);
			var1.setBlock(var3 + 6, var4 + 16, var5 + 5, BOPBlocks.appleLeavesFruitless.blockID, 4, 2);
			var1.setBlock(var3 + 6, var4 + 16, var5 + 7, BOPBlocks.appleLeaves.blockID, 4, 2);
			var1.setBlock(var3 + 6, var4 + 16, var5 + 9, BOPBlocks.appleLeavesFruitless.blockID, 4, 2);
			var1.setBlock(var3 + 6, var4 + 16, var5 + 16, BOPBlocks.appleLeavesFruitless.blockID, 12, 2);
			var1.setBlock(var3 + 6, var4 + 16, var5 + 17, BOPBlocks.appleLeavesFruitless.blockID, 12, 2);
			var1.setBlock(var3 + 6, var4 + 16, var5 + 18, BOPBlocks.appleLeavesFruitless.blockID, 4, 2);
			var1.setBlock(var3 + 6, var4 + 17, var5 + 7, BOPBlocks.appleLeavesFruitless.blockID, 4, 2);
			var1.setBlock(var3 + 6, var4 + 17, var5 + 8, BOPBlocks.appleLeavesFruitless.blockID, 4, 2);
			var1.setBlock(var3 + 6, var4 + 17, var5 + 9, BOPBlocks.appleLeavesFruitless.blockID, 4, 2);
			var1.setBlock(var3 + 6, var4 + 17, var5 + 10, BOPBlocks.appleLeavesFruitless.blockID, 4, 2);
			var1.setBlock(var3 + 6, var4 + 17, var5 + 12, BOPBlocks.appleLeavesFruitless.blockID, 4, 2);
			var1.setBlock(var3 + 6, var4 + 17, var5 + 13, BOPBlocks.appleLeaves.blockID, 4, 2);
			var1.setBlock(var3 + 6, var4 + 17, var5 + 15, BOPBlocks.appleLeavesFruitless.blockID, 4, 2);
			var1.setBlock(var3 + 6, var4 + 18, var5 + 7, BOPBlocks.appleLeavesFruitless.blockID, 4, 2);
			var1.setBlock(var3 + 6, var4 + 18, var5 + 9, BOPBlocks.appleLeaves.blockID, 4, 2);
			var1.setBlock(var3 + 6, var4 + 19, var5 + 8, BOPBlocks.appleLeavesFruitless.blockID, 4, 2);
			var1.setBlock(var3 + 6, var4 + 19, var5 + 9, BOPBlocks.appleLeaves.blockID, 4, 2);
			var1.setBlock(var3 + 6, var4 + 19, var5 + 10, BOPBlocks.appleLeaves.blockID, 4, 2);
			var1.setBlock(var3 + 6, var4 + 20, var5 + 8, BOPBlocks.appleLeavesFruitless.blockID, 4, 2);
			var1.setBlock(var3 + 6, var4 + 20, var5 + 9, BOPBlocks.appleLeavesFruitless.blockID, 4, 2);
			var1.setBlock(var3 + 7, var4 + 4, var5 + 8, BOPBlocks.appleLeavesFruitless.blockID, 4, 2);
			var1.setBlock(var3 + 7, var4 + 4, var5 + 9, BOPBlocks.appleLeavesFruitless.blockID, 4, 2);
			var1.setBlock(var3 + 7, var4 + 4, var5 + 11, BOPBlocks.appleLeavesFruitless.blockID, 4, 2);
			var1.setBlock(var3 + 7, var4 + 4, var5 + 13, BOPBlocks.appleLeavesFruitless.blockID, 4, 2);
			var1.setBlock(var3 + 7, var4 + 4, var5 + 18, BOPBlocks.appleLeavesFruitless.blockID, 4, 2);
			var1.setBlock(var3 + 7, var4 + 4, var5 + 21, BOPBlocks.appleLeavesFruitless.blockID, 4, 2);
			var1.setBlock(var3 + 7, var4 + 5, var5 + 6, BOPBlocks.appleLeavesFruitless.blockID, 4, 2);
			var1.setBlock(var3 + 7, var4 + 5, var5 + 21, BOPBlocks.appleLeavesFruitless.blockID, 4, 2);
			var1.setBlock(var3 + 7, var4 + 6, var5 + 16, BOPBlocks.appleLeaves.blockID, 4, 2);
			var1.setBlock(var3 + 7, var4 + 6, var5 + 17, BOPBlocks.appleLeaves.blockID, 4, 2);
			var1.setBlock(var3 + 7, var4 + 6, var5 + 19, BOPBlocks.appleLeavesFruitless.blockID, 4, 2);
			var1.setBlock(var3 + 7, var4 + 6, var5 + 22, BOPBlocks.appleLeaves.blockID, 4, 2);
			var1.setBlock(var3 + 7, var4 + 6, var5 + 25, BOPBlocks.appleLeavesFruitless.blockID, 4, 2);
			var1.setBlock(var3 + 7, var4 + 7, var5 + 22, BOPBlocks.appleLeavesFruitless.blockID, 4, 2);
			var1.setBlock(var3 + 7, var4 + 8, var5 + 18, BOPBlocks.appleLeaves.blockID, 4, 2);
			var1.setBlock(var3 + 7, var4 + 8, var5 + 19, BOPBlocks.appleLeaves.blockID, 4, 2);
			var1.setBlock(var3 + 7, var4 + 8, var5 + 20, BOPBlocks.appleLeavesFruitless.blockID, 4, 2);
			var1.setBlock(var3 + 7, var4 + 8, var5 + 21, BOPBlocks.appleLeavesFruitless.blockID, 4, 2);
			var1.setBlock(var3 + 7, var4 + 8, var5 + 23, BOPBlocks.appleLeavesFruitless.blockID, 4, 2);
			var1.setBlock(var3 + 7, var4 + 8, var5 + 26, BOPBlocks.appleLeavesFruitless.blockID, 4, 2);
			var1.setBlock(var3 + 7, var4 + 9, var5 + 10, Block.wood.blockID, 12, 2);
			var1.setBlock(var3 + 7, var4 + 9, var5 + 19, BOPBlocks.appleLeavesFruitless.blockID, 4, 2);
			var1.setBlock(var3 + 7, var4 + 9, var5 + 20, BOPBlocks.appleLeavesFruitless.blockID, 4, 2);
			var1.setBlock(var3 + 7, var4 + 9, var5 + 22, BOPBlocks.appleLeaves.blockID, 4, 2);
			var1.setBlock(var3 + 7, var4 + 9, var5 + 25, BOPBlocks.appleLeavesFruitless.blockID, 4, 2);
			var1.setBlock(var3 + 7, var4 + 9, var5 + 27, BOPBlocks.appleLeaves.blockID, 4, 2);
			var1.setBlock(var3 + 7, var4 + 10, var5 + 8, BOPBlocks.appleLeavesFruitless.blockID, 4, 2);
			var1.setBlock(var3 + 7, var4 + 10, var5 + 9, Block.wood.blockID, 12, 2);
			var1.setBlock(var3 + 7, var4 + 11, var5 + 8, Block.wood.blockID, 12, 2);
			var1.setBlock(var3 + 7, var4 + 11, var5 + 10, BOPBlocks.appleLeavesFruitless.blockID, 4, 2);
			var1.setBlock(var3 + 7, var4 + 11, var5 + 20, BOPBlocks.appleLeavesFruitless.blockID, 4, 2);
			var1.setBlock(var3 + 7, var4 + 11, var5 + 26, BOPBlocks.appleLeavesFruitless.blockID, 4, 2);
			var1.setBlock(var3 + 7, var4 + 12, var5 + 1, BOPBlocks.appleLeaves.blockID, 4, 2);
			var1.setBlock(var3 + 7, var4 + 12, var5 + 4, BOPBlocks.appleLeavesFruitless.blockID, 4, 2);
			var1.setBlock(var3 + 7, var4 + 12, var5 + 5, BOPBlocks.appleLeavesFruitless.blockID, 4, 2);
			var1.setBlock(var3 + 7, var4 + 12, var5 + 7, Block.wood.blockID, 12, 2);
			var1.setBlock(var3 + 7, var4 + 12, var5 + 11, BOPBlocks.appleLeavesFruitless.blockID, 4, 2);
			var1.setBlock(var3 + 7, var4 + 12, var5 + 12, BOPBlocks.appleLeavesFruitless.blockID, 4, 2);
			var1.setBlock(var3 + 7, var4 + 12, var5 + 19, BOPBlocks.appleLeaves.blockID, 4, 2);
			var1.setBlock(var3 + 7, var4 + 12, var5 + 21, BOPBlocks.appleLeavesFruitless.blockID, 4, 2);
			var1.setBlock(var3 + 7, var4 + 12, var5 + 24, BOPBlocks.appleLeavesFruitless.blockID, 4, 2);
			var1.setBlock(var3 + 7, var4 + 13, var5 + 3, BOPBlocks.appleLeavesFruitless.blockID, 4, 2);
			var1.setBlock(var3 + 7, var4 + 13, var5 + 6, BOPBlocks.appleLeavesFruitless.blockID, 4, 2);
			var1.setBlock(var3 + 7, var4 + 13, var5 + 7, Block.wood.blockID, 12, 2);
			var1.setBlock(var3 + 7, var4 + 13, var5 + 15, BOPBlocks.appleLeavesFruitless.blockID, 4, 2);
			var1.setBlock(var3 + 7, var4 + 13, var5 + 17, BOPBlocks.appleLeavesFruitless.blockID, 4, 2);
			var1.setBlock(var3 + 7, var4 + 13, var5 + 22, BOPBlocks.appleLeavesFruitless.blockID, 4, 2);
			var1.setBlock(var3 + 7, var4 + 14, var5 + 6, BOPBlocks.appleLeavesFruitless.blockID, 4, 2);
			var1.setBlock(var3 + 7, var4 + 14, var5 + 8, BOPBlocks.appleLeavesFruitless.blockID, 4, 2);
			var1.setBlock(var3 + 7, var4 + 14, var5 + 14, BOPBlocks.appleLeaves.blockID, 4, 2);
			var1.setBlock(var3 + 7, var4 + 14, var5 + 18, BOPBlocks.appleLeaves.blockID, 4, 2);
			var1.setBlock(var3 + 7, var4 + 14, var5 + 21, BOPBlocks.appleLeavesFruitless.blockID, 4, 2);
			var1.setBlock(var3 + 7, var4 + 15, var5 + 6, BOPBlocks.appleLeavesFruitless.blockID, 4, 2);
			var1.setBlock(var3 + 7, var4 + 15, var5 + 12, BOPBlocks.appleLeavesFruitless.blockID, 4, 2);
			var1.setBlock(var3 + 7, var4 + 15, var5 + 17, BOPBlocks.appleLeavesFruitless.blockID, 12, 2);
			var1.setBlock(var3 + 7, var4 + 16, var5 + 8, BOPBlocks.appleLeavesFruitless.blockID, 4, 2);
			var1.setBlock(var3 + 7, var4 + 16, var5 + 10, BOPBlocks.appleLeavesFruitless.blockID, 4, 2);
			var1.setBlock(var3 + 7, var4 + 17, var5 + 7, BOPBlocks.appleLeaves.blockID, 4, 2);
			var1.setBlock(var3 + 7, var4 + 18, var5 + 8, BOPBlocks.appleLeavesFruitless.blockID, 4, 2);
			var1.setBlock(var3 + 7, var4 + 18, var5 + 11, BOPBlocks.appleLeavesFruitless.blockID, 4, 2);
			var1.setBlock(var3 + 8, var4 + 0, var5 + 9, Block.wood.blockID, 12, 2);
			var1.setBlock(var3 + 8, var4 + 0, var5 + 10, Block.wood.blockID, 12, 2);
			var1.setBlock(var3 + 8, var4 + 0, var5 + 13, Block.wood.blockID, 12, 2);
			var1.setBlock(var3 + 8, var4 + 3, var5 + 12, BOPBlocks.appleLeavesFruitless.blockID, 4, 2);
			var1.setBlock(var3 + 8, var4 + 3, var5 + 18, BOPBlocks.appleLeavesFruitless.blockID, 4, 2);
			var1.setBlock(var3 + 8, var4 + 4, var5 + 13, Block.wood.blockID, 12, 2);
			var1.setBlock(var3 + 8, var4 + 4, var5 + 17, BOPBlocks.appleLeaves.blockID, 4, 2);
			var1.setBlock(var3 + 8, var4 + 4, var5 + 19, BOPBlocks.appleLeaves.blockID, 4, 2);
			var1.setBlock(var3 + 8, var4 + 4, var5 + 20, BOPBlocks.appleLeavesFruitless.blockID, 4, 2);
			var1.setBlock(var3 + 8, var4 + 5, var5 + 10, BOPBlocks.appleLeavesFruitless.blockID, 4, 2);
			var1.setBlock(var3 + 8, var4 + 5, var5 + 11, Block.wood.blockID, 12, 2);
			var1.setBlock(var3 + 8, var4 + 5, var5 + 12, Block.wood.blockID, 12, 2);
			var1.setBlock(var3 + 8, var4 + 5, var5 + 17, BOPBlocks.appleLeavesFruitless.blockID, 4, 2);
			var1.setBlock(var3 + 8, var4 + 5, var5 + 18, BOPBlocks.appleLeaves.blockID, 4, 2);
			var1.setBlock(var3 + 8, var4 + 5, var5 + 20, BOPBlocks.appleLeavesFruitless.blockID, 4, 2);
			var1.setBlock(var3 + 8, var4 + 6, var5 + 10, Block.wood.blockID, 12, 2);
			var1.setBlock(var3 + 8, var4 + 6, var5 + 11, Block.wood.blockID, 12, 2);
			var1.setBlock(var3 + 8, var4 + 6, var5 + 19, BOPBlocks.appleLeavesFruitless.blockID, 4, 2);
			var1.setBlock(var3 + 8, var4 + 6, var5 + 21, BOPBlocks.appleLeavesFruitless.blockID, 4, 2);
			var1.setBlock(var3 + 8, var4 + 7, var5 + 10, Block.wood.blockID, 12, 2);
			var1.setBlock(var3 + 8, var4 + 7, var5 + 11, Block.wood.blockID, 12, 2);
			var1.setBlock(var3 + 8, var4 + 7, var5 + 23, BOPBlocks.appleLeavesFruitless.blockID, 4, 2);
			var1.setBlock(var3 + 8, var4 + 8, var5 + 10, Block.wood.blockID, 12, 2);
			var1.setBlock(var3 + 8, var4 + 8, var5 + 11, Block.wood.blockID, 12, 2);
			var1.setBlock(var3 + 8, var4 + 8, var5 + 18, BOPBlocks.appleLeavesFruitless.blockID, 4, 2);
			var1.setBlock(var3 + 8, var4 + 8, var5 + 19, BOPBlocks.appleLeaves.blockID, 4, 2);
			var1.setBlock(var3 + 8, var4 + 8, var5 + 23, BOPBlocks.appleLeavesFruitless.blockID, 4, 2);
			var1.setBlock(var3 + 8, var4 + 9, var5 + 9, Block.wood.blockID, 12, 2);
			var1.setBlock(var3 + 8, var4 + 9, var5 + 10, Block.wood.blockID, 12, 2);
			var1.setBlock(var3 + 8, var4 + 9, var5 + 11, Block.wood.blockID, 12, 2);
			var1.setBlock(var3 + 8, var4 + 9, var5 + 20, BOPBlocks.appleLeavesFruitless.blockID, 4, 2);
			var1.setBlock(var3 + 8, var4 + 9, var5 + 24, BOPBlocks.appleLeavesFruitless.blockID, 4, 2);
			var1.setBlock(var3 + 8, var4 + 9, var5 + 25, BOPBlocks.appleLeavesFruitless.blockID, 4, 2);
			var1.setBlock(var3 + 8, var4 + 10, var5 + 1, BOPBlocks.appleLeaves.blockID, 4, 2);
			var1.setBlock(var3 + 8, var4 + 10, var5 + 2, BOPBlocks.appleLeavesFruitless.blockID, 4, 2);
			var1.setBlock(var3 + 8, var4 + 10, var5 + 3, BOPBlocks.appleLeavesFruitless.blockID, 4, 2);
			var1.setBlock(var3 + 8, var4 + 10, var5 + 6, BOPBlocks.appleLeavesFruitless.blockID, 4, 2);
			var1.setBlock(var3 + 8, var4 + 10, var5 + 7, BOPBlocks.appleLeaves.blockID, 4, 2);
			var1.setBlock(var3 + 8, var4 + 10, var5 + 8, BOPBlocks.appleLeavesFruitless.blockID, 4, 2);
			var1.setBlock(var3 + 8, var4 + 10, var5 + 9, Block.wood.blockID, 12, 2);
			var1.setBlock(var3 + 8, var4 + 10, var5 + 21, BOPBlocks.appleLeavesFruitless.blockID, 4, 2);
			var1.setBlock(var3 + 8, var4 + 10, var5 + 23, BOPBlocks.appleLeavesFruitless.blockID, 4, 2);
			var1.setBlock(var3 + 8, var4 + 11, var5 + 1, BOPBlocks.appleLeaves.blockID, 4, 2);
			var1.setBlock(var3 + 8, var4 + 11, var5 + 2, BOPBlocks.appleLeavesFruitless.blockID, 4, 2);
			var1.setBlock(var3 + 8, var4 + 11, var5 + 4, BOPBlocks.appleLeavesFruitless.blockID, 4, 2);
			var1.setBlock(var3 + 8, var4 + 11, var5 + 12, BOPBlocks.appleLeavesFruitless.blockID, 4, 2);
			var1.setBlock(var3 + 8, var4 + 11, var5 + 20, BOPBlocks.appleLeaves.blockID, 4, 2);
			var1.setBlock(var3 + 8, var4 + 12, var5 + 2, BOPBlocks.appleLeavesFruitless.blockID, 4, 2);
			var1.setBlock(var3 + 8, var4 + 12, var5 + 3, BOPBlocks.appleLeavesFruitless.blockID, 4, 2);
			var1.setBlock(var3 + 8, var4 + 12, var5 + 7, BOPBlocks.appleLeavesFruitless.blockID, 4, 2);
			var1.setBlock(var3 + 8, var4 + 12, var5 + 8, BOPBlocks.appleLeavesFruitless.blockID, 4, 2);
			var1.setBlock(var3 + 8, var4 + 12, var5 + 11, BOPBlocks.appleLeaves.blockID, 4, 2);
			var1.setBlock(var3 + 8, var4 + 12, var5 + 17, BOPBlocks.appleLeaves.blockID, 4, 2);
			var1.setBlock(var3 + 8, var4 + 12, var5 + 19, BOPBlocks.appleLeavesFruitless.blockID, 4, 2);
			var1.setBlock(var3 + 8, var4 + 12, var5 + 20, BOPBlocks.appleLeavesFruitless.blockID, 4, 2);
			var1.setBlock(var3 + 8, var4 + 13, var5 + 1, BOPBlocks.appleLeaves.blockID, 4, 2);
			var1.setBlock(var3 + 8, var4 + 13, var5 + 2, BOPBlocks.appleLeavesFruitless.blockID, 4, 2);
			var1.setBlock(var3 + 8, var4 + 13, var5 + 4, BOPBlocks.appleLeavesFruitless.blockID, 4, 2);
			var1.setBlock(var3 + 8, var4 + 13, var5 + 6, BOPBlocks.appleLeavesFruitless.blockID, 4, 2);
			var1.setBlock(var3 + 8, var4 + 13, var5 + 8, BOPBlocks.appleLeavesFruitless.blockID, 4, 2);
			var1.setBlock(var3 + 8, var4 + 13, var5 + 17, BOPBlocks.appleLeavesFruitless.blockID, 4, 2);
			var1.setBlock(var3 + 8, var4 + 13, var5 + 18, BOPBlocks.appleLeavesFruitless.blockID, 4, 2);
			var1.setBlock(var3 + 8, var4 + 13, var5 + 22, BOPBlocks.appleLeaves.blockID, 4, 2);
			var1.setBlock(var3 + 8, var4 + 14, var5 + 2, BOPBlocks.appleLeavesFruitless.blockID, 4, 2);
			var1.setBlock(var3 + 8, var4 + 14, var5 + 6, Block.wood.blockID, 12, 2);
			var1.setBlock(var3 + 8, var4 + 14, var5 + 8, BOPBlocks.appleLeavesFruitless.blockID, 4, 2);
			var1.setBlock(var3 + 8, var4 + 14, var5 + 14, BOPBlocks.appleLeavesFruitless.blockID, 4, 2);
			var1.setBlock(var3 + 8, var4 + 14, var5 + 17, BOPBlocks.appleLeavesFruitless.blockID, 12, 2);
			var1.setBlock(var3 + 8, var4 + 14, var5 + 21, BOPBlocks.appleLeavesFruitless.blockID, 4, 2);
			var1.setBlock(var3 + 8, var4 + 14, var5 + 22, BOPBlocks.appleLeavesFruitless.blockID, 4, 2);
			var1.setBlock(var3 + 8, var4 + 14, var5 + 23, BOPBlocks.appleLeavesFruitless.blockID, 4, 2);
			var1.setBlock(var3 + 8, var4 + 15, var5 + 0, BOPBlocks.appleLeavesFruitless.blockID, 4, 2);
			var1.setBlock(var3 + 8, var4 + 15, var5 + 3, BOPBlocks.appleLeavesFruitless.blockID, 4, 2);
			var1.setBlock(var3 + 8, var4 + 15, var5 + 6, Block.wood.blockID, 12, 2);
			var1.setBlock(var3 + 8, var4 + 15, var5 + 11, BOPBlocks.appleLeavesFruitless.blockID, 4, 2);
			var1.setBlock(var3 + 8, var4 + 15, var5 + 14, BOPBlocks.appleLeavesFruitless.blockID, 4, 2);
			var1.setBlock(var3 + 8, var4 + 15, var5 + 15, BOPBlocks.appleLeavesFruitless.blockID, 12, 2);
			var1.setBlock(var3 + 8, var4 + 15, var5 + 20, BOPBlocks.appleLeavesFruitless.blockID, 4, 2);
			var1.setBlock(var3 + 8, var4 + 16, var5 + 8, BOPBlocks.appleLeavesFruitless.blockID, 4, 2);
			var1.setBlock(var3 + 8, var4 + 16, var5 + 17, BOPBlocks.appleLeavesFruitless.blockID, 12, 2);
			var1.setBlock(var3 + 8, var4 + 17, var5 + 5, BOPBlocks.appleLeaves.blockID, 4, 2);
			var1.setBlock(var3 + 8, var4 + 17, var5 + 15, BOPBlocks.appleLeaves.blockID, 4, 2);
			var1.setBlock(var3 + 8, var4 + 17, var5 + 23, BOPBlocks.appleLeaves.blockID, 4, 2);
			var1.setBlock(var3 + 8, var4 + 18, var5 + 4, BOPBlocks.appleLeavesFruitless.blockID, 4, 2);
			var1.setBlock(var3 + 8, var4 + 18, var5 + 6, BOPBlocks.appleLeavesFruitless.blockID, 4, 2);
			var1.setBlock(var3 + 8, var4 + 18, var5 + 8, BOPBlocks.appleLeavesFruitless.blockID, 4, 2);
			var1.setBlock(var3 + 8, var4 + 18, var5 + 17, BOPBlocks.appleLeavesFruitless.blockID, 4, 2);
			var1.setBlock(var3 + 8, var4 + 18, var5 + 24, BOPBlocks.appleLeaves.blockID, 4, 2);
			var1.setBlock(var3 + 8, var4 + 19, var5 + 12, BOPBlocks.appleLeavesFruitless.blockID, 4, 2);
			var1.setBlock(var3 + 8, var4 + 20, var5 + 6, BOPBlocks.appleLeavesFruitless.blockID, 4, 2);
			var1.setBlock(var3 + 8, var4 + 20, var5 + 8, BOPBlocks.appleLeavesFruitless.blockID, 4, 2);
			var1.setBlock(var3 + 8, var4 + 21, var5 + 5, BOPBlocks.appleLeavesFruitless.blockID, 4, 2);
			var1.setBlock(var3 + 9, var4 + 0, var5 + 11, Block.wood.blockID, 12, 2);
			var1.setBlock(var3 + 9, var4 + 0, var5 + 12, Block.wood.blockID, 12, 2);
			var1.setBlock(var3 + 9, var4 + 0, var5 + 13, Block.wood.blockID, 12, 2);
			var1.setBlock(var3 + 9, var4 + 0, var5 + 14, Block.wood.blockID, 12, 2);
			var1.setBlock(var3 + 9, var4 + 1, var5 + 12, Block.wood.blockID, 12, 2);
			var1.setBlock(var3 + 9, var4 + 1, var5 + 13, Block.wood.blockID, 12, 2);
			var1.setBlock(var3 + 9, var4 + 2, var5 + 12, Block.wood.blockID, 12, 2);
			var1.setBlock(var3 + 9, var4 + 2, var5 + 13, Block.wood.blockID, 12, 2);
			var1.setBlock(var3 + 9, var4 + 3, var5 + 12, Block.wood.blockID, 12, 2);
			var1.setBlock(var3 + 9, var4 + 3, var5 + 13, Block.wood.blockID, 12, 2);
			var1.setBlock(var3 + 9, var4 + 4, var5 + 11, Block.wood.blockID, 12, 2);
			var1.setBlock(var3 + 9, var4 + 4, var5 + 12, Block.wood.blockID, 12, 2);
			var1.setBlock(var3 + 9, var4 + 4, var5 + 13, Block.wood.blockID, 12, 2);
			var1.setBlock(var3 + 9, var4 + 4, var5 + 17, BOPBlocks.appleLeavesFruitless.blockID, 4, 2);
			var1.setBlock(var3 + 9, var4 + 5, var5 + 11, Block.wood.blockID, 12, 2);
			var1.setBlock(var3 + 9, var4 + 5, var5 + 12, Block.wood.blockID, 12, 2);
			var1.setBlock(var3 + 9, var4 + 5, var5 + 13, Block.wood.blockID, 12, 2);
			var1.setBlock(var3 + 9, var4 + 6, var5 + 9, BOPBlocks.appleLeavesFruitless.blockID, 4, 2);
			var1.setBlock(var3 + 9, var4 + 6, var5 + 10, Block.wood.blockID, 12, 2);
			var1.setBlock(var3 + 9, var4 + 6, var5 + 11, Block.wood.blockID, 12, 2);
			var1.setBlock(var3 + 9, var4 + 6, var5 + 12, Block.wood.blockID, 12, 2);
			var1.setBlock(var3 + 9, var4 + 6, var5 + 19, BOPBlocks.appleLeavesFruitless.blockID, 4, 2);
			var1.setBlock(var3 + 9, var4 + 6, var5 + 25, BOPBlocks.appleLeaves.blockID, 4, 2);
			var1.setBlock(var3 + 9, var4 + 7, var5 + 10, Block.wood.blockID, 12, 2);
			var1.setBlock(var3 + 9, var4 + 7, var5 + 11, Block.wood.blockID, 12, 2);
			var1.setBlock(var3 + 9, var4 + 7, var5 + 20, BOPBlocks.appleLeavesFruitless.blockID, 4, 2);
			var1.setBlock(var3 + 9, var4 + 7, var5 + 22, BOPBlocks.appleLeavesFruitless.blockID, 4, 2);
			var1.setBlock(var3 + 9, var4 + 8, var5 + 10, Block.wood.blockID, 12, 2);
			var1.setBlock(var3 + 9, var4 + 8, var5 + 22, BOPBlocks.appleLeavesFruitless.blockID, 4, 2);
			var1.setBlock(var3 + 9, var4 + 8, var5 + 23, BOPBlocks.appleLeaves.blockID, 4, 2);
			var1.setBlock(var3 + 9, var4 + 8, var5 + 25, BOPBlocks.appleLeavesFruitless.blockID, 4, 2);
			var1.setBlock(var3 + 9, var4 + 8, var5 + 26, BOPBlocks.appleLeaves.blockID, 4, 2);
			var1.setBlock(var3 + 9, var4 + 9, var5 + 7, BOPBlocks.appleLeavesFruitless.blockID, 4, 2);
			var1.setBlock(var3 + 9, var4 + 9, var5 + 10, Block.wood.blockID, 12, 2);
			var1.setBlock(var3 + 9, var4 + 9, var5 + 23, BOPBlocks.appleLeavesFruitless.blockID, 4, 2);
			var1.setBlock(var3 + 9, var4 + 9, var5 + 25, BOPBlocks.appleLeavesFruitless.blockID, 4, 2);
			var1.setBlock(var3 + 9, var4 + 9, var5 + 26, BOPBlocks.appleLeavesFruitless.blockID, 4, 2);
			var1.setBlock(var3 + 9, var4 + 10, var5 + 10, Block.wood.blockID, 12, 2);
			var1.setBlock(var3 + 9, var4 + 10, var5 + 21, BOPBlocks.appleLeavesFruitless.blockID, 4, 2);
			var1.setBlock(var3 + 9, var4 + 11, var5 + 0, BOPBlocks.appleLeaves.blockID, 4, 2);
			var1.setBlock(var3 + 9, var4 + 11, var5 + 8, BOPBlocks.appleLeavesFruitless.blockID, 4, 2);
			var1.setBlock(var3 + 9, var4 + 11, var5 + 11, BOPBlocks.appleLeaves.blockID, 4, 2);
			var1.setBlock(var3 + 9, var4 + 11, var5 + 21, BOPBlocks.appleLeavesFruitless.blockID, 4, 2);
			var1.setBlock(var3 + 9, var4 + 12, var5 + 5, BOPBlocks.appleLeavesFruitless.blockID, 4, 2);
			var1.setBlock(var3 + 9, var4 + 12, var5 + 10, BOPBlocks.appleLeavesFruitless.blockID, 4, 2);
			var1.setBlock(var3 + 9, var4 + 12, var5 + 23, BOPBlocks.appleLeavesFruitless.blockID, 4, 2);
			var1.setBlock(var3 + 9, var4 + 12, var5 + 26, BOPBlocks.appleLeavesFruitless.blockID, 4, 2);
			var1.setBlock(var3 + 9, var4 + 13, var5 + 2, BOPBlocks.appleLeaves.blockID, 4, 2);
			var1.setBlock(var3 + 9, var4 + 13, var5 + 7, BOPBlocks.appleLeavesFruitless.blockID, 4, 2);
			var1.setBlock(var3 + 9, var4 + 13, var5 + 8, BOPBlocks.appleLeavesFruitless.blockID, 4, 2);
			var1.setBlock(var3 + 9, var4 + 13, var5 + 17, BOPBlocks.appleLeavesFruitless.blockID, 4, 2);
			var1.setBlock(var3 + 9, var4 + 13, var5 + 18, BOPBlocks.appleLeaves.blockID, 4, 2);
			var1.setBlock(var3 + 9, var4 + 13, var5 + 20, BOPBlocks.appleLeavesFruitless.blockID, 4, 2);
			var1.setBlock(var3 + 9, var4 + 14, var5 + 8, BOPBlocks.appleLeavesFruitless.blockID, 4, 2);
			var1.setBlock(var3 + 9, var4 + 14, var5 + 20, BOPBlocks.appleLeavesFruitless.blockID, 4, 2);
			var1.setBlock(var3 + 9, var4 + 14, var5 + 21, BOPBlocks.appleLeaves.blockID, 4, 2);
			var1.setBlock(var3 + 9, var4 + 14, var5 + 24, BOPBlocks.appleLeaves.blockID, 4, 2);
			var1.setBlock(var3 + 9, var4 + 15, var5 + 9, BOPBlocks.appleLeavesFruitless.blockID, 4, 2);
			var1.setBlock(var3 + 9, var4 + 15, var5 + 15, BOPBlocks.appleLeavesFruitless.blockID, 4, 2);
			var1.setBlock(var3 + 9, var4 + 15, var5 + 16, BOPBlocks.appleLeavesFruitless.blockID, 4, 2);
			var1.setBlock(var3 + 9, var4 + 15, var5 + 17, BOPBlocks.appleLeavesFruitless.blockID, 4, 2);
			var1.setBlock(var3 + 9, var4 + 15, var5 + 19, BOPBlocks.appleLeavesFruitless.blockID, 4, 2);
			var1.setBlock(var3 + 9, var4 + 15, var5 + 20, BOPBlocks.appleLeavesFruitless.blockID, 4, 2);
			var1.setBlock(var3 + 9, var4 + 16, var5 + 9, BOPBlocks.appleLeavesFruitless.blockID, 4, 2);
			var1.setBlock(var3 + 9, var4 + 16, var5 + 11, BOPBlocks.appleLeavesFruitless.blockID, 4, 2);
			var1.setBlock(var3 + 9, var4 + 16, var5 + 14, BOPBlocks.appleLeavesFruitless.blockID, 4, 2);
			var1.setBlock(var3 + 9, var4 + 16, var5 + 16, BOPBlocks.appleLeavesFruitless.blockID, 4, 2);
			var1.setBlock(var3 + 9, var4 + 16, var5 + 17, BOPBlocks.appleLeavesFruitless.blockID, 4, 2);
			var1.setBlock(var3 + 9, var4 + 16, var5 + 21, BOPBlocks.appleLeavesFruitless.blockID, 4, 2);
			var1.setBlock(var3 + 9, var4 + 16, var5 + 24, BOPBlocks.appleLeavesFruitless.blockID, 4, 2);
			var1.setBlock(var3 + 9, var4 + 16, var5 + 25, BOPBlocks.appleLeavesFruitless.blockID, 4, 2);
			var1.setBlock(var3 + 9, var4 + 17, var5 + 5, BOPBlocks.appleLeaves.blockID, 4, 2);
			var1.setBlock(var3 + 9, var4 + 17, var5 + 7, BOPBlocks.appleLeavesFruitless.blockID, 4, 2);
			var1.setBlock(var3 + 9, var4 + 17, var5 + 10, BOPBlocks.appleLeavesFruitless.blockID, 4, 2);
			var1.setBlock(var3 + 9, var4 + 17, var5 + 17, BOPBlocks.appleLeavesFruitless.blockID, 4, 2);
			var1.setBlock(var3 + 9, var4 + 18, var5 + 8, BOPBlocks.appleLeavesFruitless.blockID, 4, 2);
			var1.setBlock(var3 + 9, var4 + 18, var5 + 22, BOPBlocks.appleLeavesFruitless.blockID, 4, 2);
			var1.setBlock(var3 + 9, var4 + 19, var5 + 4, BOPBlocks.appleLeavesFruitless.blockID, 4, 2);
			var1.setBlock(var3 + 9, var4 + 19, var5 + 6, BOPBlocks.appleLeavesFruitless.blockID, 4, 2);
			var1.setBlock(var3 + 9, var4 + 19, var5 + 9, BOPBlocks.appleLeaves.blockID, 4, 2);
			var1.setBlock(var3 + 9, var4 + 20, var5 + 24, BOPBlocks.appleLeavesFruitless.blockID, 12, 2);
			var1.setBlock(var3 + 9, var4 + 22, var5 + 6, BOPBlocks.appleLeavesFruitless.blockID, 4, 2);
			var1.setBlock(var3 + 10, var4 + 0, var5 + 10, Block.wood.blockID, 12, 2);
			var1.setBlock(var3 + 10, var4 + 0, var5 + 12, Block.wood.blockID, 12, 2);
			var1.setBlock(var3 + 10, var4 + 0, var5 + 13, Block.wood.blockID, 12, 2);
			var1.setBlock(var3 + 10, var4 + 1, var5 + 12, Block.wood.blockID, 12, 2);
			var1.setBlock(var3 + 10, var4 + 1, var5 + 13, Block.wood.blockID, 12, 2);
			var1.setBlock(var3 + 10, var4 + 2, var5 + 12, Block.wood.blockID, 12, 2);
			var1.setBlock(var3 + 10, var4 + 2, var5 + 13, Block.wood.blockID, 12, 2);
			var1.setBlock(var3 + 10, var4 + 3, var5 + 12, Block.wood.blockID, 12, 2);
			var1.setBlock(var3 + 10, var4 + 3, var5 + 13, Block.wood.blockID, 12, 2);
			var1.setBlock(var3 + 10, var4 + 3, var5 + 14, Block.wood.blockID, 12, 2);
			var1.setBlock(var3 + 10, var4 + 4, var5 + 11, Block.wood.blockID, 12, 2);
			var1.setBlock(var3 + 10, var4 + 4, var5 + 12, Block.wood.blockID, 12, 2);
			var1.setBlock(var3 + 10, var4 + 4, var5 + 13, Block.wood.blockID, 12, 2);
			var1.setBlock(var3 + 10, var4 + 4, var5 + 14, Block.wood.blockID, 12, 2);
			var1.setBlock(var3 + 10, var4 + 5, var5 + 11, Block.wood.blockID, 12, 2);
			var1.setBlock(var3 + 10, var4 + 5, var5 + 12, Block.wood.blockID, 12, 2);
			var1.setBlock(var3 + 10, var4 + 5, var5 + 13, Block.wood.blockID, 12, 2);
			var1.setBlock(var3 + 10, var4 + 5, var5 + 14, Block.wood.blockID, 12, 2);
			var1.setBlock(var3 + 10, var4 + 6, var5 + 15, Block.wood.blockID, 12, 2);
			var1.setBlock(var3 + 10, var4 + 6, var5 + 17, BOPBlocks.appleLeavesFruitless.blockID, 4, 2);
			var1.setBlock(var3 + 10, var4 + 7, var5 + 17, BOPBlocks.appleLeavesFruitless.blockID, 4, 2);
			var1.setBlock(var3 + 10, var4 + 7, var5 + 23, BOPBlocks.appleLeavesFruitless.blockID, 4, 2);
			var1.setBlock(var3 + 10, var4 + 8, var5 + 1, BOPBlocks.appleLeavesFruitless.blockID, 4, 2);
			var1.setBlock(var3 + 10, var4 + 8, var5 + 19, BOPBlocks.appleLeavesFruitless.blockID, 4, 2);
			var1.setBlock(var3 + 10, var4 + 8, var5 + 27, BOPBlocks.appleLeavesFruitless.blockID, 4, 2);
			var1.setBlock(var3 + 10, var4 + 9, var5 + 4, BOPBlocks.appleLeavesFruitless.blockID, 4, 2);
			var1.setBlock(var3 + 10, var4 + 9, var5 + 9, BOPBlocks.appleLeavesFruitless.blockID, 4, 2);
			var1.setBlock(var3 + 10, var4 + 9, var5 + 10, Block.wood.blockID, 12, 2);
			var1.setBlock(var3 + 10, var4 + 9, var5 + 16, BOPBlocks.appleLeavesFruitless.blockID, 4, 2);
			var1.setBlock(var3 + 10, var4 + 9, var5 + 17, BOPBlocks.appleLeavesFruitless.blockID, 4, 2);
			var1.setBlock(var3 + 10, var4 + 9, var5 + 23, BOPBlocks.appleLeavesFruitless.blockID, 4, 2);
			var1.setBlock(var3 + 10, var4 + 9, var5 + 24, BOPBlocks.appleLeavesFruitless.blockID, 4, 2);
			var1.setBlock(var3 + 10, var4 + 10, var5 + 10, Block.wood.blockID, 12, 2);
			var1.setBlock(var3 + 10, var4 + 10, var5 + 16, BOPBlocks.appleLeavesFruitless.blockID, 4, 2);
			var1.setBlock(var3 + 10, var4 + 10, var5 + 24, BOPBlocks.appleLeavesFruitless.blockID, 4, 2);
			var1.setBlock(var3 + 10, var4 + 11, var5 + 20, BOPBlocks.appleLeavesFruitless.blockID, 4, 2);
			var1.setBlock(var3 + 10, var4 + 11, var5 + 21, BOPBlocks.appleLeavesFruitless.blockID, 4, 2);
			var1.setBlock(var3 + 10, var4 + 11, var5 + 26, BOPBlocks.appleLeaves.blockID, 4, 2);
			var1.setBlock(var3 + 10, var4 + 12, var5 + 0, BOPBlocks.appleLeavesFruitless.blockID, 4, 2);
			var1.setBlock(var3 + 10, var4 + 13, var5 + 1, BOPBlocks.appleLeavesFruitless.blockID, 4, 2);
			var1.setBlock(var3 + 10, var4 + 13, var5 + 2, BOPBlocks.appleLeavesFruitless.blockID, 4, 2);
			var1.setBlock(var3 + 10, var4 + 13, var5 + 8, BOPBlocks.appleLeaves.blockID, 4, 2);
			var1.setBlock(var3 + 10, var4 + 13, var5 + 17, BOPBlocks.appleLeaves.blockID, 4, 2);
			var1.setBlock(var3 + 10, var4 + 13, var5 + 19, BOPBlocks.appleLeavesFruitless.blockID, 4, 2);
			var1.setBlock(var3 + 10, var4 + 14, var5 + 15, BOPBlocks.appleLeavesFruitless.blockID, 4, 2);
			var1.setBlock(var3 + 10, var4 + 14, var5 + 21, BOPBlocks.appleLeavesFruitless.blockID, 4, 2);
			var1.setBlock(var3 + 10, var4 + 14, var5 + 23, BOPBlocks.appleLeaves.blockID, 4, 2);
			var1.setBlock(var3 + 10, var4 + 15, var5 + 2, BOPBlocks.appleLeavesFruitless.blockID, 4, 2);
			var1.setBlock(var3 + 10, var4 + 15, var5 + 16, BOPBlocks.appleLeavesFruitless.blockID, 4, 2);
			var1.setBlock(var3 + 10, var4 + 15, var5 + 18, BOPBlocks.appleLeaves.blockID, 4, 2);
			var1.setBlock(var3 + 10, var4 + 15, var5 + 24, BOPBlocks.appleLeavesFruitless.blockID, 4, 2);
			var1.setBlock(var3 + 10, var4 + 16, var5 + 13, BOPBlocks.appleLeavesFruitless.blockID, 4, 2);
			var1.setBlock(var3 + 10, var4 + 16, var5 + 23, BOPBlocks.appleLeaves.blockID, 4, 2);
			var1.setBlock(var3 + 10, var4 + 16, var5 + 24, BOPBlocks.appleLeavesFruitless.blockID, 4, 2);
			var1.setBlock(var3 + 10, var4 + 17, var5 + 4, BOPBlocks.appleLeavesFruitless.blockID, 4, 2);
			var1.setBlock(var3 + 10, var4 + 17, var5 + 5, BOPBlocks.appleLeavesFruitless.blockID, 4, 2);
			var1.setBlock(var3 + 10, var4 + 17, var5 + 15, BOPBlocks.appleLeavesFruitless.blockID, 4, 2);
			var1.setBlock(var3 + 10, var4 + 17, var5 + 21, BOPBlocks.appleLeavesFruitless.blockID, 4, 2);
			var1.setBlock(var3 + 10, var4 + 18, var5 + 7, BOPBlocks.appleLeavesFruitless.blockID, 4, 2);
			var1.setBlock(var3 + 10, var4 + 18, var5 + 22, BOPBlocks.appleLeavesFruitless.blockID, 4, 2);
			var1.setBlock(var3 + 10, var4 + 18, var5 + 23, BOPBlocks.appleLeavesFruitless.blockID, 4, 2);
			var1.setBlock(var3 + 10, var4 + 18, var5 + 25, BOPBlocks.appleLeavesFruitless.blockID, 4, 2);
			var1.setBlock(var3 + 10, var4 + 19, var5 + 6, BOPBlocks.appleLeavesFruitless.blockID, 4, 2);
			var1.setBlock(var3 + 10, var4 + 19, var5 + 21, BOPBlocks.appleLeavesFruitless.blockID, 4, 2);
			var1.setBlock(var3 + 10, var4 + 20, var5 + 21, BOPBlocks.appleLeaves.blockID, 4, 2);
			var1.setBlock(var3 + 10, var4 + 20, var5 + 23, BOPBlocks.appleLeavesFruitless.blockID, 12, 2);
			var1.setBlock(var3 + 10, var4 + 21, var5 + 6, BOPBlocks.appleLeavesFruitless.blockID, 4, 2);
			var1.setBlock(var3 + 10, var4 + 21, var5 + 23, BOPBlocks.appleLeavesFruitless.blockID, 12, 2);
			var1.setBlock(var3 + 11, var4 + 0, var5 + 13, Block.wood.blockID, 12, 2);
			var1.setBlock(var3 + 11, var4 + 4, var5 + 13, Block.wood.blockID, 12, 2);
			var1.setBlock(var3 + 11, var4 + 4, var5 + 14, Block.wood.blockID, 12, 2);
			var1.setBlock(var3 + 11, var4 + 5, var5 + 14, Block.wood.blockID, 12, 2);
			var1.setBlock(var3 + 11, var4 + 5, var5 + 15, Block.wood.blockID, 12, 2);
			var1.setBlock(var3 + 11, var4 + 5, var5 + 19, BOPBlocks.appleLeavesFruitless.blockID, 4, 2);
			var1.setBlock(var3 + 11, var4 + 6, var5 + 3, BOPBlocks.appleLeaves.blockID, 4, 2);
			var1.setBlock(var3 + 11, var4 + 6, var5 + 14, Block.wood.blockID, 12, 2);
			var1.setBlock(var3 + 11, var4 + 6, var5 + 15, Block.wood.blockID, 12, 2);
			var1.setBlock(var3 + 11, var4 + 6, var5 + 16, Block.wood.blockID, 12, 2);
			var1.setBlock(var3 + 11, var4 + 6, var5 + 19, BOPBlocks.appleLeavesFruitless.blockID, 4, 2);
			var1.setBlock(var3 + 11, var4 + 6, var5 + 20, BOPBlocks.appleLeaves.blockID, 4, 2);
			var1.setBlock(var3 + 11, var4 + 7, var5 + 14, BOPBlocks.appleLeavesFruitless.blockID, 4, 2);
			var1.setBlock(var3 + 11, var4 + 7, var5 + 17, Block.wood.blockID, 12, 2);
			var1.setBlock(var3 + 11, var4 + 7, var5 + 18, Block.wood.blockID, 12, 2);
			var1.setBlock(var3 + 11, var4 + 7, var5 + 19, Block.wood.blockID, 12, 2);
			var1.setBlock(var3 + 11, var4 + 7, var5 + 26, BOPBlocks.appleLeavesFruitless.blockID, 4, 2);
			var1.setBlock(var3 + 11, var4 + 7, var5 + 27, BOPBlocks.appleLeaves.blockID, 4, 2);
			var1.setBlock(var3 + 11, var4 + 8, var5 + 1, BOPBlocks.appleLeavesFruitless.blockID, 4, 2);
			var1.setBlock(var3 + 11, var4 + 8, var5 + 20, Block.wood.blockID, 12, 2);
			var1.setBlock(var3 + 11, var4 + 8, var5 + 24, BOPBlocks.appleLeavesFruitless.blockID, 4, 2);
			var1.setBlock(var3 + 11, var4 + 9, var5 + 15, BOPBlocks.appleLeavesFruitless.blockID, 4, 2);
			var1.setBlock(var3 + 11, var4 + 9, var5 + 21, Block.wood.blockID, 12, 2);
			var1.setBlock(var3 + 11, var4 + 9, var5 + 25, BOPBlocks.appleLeavesFruitless.blockID, 4, 2);
			var1.setBlock(var3 + 11, var4 + 9, var5 + 27, BOPBlocks.appleLeaves.blockID, 4, 2);
			var1.setBlock(var3 + 11, var4 + 10, var5 + 24, BOPBlocks.appleLeavesFruitless.blockID, 4, 2);
			var1.setBlock(var3 + 11, var4 + 10, var5 + 26, BOPBlocks.appleLeavesFruitless.blockID, 4, 2);
			var1.setBlock(var3 + 11, var4 + 10, var5 + 28, BOPBlocks.appleLeavesFruitless.blockID, 4, 2);
			var1.setBlock(var3 + 11, var4 + 11, var5 + 10, Block.wood.blockID, 12, 2);
			var1.setBlock(var3 + 11, var4 + 11, var5 + 16, BOPBlocks.appleLeavesFruitless.blockID, 4, 2);
			var1.setBlock(var3 + 11, var4 + 11, var5 + 27, BOPBlocks.appleLeavesFruitless.blockID, 4, 2);
			var1.setBlock(var3 + 11, var4 + 12, var5 + 6, BOPBlocks.appleLeavesFruitless.blockID, 4, 2);
			var1.setBlock(var3 + 11, var4 + 12, var5 + 8, BOPBlocks.appleLeaves.blockID, 4, 2);
			var1.setBlock(var3 + 11, var4 + 12, var5 + 21, BOPBlocks.appleLeavesFruitless.blockID, 4, 2);
			var1.setBlock(var3 + 11, var4 + 12, var5 + 24, BOPBlocks.appleLeavesFruitless.blockID, 4, 2);
			var1.setBlock(var3 + 11, var4 + 13, var5 + 1, BOPBlocks.appleLeaves.blockID, 4, 2);
			var1.setBlock(var3 + 11, var4 + 13, var5 + 3, BOPBlocks.appleLeaves.blockID, 4, 2);
			var1.setBlock(var3 + 11, var4 + 13, var5 + 21, BOPBlocks.appleLeavesFruitless.blockID, 4, 2);
			var1.setBlock(var3 + 11, var4 + 13, var5 + 22, Block.wood.blockID, 12, 2);
			var1.setBlock(var3 + 11, var4 + 13, var5 + 24, BOPBlocks.appleLeavesFruitless.blockID, 4, 2);
			var1.setBlock(var3 + 11, var4 + 13, var5 + 25, BOPBlocks.appleLeavesFruitless.blockID, 4, 2);
			var1.setBlock(var3 + 11, var4 + 13, var5 + 26, BOPBlocks.appleLeavesFruitless.blockID, 4, 2);
			var1.setBlock(var3 + 11, var4 + 14, var5 + 19, BOPBlocks.appleLeaves.blockID, 4, 2);
			var1.setBlock(var3 + 11, var4 + 14, var5 + 21, BOPBlocks.appleLeavesFruitless.blockID, 4, 2);
			var1.setBlock(var3 + 11, var4 + 14, var5 + 22, Block.wood.blockID, 12, 2);
			var1.setBlock(var3 + 11, var4 + 14, var5 + 23, BOPBlocks.appleLeavesFruitless.blockID, 4, 2);
			var1.setBlock(var3 + 11, var4 + 15, var5 + 4, BOPBlocks.appleLeavesFruitless.blockID, 4, 2);
			var1.setBlock(var3 + 11, var4 + 15, var5 + 13, BOPBlocks.appleLeavesFruitless.blockID, 4, 2);
			var1.setBlock(var3 + 11, var4 + 15, var5 + 14, BOPBlocks.appleLeavesFruitless.blockID, 4, 2);
			var1.setBlock(var3 + 11, var4 + 15, var5 + 17, BOPBlocks.appleLeavesFruitless.blockID, 4, 2);
			var1.setBlock(var3 + 11, var4 + 15, var5 + 19, BOPBlocks.appleLeaves.blockID, 4, 2);
			var1.setBlock(var3 + 11, var4 + 15, var5 + 21, BOPBlocks.appleLeavesFruitless.blockID, 4, 2);
			var1.setBlock(var3 + 11, var4 + 16, var5 + 23, BOPBlocks.appleLeavesFruitless.blockID, 4, 2);
			var1.setBlock(var3 + 11, var4 + 17, var5 + 4, BOPBlocks.appleLeavesFruitless.blockID, 4, 2);
			var1.setBlock(var3 + 11, var4 + 17, var5 + 8, BOPBlocks.appleLeavesFruitless.blockID, 4, 2);
			var1.setBlock(var3 + 11, var4 + 17, var5 + 10, BOPBlocks.appleLeavesFruitless.blockID, 4, 2);
			var1.setBlock(var3 + 11, var4 + 17, var5 + 11, BOPBlocks.appleLeavesFruitless.blockID, 4, 2);
			var1.setBlock(var3 + 11, var4 + 17, var5 + 12, BOPBlocks.appleLeavesFruitless.blockID, 4, 2);
			var1.setBlock(var3 + 11, var4 + 17, var5 + 22, BOPBlocks.appleLeavesFruitless.blockID, 4, 2);
			var1.setBlock(var3 + 11, var4 + 18, var5 + 1, BOPBlocks.appleLeavesFruitless.blockID, 4, 2);
			var1.setBlock(var3 + 11, var4 + 18, var5 + 24, BOPBlocks.appleLeaves.blockID, 4, 2);
			var1.setBlock(var3 + 11, var4 + 18, var5 + 26, BOPBlocks.appleLeaves.blockID, 4, 2);
			var1.setBlock(var3 + 11, var4 + 19, var5 + 8, BOPBlocks.appleLeavesFruitless.blockID, 4, 2);
			var1.setBlock(var3 + 11, var4 + 19, var5 + 25, BOPBlocks.appleLeavesFruitless.blockID, 4, 2);
			var1.setBlock(var3 + 11, var4 + 20, var5 + 5, BOPBlocks.appleLeaves.blockID, 4, 2);
			var1.setBlock(var3 + 11, var4 + 21, var5 + 7, BOPBlocks.appleLeavesFruitless.blockID, 4, 2);
			var1.setBlock(var3 + 12, var4 + 0, var5 + 12, Block.wood.blockID, 12, 2);
			var1.setBlock(var3 + 12, var4 + 6, var5 + 4, BOPBlocks.appleLeavesFruitless.blockID, 4, 2);
			var1.setBlock(var3 + 12, var4 + 6, var5 + 16, Block.wood.blockID, 12, 2);
			var1.setBlock(var3 + 12, var4 + 6, var5 + 17, Block.wood.blockID, 12, 2);
			var1.setBlock(var3 + 12, var4 + 7, var5 + 5, BOPBlocks.appleLeavesFruitless.blockID, 4, 2);
			var1.setBlock(var3 + 12, var4 + 7, var5 + 16, Block.wood.blockID, 12, 2);
			var1.setBlock(var3 + 12, var4 + 7, var5 + 17, Block.wood.blockID, 12, 2);
			var1.setBlock(var3 + 12, var4 + 7, var5 + 18, Block.wood.blockID, 12, 2);
			var1.setBlock(var3 + 12, var4 + 7, var5 + 19, Block.wood.blockID, 12, 2);
			var1.setBlock(var3 + 12, var4 + 7, var5 + 20, Block.wood.blockID, 12, 2);
			var1.setBlock(var3 + 12, var4 + 8, var5 + 0, BOPBlocks.appleLeavesFruitless.blockID, 4, 2);
			var1.setBlock(var3 + 12, var4 + 8, var5 + 16, BOPBlocks.appleLeaves.blockID, 4, 2);
			var1.setBlock(var3 + 12, var4 + 8, var5 + 18, Block.wood.blockID, 12, 2);
			var1.setBlock(var3 + 12, var4 + 8, var5 + 19, Block.wood.blockID, 12, 2);
			var1.setBlock(var3 + 12, var4 + 8, var5 + 20, Block.wood.blockID, 12, 2);
			var1.setBlock(var3 + 12, var4 + 8, var5 + 21, Block.wood.blockID, 12, 2);
			var1.setBlock(var3 + 12, var4 + 8, var5 + 25, BOPBlocks.appleLeavesFruitless.blockID, 4, 2);
			var1.setBlock(var3 + 12, var4 + 9, var5 + 3, BOPBlocks.appleLeavesFruitless.blockID, 4, 2);
			var1.setBlock(var3 + 12, var4 + 9, var5 + 4, BOPBlocks.appleLeavesFruitless.blockID, 4, 2);
			var1.setBlock(var3 + 12, var4 + 9, var5 + 6, BOPBlocks.appleLeavesFruitless.blockID, 4, 2);
			var1.setBlock(var3 + 12, var4 + 9, var5 + 14, BOPBlocks.appleLeavesFruitless.blockID, 4, 2);
			var1.setBlock(var3 + 12, var4 + 9, var5 + 21, Block.wood.blockID, 12, 2);
			var1.setBlock(var3 + 12, var4 + 9, var5 + 22, Block.wood.blockID, 12, 2);
			var1.setBlock(var3 + 12, var4 + 9, var5 + 24, BOPBlocks.appleLeavesFruitless.blockID, 4, 2);
			var1.setBlock(var3 + 12, var4 + 9, var5 + 27, BOPBlocks.appleLeaves.blockID, 4, 2);
			var1.setBlock(var3 + 12, var4 + 10, var5 + 1, BOPBlocks.appleLeavesFruitless.blockID, 4, 2);
			var1.setBlock(var3 + 12, var4 + 10, var5 + 16, BOPBlocks.appleLeavesFruitless.blockID, 4, 2);
			var1.setBlock(var3 + 12, var4 + 10, var5 + 22, Block.wood.blockID, 12, 2);
			var1.setBlock(var3 + 12, var4 + 11, var5 + 3, BOPBlocks.appleLeavesFruitless.blockID, 4, 2);
			var1.setBlock(var3 + 12, var4 + 11, var5 + 5, BOPBlocks.appleLeaves.blockID, 4, 2);
			var1.setBlock(var3 + 12, var4 + 11, var5 + 7, BOPBlocks.appleLeavesFruitless.blockID, 4, 2);
			var1.setBlock(var3 + 12, var4 + 11, var5 + 15, BOPBlocks.appleLeavesFruitless.blockID, 4, 2);
			var1.setBlock(var3 + 12, var4 + 11, var5 + 22, Block.wood.blockID, 12, 2);
			var1.setBlock(var3 + 12, var4 + 11, var5 + 23, BOPBlocks.appleLeavesFruitless.blockID, 4, 2);
			var1.setBlock(var3 + 12, var4 + 12, var5 + 3, BOPBlocks.appleLeavesFruitless.blockID, 4, 2);
			var1.setBlock(var3 + 12, var4 + 12, var5 + 6, BOPBlocks.appleLeavesFruitless.blockID, 4, 2);
			var1.setBlock(var3 + 12, var4 + 12, var5 + 8, BOPBlocks.appleLeavesFruitless.blockID, 4, 2);
			var1.setBlock(var3 + 12, var4 + 12, var5 + 10, Block.wood.blockID, 12, 2);
			var1.setBlock(var3 + 12, var4 + 12, var5 + 22, Block.wood.blockID, 12, 2);
			var1.setBlock(var3 + 12, var4 + 13, var5 + 7, BOPBlocks.appleLeavesFruitless.blockID, 4, 2);
			var1.setBlock(var3 + 12, var4 + 13, var5 + 20, BOPBlocks.appleLeavesFruitless.blockID, 4, 2);
			var1.setBlock(var3 + 12, var4 + 13, var5 + 24, BOPBlocks.appleLeavesFruitless.blockID, 4, 2);
			var1.setBlock(var3 + 12, var4 + 14, var5 + 5, BOPBlocks.appleLeavesFruitless.blockID, 4, 2);
			var1.setBlock(var3 + 12, var4 + 14, var5 + 19, BOPBlocks.appleLeaves.blockID, 4, 2);
			var1.setBlock(var3 + 12, var4 + 14, var5 + 22, BOPBlocks.appleLeaves.blockID, 4, 2);
			var1.setBlock(var3 + 12, var4 + 14, var5 + 23, BOPBlocks.appleLeavesFruitless.blockID, 4, 2);
			var1.setBlock(var3 + 12, var4 + 14, var5 + 25, BOPBlocks.appleLeavesFruitless.blockID, 4, 2);
			var1.setBlock(var3 + 12, var4 + 14, var5 + 26, BOPBlocks.appleLeavesFruitless.blockID, 4, 2);
			var1.setBlock(var3 + 12, var4 + 15, var5 + 4, BOPBlocks.appleLeaves.blockID, 4, 2);
			var1.setBlock(var3 + 12, var4 + 15, var5 + 12, BOPBlocks.appleLeavesFruitless.blockID, 4, 2);
			var1.setBlock(var3 + 12, var4 + 15, var5 + 19, BOPBlocks.appleLeaves.blockID, 4, 2);
			var1.setBlock(var3 + 12, var4 + 15, var5 + 24, BOPBlocks.appleLeavesFruitless.blockID, 4, 2);
			var1.setBlock(var3 + 12, var4 + 16, var5 + 6, BOPBlocks.appleLeavesFruitless.blockID, 4, 2);
			var1.setBlock(var3 + 12, var4 + 16, var5 + 9, BOPBlocks.appleLeavesFruitless.blockID, 4, 2);
			var1.setBlock(var3 + 12, var4 + 16, var5 + 14, BOPBlocks.appleLeavesFruitless.blockID, 4, 2);
			var1.setBlock(var3 + 12, var4 + 16, var5 + 19, BOPBlocks.appleLeavesFruitless.blockID, 4, 2);
			var1.setBlock(var3 + 12, var4 + 16, var5 + 20, BOPBlocks.appleLeaves.blockID, 4, 2);
			var1.setBlock(var3 + 12, var4 + 16, var5 + 22, BOPBlocks.appleLeavesFruitless.blockID, 4, 2);
			var1.setBlock(var3 + 12, var4 + 16, var5 + 23, BOPBlocks.appleLeavesFruitless.blockID, 4, 2);
			var1.setBlock(var3 + 12, var4 + 16, var5 + 25, BOPBlocks.appleLeavesFruitless.blockID, 4, 2);
			var1.setBlock(var3 + 12, var4 + 17, var5 + 1, BOPBlocks.appleLeavesFruitless.blockID, 4, 2);
			var1.setBlock(var3 + 12, var4 + 17, var5 + 3, BOPBlocks.appleLeavesFruitless.blockID, 4, 2);
			var1.setBlock(var3 + 12, var4 + 17, var5 + 7, BOPBlocks.appleLeavesFruitless.blockID, 4, 2);
			var1.setBlock(var3 + 12, var4 + 17, var5 + 11, BOPBlocks.appleLeavesFruitless.blockID, 4, 2);
			var1.setBlock(var3 + 12, var4 + 17, var5 + 20, BOPBlocks.appleLeavesFruitless.blockID, 4, 2);
			var1.setBlock(var3 + 12, var4 + 18, var5 + 4, BOPBlocks.appleLeavesFruitless.blockID, 4, 2);
			var1.setBlock(var3 + 12, var4 + 18, var5 + 11, BOPBlocks.appleLeaves.blockID, 4, 2);
			var1.setBlock(var3 + 12, var4 + 19, var5 + 7, BOPBlocks.appleLeavesFruitless.blockID, 4, 2);
			var1.setBlock(var3 + 12, var4 + 19, var5 + 25, BOPBlocks.appleLeavesFruitless.blockID, 4, 2);
			var1.setBlock(var3 + 12, var4 + 20, var5 + 4, BOPBlocks.appleLeavesFruitless.blockID, 4, 2);
			var1.setBlock(var3 + 12, var4 + 20, var5 + 24, BOPBlocks.appleLeavesFruitless.blockID, 4, 2);
			var1.setBlock(var3 + 13, var4 + 7, var5 + 15, BOPBlocks.appleLeavesFruitless.blockID, 4, 2);
			var1.setBlock(var3 + 13, var4 + 8, var5 + 13, BOPBlocks.appleLeaves.blockID, 4, 2);
			var1.setBlock(var3 + 13, var4 + 8, var5 + 16, Block.wood.blockID, 12, 2);
			var1.setBlock(var3 + 13, var4 + 8, var5 + 20, Block.wood.blockID, 12, 2);
			var1.setBlock(var3 + 13, var4 + 9, var5 + 16, Block.wood.blockID, 12, 2);
			var1.setBlock(var3 + 13, var4 + 9, var5 + 19, BOPBlocks.appleLeavesFruitless.blockID, 4, 2);
			var1.setBlock(var3 + 13, var4 + 9, var5 + 27, BOPBlocks.appleLeavesFruitless.blockID, 4, 2);
			var1.setBlock(var3 + 13, var4 + 10, var5 + 5, BOPBlocks.appleLeavesFruitless.blockID, 4, 2);
			var1.setBlock(var3 + 13, var4 + 10, var5 + 17, BOPBlocks.appleLeaves.blockID, 4, 2);
			var1.setBlock(var3 + 13, var4 + 10, var5 + 18, BOPBlocks.appleLeavesFruitless.blockID, 4, 2);
			var1.setBlock(var3 + 13, var4 + 10, var5 + 24, BOPBlocks.appleLeaves.blockID, 4, 2);
			var1.setBlock(var3 + 13, var4 + 10, var5 + 27, BOPBlocks.appleLeavesFruitless.blockID, 4, 2);
			var1.setBlock(var3 + 13, var4 + 10, var5 + 28, BOPBlocks.appleLeavesFruitless.blockID, 4, 2);
			var1.setBlock(var3 + 13, var4 + 11, var5 + 3, BOPBlocks.appleLeaves.blockID, 4, 2);
			var1.setBlock(var3 + 13, var4 + 11, var5 + 8, BOPBlocks.appleLeavesFruitless.blockID, 4, 2);
			var1.setBlock(var3 + 13, var4 + 11, var5 + 16, BOPBlocks.appleLeavesFruitless.blockID, 4, 2);
			var1.setBlock(var3 + 13, var4 + 12, var5 + 5, BOPBlocks.appleLeavesFruitless.blockID, 4, 2);
			var1.setBlock(var3 + 13, var4 + 12, var5 + 15, BOPBlocks.appleLeavesFruitless.blockID, 4, 2);
			var1.setBlock(var3 + 13, var4 + 12, var5 + 16, BOPBlocks.appleLeavesFruitless.blockID, 4, 2);
			var1.setBlock(var3 + 13, var4 + 12, var5 + 23, Block.wood.blockID, 12, 2);
			var1.setBlock(var3 + 13, var4 + 12, var5 + 26, BOPBlocks.appleLeavesFruitless.blockID, 4, 2);
			var1.setBlock(var3 + 13, var4 + 13, var5 + 10, Block.wood.blockID, 12, 2);
			var1.setBlock(var3 + 13, var4 + 13, var5 + 23, Block.wood.blockID, 12, 2);
			var1.setBlock(var3 + 13, var4 + 13, var5 + 27, BOPBlocks.appleLeavesFruitless.blockID, 4, 2);
			var1.setBlock(var3 + 13, var4 + 14, var5 + 5, BOPBlocks.appleLeavesFruitless.blockID, 4, 2);
			var1.setBlock(var3 + 13, var4 + 14, var5 + 9, BOPBlocks.appleLeaves.blockID, 4, 2);
			var1.setBlock(var3 + 13, var4 + 14, var5 + 11, BOPBlocks.appleLeavesFruitless.blockID, 4, 2);
			var1.setBlock(var3 + 13, var4 + 14, var5 + 21, BOPBlocks.appleLeavesFruitless.blockID, 4, 2);
			var1.setBlock(var3 + 13, var4 + 14, var5 + 22, BOPBlocks.appleLeaves.blockID, 4, 2);
			var1.setBlock(var3 + 13, var4 + 15, var5 + 10, BOPBlocks.appleLeavesFruitless.blockID, 4, 2);
			var1.setBlock(var3 + 13, var4 + 15, var5 + 11, BOPBlocks.appleLeavesFruitless.blockID, 4, 2);
			var1.setBlock(var3 + 13, var4 + 15, var5 + 12, BOPBlocks.appleLeavesFruitless.blockID, 4, 2);
			var1.setBlock(var3 + 13, var4 + 15, var5 + 22, BOPBlocks.appleLeavesFruitless.blockID, 4, 2);
			var1.setBlock(var3 + 13, var4 + 15, var5 + 23, BOPBlocks.appleLeavesFruitless.blockID, 4, 2);
			var1.setBlock(var3 + 13, var4 + 15, var5 + 24, BOPBlocks.appleLeavesFruitless.blockID, 4, 2);
			var1.setBlock(var3 + 13, var4 + 15, var5 + 25, BOPBlocks.appleLeaves.blockID, 4, 2);
			var1.setBlock(var3 + 13, var4 + 16, var5 + 20, BOPBlocks.appleLeavesFruitless.blockID, 4, 2);
			var1.setBlock(var3 + 13, var4 + 17, var5 + 7, BOPBlocks.appleLeavesFruitless.blockID, 4, 2);
			var1.setBlock(var3 + 13, var4 + 17, var5 + 10, BOPBlocks.appleLeavesFruitless.blockID, 4, 2);
			var1.setBlock(var3 + 13, var4 + 17, var5 + 11, BOPBlocks.appleLeavesFruitless.blockID, 4, 2);
			var1.setBlock(var3 + 13, var4 + 17, var5 + 12, BOPBlocks.appleLeavesFruitless.blockID, 4, 2);
			var1.setBlock(var3 + 13, var4 + 17, var5 + 13, BOPBlocks.appleLeavesFruitless.blockID, 4, 2);
			var1.setBlock(var3 + 13, var4 + 17, var5 + 19, BOPBlocks.appleLeaves.blockID, 4, 2);
			var1.setBlock(var3 + 13, var4 + 17, var5 + 21, BOPBlocks.appleLeaves.blockID, 4, 2);
			var1.setBlock(var3 + 13, var4 + 17, var5 + 24, BOPBlocks.appleLeavesFruitless.blockID, 4, 2);
			var1.setBlock(var3 + 13, var4 + 17, var5 + 25, BOPBlocks.appleLeavesFruitless.blockID, 4, 2);
			var1.setBlock(var3 + 13, var4 + 18, var5 + 4, BOPBlocks.appleLeavesFruitless.blockID, 4, 2);
			var1.setBlock(var3 + 13, var4 + 18, var5 + 19, BOPBlocks.appleLeavesFruitless.blockID, 4, 2);
			var1.setBlock(var3 + 13, var4 + 19, var5 + 9, BOPBlocks.appleLeavesFruitless.blockID, 4, 2);
			var1.setBlock(var3 + 13, var4 + 19, var5 + 10, BOPBlocks.appleLeaves.blockID, 4, 2);
			var1.setBlock(var3 + 13, var4 + 19, var5 + 22, BOPBlocks.appleLeavesFruitless.blockID, 4, 2);
			var1.setBlock(var3 + 13, var4 + 19, var5 + 23, BOPBlocks.appleLeavesFruitless.blockID, 4, 2);
			var1.setBlock(var3 + 13, var4 + 20, var5 + 23, BOPBlocks.appleLeavesFruitless.blockID, 4, 2);
			var1.setBlock(var3 + 13, var4 + 21, var5 + 8, BOPBlocks.appleLeavesFruitless.blockID, 4, 2);
			var1.setBlock(var3 + 14, var4 + 7, var5 + 18, BOPBlocks.appleLeavesFruitless.blockID, 4, 2);
			var1.setBlock(var3 + 14, var4 + 8, var5 + 15, BOPBlocks.appleLeavesFruitless.blockID, 4, 2);
			var1.setBlock(var3 + 14, var4 + 9, var5 + 5, BOPBlocks.appleLeavesFruitless.blockID, 4, 2);
			var1.setBlock(var3 + 14, var4 + 9, var5 + 20, Block.wood.blockID, 12, 2);
			var1.setBlock(var3 + 14, var4 + 9, var5 + 21, Block.wood.blockID, 12, 2);
			var1.setBlock(var3 + 14, var4 + 9, var5 + 26, BOPBlocks.appleLeavesFruitless.blockID, 4, 2);
			var1.setBlock(var3 + 14, var4 + 10, var5 + 13, BOPBlocks.appleLeavesFruitless.blockID, 4, 2);
			var1.setBlock(var3 + 14, var4 + 10, var5 + 16, BOPBlocks.appleLeaves.blockID, 4, 2);
			var1.setBlock(var3 + 14, var4 + 10, var5 + 25, BOPBlocks.appleLeavesFruitless.blockID, 4, 2);
			var1.setBlock(var3 + 14, var4 + 11, var5 + 5, BOPBlocks.appleLeavesFruitless.blockID, 4, 2);
			var1.setBlock(var3 + 14, var4 + 11, var5 + 17, BOPBlocks.appleLeavesFruitless.blockID, 4, 2);
			var1.setBlock(var3 + 14, var4 + 11, var5 + 24, BOPBlocks.appleLeaves.blockID, 4, 2);
			var1.setBlock(var3 + 14, var4 + 11, var5 + 26, BOPBlocks.appleLeavesFruitless.blockID, 4, 2);
			var1.setBlock(var3 + 14, var4 + 12, var5 + 25, BOPBlocks.appleLeavesFruitless.blockID, 4, 2);
			var1.setBlock(var3 + 14, var4 + 12, var5 + 26, BOPBlocks.appleLeavesFruitless.blockID, 4, 2);
			var1.setBlock(var3 + 14, var4 + 13, var5 + 7, BOPBlocks.appleLeavesFruitless.blockID, 4, 2);
			var1.setBlock(var3 + 14, var4 + 13, var5 + 10, Block.wood.blockID, 12, 2);
			var1.setBlock(var3 + 14, var4 + 13, var5 + 21, BOPBlocks.appleLeavesFruitless.blockID, 4, 2);
			var1.setBlock(var3 + 14, var4 + 13, var5 + 22, BOPBlocks.appleLeaves.blockID, 4, 2);
			var1.setBlock(var3 + 14, var4 + 13, var5 + 25, BOPBlocks.appleLeavesFruitless.blockID, 4, 2);
			var1.setBlock(var3 + 14, var4 + 13, var5 + 26, BOPBlocks.appleLeavesFruitless.blockID, 4, 2);
			var1.setBlock(var3 + 14, var4 + 14, var5 + 6, BOPBlocks.appleLeavesFruitless.blockID, 4, 2);
			var1.setBlock(var3 + 14, var4 + 14, var5 + 7, BOPBlocks.appleLeavesFruitless.blockID, 4, 2);
			var1.setBlock(var3 + 14, var4 + 14, var5 + 12, BOPBlocks.appleLeaves.blockID, 4, 2);
			var1.setBlock(var3 + 14, var4 + 14, var5 + 13, BOPBlocks.appleLeavesFruitless.blockID, 4, 2);
			var1.setBlock(var3 + 14, var4 + 14, var5 + 21, BOPBlocks.appleLeavesFruitless.blockID, 4, 2);
			var1.setBlock(var3 + 14, var4 + 14, var5 + 24, Block.wood.blockID, 12, 2);
			var1.setBlock(var3 + 14, var4 + 15, var5 + 13, BOPBlocks.appleLeavesFruitless.blockID, 4, 2);
			var1.setBlock(var3 + 14, var4 + 15, var5 + 22, BOPBlocks.appleLeavesFruitless.blockID, 4, 2);
			var1.setBlock(var3 + 14, var4 + 15, var5 + 25, BOPBlocks.appleLeavesFruitless.blockID, 4, 2);
			var1.setBlock(var3 + 14, var4 + 16, var5 + 9, BOPBlocks.appleLeaves.blockID, 4, 2);
			var1.setBlock(var3 + 14, var4 + 16, var5 + 17, BOPBlocks.appleLeavesFruitless.blockID, 4, 2);
			var1.setBlock(var3 + 14, var4 + 16, var5 + 18, BOPBlocks.appleLeavesFruitless.blockID, 4, 2);
			var1.setBlock(var3 + 14, var4 + 16, var5 + 21, BOPBlocks.appleLeavesFruitless.blockID, 4, 2);
			var1.setBlock(var3 + 14, var4 + 16, var5 + 24, BOPBlocks.appleLeavesFruitless.blockID, 4, 2);
			var1.setBlock(var3 + 14, var4 + 17, var5 + 3, BOPBlocks.appleLeavesFruitless.blockID, 4, 2);
			var1.setBlock(var3 + 14, var4 + 17, var5 + 4, BOPBlocks.appleLeavesFruitless.blockID, 4, 2);
			var1.setBlock(var3 + 14, var4 + 17, var5 + 6, BOPBlocks.appleLeavesFruitless.blockID, 4, 2);
			var1.setBlock(var3 + 14, var4 + 17, var5 + 13, BOPBlocks.appleLeavesFruitless.blockID, 4, 2);
			var1.setBlock(var3 + 14, var4 + 17, var5 + 15, BOPBlocks.appleLeaves.blockID, 4, 2);
			var1.setBlock(var3 + 14, var4 + 17, var5 + 17, BOPBlocks.appleLeavesFruitless.blockID, 4, 2);
			var1.setBlock(var3 + 14, var4 + 17, var5 + 18, BOPBlocks.appleLeavesFruitless.blockID, 4, 2);
			var1.setBlock(var3 + 14, var4 + 17, var5 + 19, BOPBlocks.appleLeavesFruitless.blockID, 4, 2);
			var1.setBlock(var3 + 14, var4 + 17, var5 + 20, BOPBlocks.appleLeavesFruitless.blockID, 4, 2);
			var1.setBlock(var3 + 14, var4 + 17, var5 + 24, BOPBlocks.appleLeavesFruitless.blockID, 4, 2);
			var1.setBlock(var3 + 14, var4 + 18, var5 + 6, BOPBlocks.appleLeavesFruitless.blockID, 4, 2);
			var1.setBlock(var3 + 14, var4 + 18, var5 + 9, BOPBlocks.appleLeavesFruitless.blockID, 4, 2);
			var1.setBlock(var3 + 14, var4 + 18, var5 + 11, BOPBlocks.appleLeavesFruitless.blockID, 4, 2);
			var1.setBlock(var3 + 14, var4 + 18, var5 + 12, BOPBlocks.appleLeavesFruitless.blockID, 4, 2);
			var1.setBlock(var3 + 14, var4 + 18, var5 + 13, BOPBlocks.appleLeavesFruitless.blockID, 4, 2);
			var1.setBlock(var3 + 14, var4 + 18, var5 + 17, BOPBlocks.appleLeavesFruitless.blockID, 4, 2);
			var1.setBlock(var3 + 14, var4 + 18, var5 + 26, BOPBlocks.appleLeavesFruitless.blockID, 4, 2);
			var1.setBlock(var3 + 14, var4 + 19, var5 + 12, BOPBlocks.appleLeavesFruitless.blockID, 4, 2);
			var1.setBlock(var3 + 14, var4 + 19, var5 + 18, BOPBlocks.appleLeavesFruitless.blockID, 4, 2);
			var1.setBlock(var3 + 14, var4 + 19, var5 + 19, BOPBlocks.appleLeavesFruitless.blockID, 4, 2);
			var1.setBlock(var3 + 14, var4 + 19, var5 + 22, BOPBlocks.appleLeaves.blockID, 4, 2);
			var1.setBlock(var3 + 14, var4 + 19, var5 + 23, BOPBlocks.appleLeavesFruitless.blockID, 4, 2);
			var1.setBlock(var3 + 14, var4 + 19, var5 + 24, BOPBlocks.appleLeavesFruitless.blockID, 4, 2);
			var1.setBlock(var3 + 14, var4 + 19, var5 + 26, BOPBlocks.appleLeavesFruitless.blockID, 12, 2);
			var1.setBlock(var3 + 14, var4 + 20, var5 + 6, BOPBlocks.appleLeavesFruitless.blockID, 4, 2);
			var1.setBlock(var3 + 14, var4 + 20, var5 + 22, BOPBlocks.appleLeavesFruitless.blockID, 4, 2);
			var1.setBlock(var3 + 14, var4 + 20, var5 + 24, BOPBlocks.appleLeavesFruitless.blockID, 12, 2);
			var1.setBlock(var3 + 14, var4 + 20, var5 + 25, BOPBlocks.appleLeavesFruitless.blockID, 12, 2);
			var1.setBlock(var3 + 15, var4 + 7, var5 + 18, BOPBlocks.appleLeavesFruitless.blockID, 4, 2);
			var1.setBlock(var3 + 15, var4 + 8, var5 + 14, BOPBlocks.appleLeavesFruitless.blockID, 4, 2);
			var1.setBlock(var3 + 15, var4 + 8, var5 + 18, BOPBlocks.appleLeavesFruitless.blockID, 4, 2);
			var1.setBlock(var3 + 15, var4 + 9, var5 + 2, BOPBlocks.appleLeavesFruitless.blockID, 4, 2);
			var1.setBlock(var3 + 15, var4 + 9, var5 + 3, BOPBlocks.appleLeaves.blockID, 4, 2);
			var1.setBlock(var3 + 15, var4 + 9, var5 + 16, BOPBlocks.appleLeavesFruitless.blockID, 4, 2);
			var1.setBlock(var3 + 15, var4 + 10, var5 + 5, BOPBlocks.appleLeavesFruitless.blockID, 4, 2);
			var1.setBlock(var3 + 15, var4 + 10, var5 + 7, BOPBlocks.appleLeavesFruitless.blockID, 4, 2);
			var1.setBlock(var3 + 15, var4 + 10, var5 + 21, BOPBlocks.appleLeavesFruitless.blockID, 4, 2);
			var1.setBlock(var3 + 15, var4 + 10, var5 + 22, Block.wood.blockID, 12, 2);
			var1.setBlock(var3 + 15, var4 + 10, var5 + 23, Block.wood.blockID, 12, 2);
			var1.setBlock(var3 + 15, var4 + 10, var5 + 24, Block.wood.blockID, 12, 2);
			var1.setBlock(var3 + 15, var4 + 10, var5 + 26, BOPBlocks.appleLeavesFruitless.blockID, 4, 2);
			var1.setBlock(var3 + 15, var4 + 11, var5 + 23, BOPBlocks.appleLeavesFruitless.blockID, 4, 2);
			var1.setBlock(var3 + 15, var4 + 12, var5 + 4, BOPBlocks.appleLeavesFruitless.blockID, 4, 2);
			var1.setBlock(var3 + 15, var4 + 12, var5 + 5, BOPBlocks.appleLeavesFruitless.blockID, 4, 2);
			var1.setBlock(var3 + 15, var4 + 12, var5 + 7, BOPBlocks.appleLeavesFruitless.blockID, 4, 2);
			var1.setBlock(var3 + 15, var4 + 12, var5 + 9, BOPBlocks.appleLeaves.blockID, 4, 2);
			var1.setBlock(var3 + 15, var4 + 12, var5 + 10, BOPBlocks.appleLeavesFruitless.blockID, 4, 2);
			var1.setBlock(var3 + 15, var4 + 12, var5 + 28, BOPBlocks.appleLeavesFruitless.blockID, 4, 2);
			var1.setBlock(var3 + 15, var4 + 13, var5 + 10, Block.wood.blockID, 12, 2);
			var1.setBlock(var3 + 15, var4 + 13, var5 + 19, BOPBlocks.appleLeavesFruitless.blockID, 4, 2);
			var1.setBlock(var3 + 15, var4 + 13, var5 + 23, BOPBlocks.appleLeaves.blockID, 4, 2);
			var1.setBlock(var3 + 15, var4 + 13, var5 + 27, BOPBlocks.appleLeavesFruitless.blockID, 4, 2);
			var1.setBlock(var3 + 15, var4 + 14, var5 + 6, BOPBlocks.appleLeavesFruitless.blockID, 4, 2);
			var1.setBlock(var3 + 15, var4 + 14, var5 + 24, BOPBlocks.appleLeavesFruitless.blockID, 4, 2);
			var1.setBlock(var3 + 15, var4 + 14, var5 + 26, BOPBlocks.appleLeavesFruitless.blockID, 4, 2);
			var1.setBlock(var3 + 15, var4 + 15, var5 + 2, BOPBlocks.appleLeavesFruitless.blockID, 4, 2);
			var1.setBlock(var3 + 15, var4 + 15, var5 + 3, BOPBlocks.appleLeavesFruitless.blockID, 4, 2);
			var1.setBlock(var3 + 15, var4 + 15, var5 + 4, BOPBlocks.appleLeaves.blockID, 4, 2);
			var1.setBlock(var3 + 15, var4 + 15, var5 + 7, BOPBlocks.appleLeavesFruitless.blockID, 4, 2);
			var1.setBlock(var3 + 15, var4 + 15, var5 + 16, BOPBlocks.appleLeaves.blockID, 4, 2);
			var1.setBlock(var3 + 15, var4 + 15, var5 + 19, BOPBlocks.appleLeavesFruitless.blockID, 4, 2);
			var1.setBlock(var3 + 15, var4 + 16, var5 + 5, BOPBlocks.appleLeavesFruitless.blockID, 4, 2);
			var1.setBlock(var3 + 15, var4 + 16, var5 + 20, BOPBlocks.appleLeavesFruitless.blockID, 4, 2);
			var1.setBlock(var3 + 15, var4 + 16, var5 + 22, BOPBlocks.appleLeavesFruitless.blockID, 4, 2);
			var1.setBlock(var3 + 15, var4 + 16, var5 + 23, BOPBlocks.appleLeavesFruitless.blockID, 4, 2);
			var1.setBlock(var3 + 15, var4 + 16, var5 + 25, BOPBlocks.appleLeavesFruitless.blockID, 4, 2);
			var1.setBlock(var3 + 15, var4 + 17, var5 + 3, BOPBlocks.appleLeavesFruitless.blockID, 4, 2);
			var1.setBlock(var3 + 15, var4 + 17, var5 + 10, BOPBlocks.appleLeavesFruitless.blockID, 4, 2);
			var1.setBlock(var3 + 15, var4 + 17, var5 + 12, BOPBlocks.appleLeavesFruitless.blockID, 4, 2);
			var1.setBlock(var3 + 15, var4 + 17, var5 + 14, BOPBlocks.appleLeavesFruitless.blockID, 4, 2);
			var1.setBlock(var3 + 15, var4 + 17, var5 + 19, BOPBlocks.appleLeavesFruitless.blockID, 4, 2);
			var1.setBlock(var3 + 15, var4 + 17, var5 + 24, BOPBlocks.appleLeaves.blockID, 4, 2);
			var1.setBlock(var3 + 15, var4 + 18, var5 + 3, BOPBlocks.appleLeavesFruitless.blockID, 4, 2);
			var1.setBlock(var3 + 15, var4 + 18, var5 + 8, BOPBlocks.appleLeavesFruitless.blockID, 4, 2);
			var1.setBlock(var3 + 15, var4 + 18, var5 + 13, BOPBlocks.appleLeavesFruitless.blockID, 4, 2);
			var1.setBlock(var3 + 15, var4 + 18, var5 + 14, BOPBlocks.appleLeavesFruitless.blockID, 4, 2);
			var1.setBlock(var3 + 15, var4 + 18, var5 + 23, BOPBlocks.appleLeavesFruitless.blockID, 4, 2);
			var1.setBlock(var3 + 15, var4 + 18, var5 + 27, BOPBlocks.appleLeavesFruitless.blockID, 4, 2);
			var1.setBlock(var3 + 15, var4 + 19, var5 + 9, BOPBlocks.appleLeavesFruitless.blockID, 4, 2);
			var1.setBlock(var3 + 15, var4 + 19, var5 + 10, BOPBlocks.appleLeavesFruitless.blockID, 4, 2);
			var1.setBlock(var3 + 15, var4 + 19, var5 + 13, BOPBlocks.appleLeavesFruitless.blockID, 4, 2);
			var1.setBlock(var3 + 15, var4 + 19, var5 + 18, BOPBlocks.appleLeavesFruitless.blockID, 4, 2);
			var1.setBlock(var3 + 15, var4 + 19, var5 + 19, BOPBlocks.appleLeavesFruitless.blockID, 4, 2);
			var1.setBlock(var3 + 15, var4 + 19, var5 + 21, BOPBlocks.appleLeaves.blockID, 4, 2);
			var1.setBlock(var3 + 15, var4 + 19, var5 + 22, BOPBlocks.appleLeaves.blockID, 4, 2);
			var1.setBlock(var3 + 15, var4 + 20, var5 + 6, BOPBlocks.appleLeavesFruitless.blockID, 4, 2);
			var1.setBlock(var3 + 15, var4 + 20, var5 + 24, BOPBlocks.appleLeavesFruitless.blockID, 12, 2);
			var1.setBlock(var3 + 15, var4 + 21, var5 + 8, BOPBlocks.appleLeavesFruitless.blockID, 4, 2);
			var1.setBlock(var3 + 15, var4 + 22, var5 + 9, BOPBlocks.appleLeavesFruitless.blockID, 4, 2);
			var1.setBlock(var3 + 16, var4 + 8, var5 + 16, BOPBlocks.appleLeavesFruitless.blockID, 4, 2);
			var1.setBlock(var3 + 16, var4 + 9, var5 + 17, BOPBlocks.appleLeavesFruitless.blockID, 4, 2);
			var1.setBlock(var3 + 16, var4 + 9, var5 + 18, BOPBlocks.appleLeavesFruitless.blockID, 4, 2);
			var1.setBlock(var3 + 16, var4 + 10, var5 + 9, BOPBlocks.appleLeavesFruitless.blockID, 4, 2);
			var1.setBlock(var3 + 16, var4 + 10, var5 + 16, BOPBlocks.appleLeavesFruitless.blockID, 4, 2);
			var1.setBlock(var3 + 16, var4 + 11, var5 + 5, BOPBlocks.appleLeavesFruitless.blockID, 4, 2);
			var1.setBlock(var3 + 16, var4 + 11, var5 + 13, BOPBlocks.appleLeaves.blockID, 4, 2);
			var1.setBlock(var3 + 16, var4 + 11, var5 + 21, BOPBlocks.appleLeavesFruitless.blockID, 4, 2);
			var1.setBlock(var3 + 16, var4 + 11, var5 + 24, Block.wood.blockID, 12, 2);
			var1.setBlock(var3 + 16, var4 + 11, var5 + 25, Block.wood.blockID, 12, 2);
			var1.setBlock(var3 + 16, var4 + 11, var5 + 27, BOPBlocks.appleLeavesFruitless.blockID, 4, 2);
			var1.setBlock(var3 + 16, var4 + 12, var5 + 10, BOPBlocks.appleLeavesFruitless.blockID, 4, 2);
			var1.setBlock(var3 + 16, var4 + 12, var5 + 24, BOPBlocks.appleLeavesFruitless.blockID, 4, 2);
			var1.setBlock(var3 + 16, var4 + 12, var5 + 26, Block.wood.blockID, 12, 2);
			var1.setBlock(var3 + 16, var4 + 12, var5 + 28, BOPBlocks.appleLeavesFruitless.blockID, 4, 2);
			var1.setBlock(var3 + 16, var4 + 13, var5 + 2, BOPBlocks.appleLeavesFruitless.blockID, 4, 2);
			var1.setBlock(var3 + 16, var4 + 13, var5 + 11, BOPBlocks.appleLeavesFruitless.blockID, 4, 2);
			var1.setBlock(var3 + 16, var4 + 13, var5 + 13, BOPBlocks.appleLeaves.blockID, 4, 2);
			var1.setBlock(var3 + 16, var4 + 13, var5 + 15, BOPBlocks.appleLeavesFruitless.blockID, 4, 2);
			var1.setBlock(var3 + 16, var4 + 13, var5 + 20, BOPBlocks.appleLeavesFruitless.blockID, 4, 2);
			var1.setBlock(var3 + 16, var4 + 13, var5 + 22, BOPBlocks.appleLeavesFruitless.blockID, 4, 2);
			var1.setBlock(var3 + 16, var4 + 13, var5 + 23, BOPBlocks.appleLeaves.blockID, 4, 2);
			var1.setBlock(var3 + 16, var4 + 13, var5 + 24, BOPBlocks.appleLeavesFruitless.blockID, 4, 2);
			var1.setBlock(var3 + 16, var4 + 13, var5 + 25, BOPBlocks.appleLeavesFruitless.blockID, 4, 2);
			var1.setBlock(var3 + 16, var4 + 13, var5 + 26, BOPBlocks.appleLeavesFruitless.blockID, 4, 2);
			var1.setBlock(var3 + 16, var4 + 13, var5 + 28, BOPBlocks.appleLeavesFruitless.blockID, 4, 2);
			var1.setBlock(var3 + 16, var4 + 14, var5 + 5, BOPBlocks.appleLeavesFruitless.blockID, 4, 2);
			var1.setBlock(var3 + 16, var4 + 14, var5 + 10, Block.wood.blockID, 12, 2);
			var1.setBlock(var3 + 16, var4 + 14, var5 + 12, BOPBlocks.appleLeavesFruitless.blockID, 4, 2);
			var1.setBlock(var3 + 16, var4 + 14, var5 + 16, BOPBlocks.appleLeavesFruitless.blockID, 4, 2);
			var1.setBlock(var3 + 16, var4 + 14, var5 + 17, BOPBlocks.appleLeavesFruitless.blockID, 4, 2);
			var1.setBlock(var3 + 16, var4 + 14, var5 + 24, BOPBlocks.appleLeavesFruitless.blockID, 4, 2);
			var1.setBlock(var3 + 16, var4 + 14, var5 + 26, BOPBlocks.appleLeavesFruitless.blockID, 4, 2);
			var1.setBlock(var3 + 16, var4 + 15, var5 + 2, BOPBlocks.appleLeavesFruitless.blockID, 4, 2);
			var1.setBlock(var3 + 16, var4 + 15, var5 + 8, BOPBlocks.appleLeavesFruitless.blockID, 4, 2);
			var1.setBlock(var3 + 16, var4 + 15, var5 + 17, BOPBlocks.appleLeaves.blockID, 4, 2);
			var1.setBlock(var3 + 16, var4 + 15, var5 + 19, BOPBlocks.appleLeavesFruitless.blockID, 4, 2);
			var1.setBlock(var3 + 16, var4 + 15, var5 + 20, BOPBlocks.appleLeavesFruitless.blockID, 4, 2);
			var1.setBlock(var3 + 16, var4 + 15, var5 + 27, BOPBlocks.appleLeavesFruitless.blockID, 4, 2);
			var1.setBlock(var3 + 16, var4 + 16, var5 + 3, BOPBlocks.appleLeavesFruitless.blockID, 4, 2);
			var1.setBlock(var3 + 16, var4 + 16, var5 + 4, BOPBlocks.appleLeavesFruitless.blockID, 4, 2);
			var1.setBlock(var3 + 16, var4 + 16, var5 + 5, BOPBlocks.appleLeavesFruitless.blockID, 4, 2);
			var1.setBlock(var3 + 16, var4 + 16, var5 + 11, BOPBlocks.appleLeavesFruitless.blockID, 4, 2);
			var1.setBlock(var3 + 16, var4 + 16, var5 + 12, BOPBlocks.appleLeavesFruitless.blockID, 4, 2);
			var1.setBlock(var3 + 16, var4 + 16, var5 + 13, BOPBlocks.appleLeavesFruitless.blockID, 4, 2);
			var1.setBlock(var3 + 16, var4 + 16, var5 + 19, BOPBlocks.appleLeavesFruitless.blockID, 4, 2);
			var1.setBlock(var3 + 16, var4 + 16, var5 + 22, BOPBlocks.appleLeaves.blockID, 4, 2);
			var1.setBlock(var3 + 16, var4 + 16, var5 + 24, BOPBlocks.appleLeavesFruitless.blockID, 4, 2);
			var1.setBlock(var3 + 16, var4 + 17, var5 + 2, BOPBlocks.appleLeavesFruitless.blockID, 4, 2);
			var1.setBlock(var3 + 16, var4 + 17, var5 + 4, BOPBlocks.appleLeavesFruitless.blockID, 4, 2);
			var1.setBlock(var3 + 16, var4 + 17, var5 + 12, BOPBlocks.appleLeavesFruitless.blockID, 4, 2);
			var1.setBlock(var3 + 16, var4 + 17, var5 + 16, BOPBlocks.appleLeavesFruitless.blockID, 4, 2);
			var1.setBlock(var3 + 16, var4 + 17, var5 + 19, BOPBlocks.appleLeavesFruitless.blockID, 4, 2);
			var1.setBlock(var3 + 16, var4 + 17, var5 + 24, BOPBlocks.appleLeavesFruitless.blockID, 4, 2);
			var1.setBlock(var3 + 16, var4 + 17, var5 + 25, BOPBlocks.appleLeavesFruitless.blockID, 4, 2);
			var1.setBlock(var3 + 16, var4 + 18, var5 + 7, BOPBlocks.appleLeavesFruitless.blockID, 4, 2);
			var1.setBlock(var3 + 16, var4 + 18, var5 + 12, BOPBlocks.appleLeavesFruitless.blockID, 4, 2);
			var1.setBlock(var3 + 16, var4 + 18, var5 + 17, BOPBlocks.appleLeaves.blockID, 4, 2);
			var1.setBlock(var3 + 16, var4 + 19, var5 + 9, BOPBlocks.appleLeavesFruitless.blockID, 4, 2);
			var1.setBlock(var3 + 16, var4 + 20, var5 + 7, BOPBlocks.appleLeaves.blockID, 4, 2);
			var1.setBlock(var3 + 16, var4 + 20, var5 + 8, BOPBlocks.appleLeavesFruitless.blockID, 4, 2);
			var1.setBlock(var3 + 16, var4 + 20, var5 + 10, BOPBlocks.appleLeavesFruitless.blockID, 4, 2);
			var1.setBlock(var3 + 16, var4 + 20, var5 + 11, BOPBlocks.appleLeavesFruitless.blockID, 4, 2);
			var1.setBlock(var3 + 16, var4 + 20, var5 + 13, BOPBlocks.appleLeavesFruitless.blockID, 4, 2);
			var1.setBlock(var3 + 16, var4 + 22, var5 + 8, BOPBlocks.appleLeavesFruitless.blockID, 4, 2);
			var1.setBlock(var3 + 17, var4 + 8, var5 + 2, BOPBlocks.appleLeavesFruitless.blockID, 4, 2);
			var1.setBlock(var3 + 17, var4 + 8, var5 + 3, BOPBlocks.appleLeavesFruitless.blockID, 4, 2);
			var1.setBlock(var3 + 17, var4 + 8, var5 + 20, BOPBlocks.appleLeavesFruitless.blockID, 4, 2);
			var1.setBlock(var3 + 17, var4 + 9, var5 + 5, BOPBlocks.appleLeavesFruitless.blockID, 4, 2);
			var1.setBlock(var3 + 17, var4 + 10, var5 + 3, BOPBlocks.appleLeaves.blockID, 4, 2);
			var1.setBlock(var3 + 17, var4 + 10, var5 + 26, BOPBlocks.appleLeavesFruitless.blockID, 4, 2);
			var1.setBlock(var3 + 17, var4 + 11, var5 + 12, BOPBlocks.appleLeavesFruitless.blockID, 4, 2);
			var1.setBlock(var3 + 17, var4 + 11, var5 + 22, BOPBlocks.appleLeavesFruitless.blockID, 4, 2);
			var1.setBlock(var3 + 17, var4 + 12, var5 + 13, BOPBlocks.appleLeavesFruitless.blockID, 4, 2);
			var1.setBlock(var3 + 17, var4 + 12, var5 + 23, BOPBlocks.appleLeavesFruitless.blockID, 4, 2);
			var1.setBlock(var3 + 17, var4 + 12, var5 + 25, BOPBlocks.appleLeavesFruitless.blockID, 4, 2);
			var1.setBlock(var3 + 17, var4 + 13, var5 + 2, BOPBlocks.appleLeavesFruitless.blockID, 4, 2);
			var1.setBlock(var3 + 17, var4 + 13, var5 + 7, BOPBlocks.appleLeavesFruitless.blockID, 4, 2);
			var1.setBlock(var3 + 17, var4 + 13, var5 + 10, BOPBlocks.appleLeavesFruitless.blockID, 4, 2);
			var1.setBlock(var3 + 17, var4 + 13, var5 + 11, BOPBlocks.appleLeavesFruitless.blockID, 4, 2);
			var1.setBlock(var3 + 17, var4 + 13, var5 + 12, BOPBlocks.appleLeavesFruitless.blockID, 4, 2);
			var1.setBlock(var3 + 17, var4 + 13, var5 + 21, BOPBlocks.appleLeavesFruitless.blockID, 4, 2);
			var1.setBlock(var3 + 17, var4 + 13, var5 + 26, BOPBlocks.appleLeaves.blockID, 4, 2);
			var1.setBlock(var3 + 17, var4 + 14, var5 + 3, BOPBlocks.appleLeavesFruitless.blockID, 4, 2);
			var1.setBlock(var3 + 17, var4 + 14, var5 + 10, Block.wood.blockID, 12, 2);
			var1.setBlock(var3 + 17, var4 + 14, var5 + 12, BOPBlocks.appleLeavesFruitless.blockID, 4, 2);
			var1.setBlock(var3 + 17, var4 + 14, var5 + 13, BOPBlocks.appleLeaves.blockID, 4, 2);
			var1.setBlock(var3 + 17, var4 + 14, var5 + 25, BOPBlocks.appleLeavesFruitless.blockID, 4, 2);
			var1.setBlock(var3 + 17, var4 + 15, var5 + 0, BOPBlocks.appleLeavesFruitless.blockID, 4, 2);
			var1.setBlock(var3 + 17, var4 + 15, var5 + 5, BOPBlocks.appleLeaves.blockID, 4, 2);
			var1.setBlock(var3 + 17, var4 + 15, var5 + 16, BOPBlocks.appleLeavesFruitless.blockID, 4, 2);
			var1.setBlock(var3 + 17, var4 + 16, var5 + 1, BOPBlocks.appleLeavesFruitless.blockID, 4, 2);
			var1.setBlock(var3 + 17, var4 + 16, var5 + 10, BOPBlocks.appleLeavesFruitless.blockID, 4, 2);
			var1.setBlock(var3 + 17, var4 + 16, var5 + 15, BOPBlocks.appleLeavesFruitless.blockID, 4, 2);
			var1.setBlock(var3 + 17, var4 + 16, var5 + 19, BOPBlocks.appleLeavesFruitless.blockID, 4, 2);
			var1.setBlock(var3 + 17, var4 + 17, var5 + 3, BOPBlocks.appleLeavesFruitless.blockID, 4, 2);
			var1.setBlock(var3 + 17, var4 + 17, var5 + 5, BOPBlocks.appleLeavesFruitless.blockID, 4, 2);
			var1.setBlock(var3 + 17, var4 + 17, var5 + 9, BOPBlocks.appleLeavesFruitless.blockID, 4, 2);
			var1.setBlock(var3 + 17, var4 + 17, var5 + 13, BOPBlocks.appleLeavesFruitless.blockID, 4, 2);
			var1.setBlock(var3 + 17, var4 + 17, var5 + 14, BOPBlocks.appleLeavesFruitless.blockID, 4, 2);
			var1.setBlock(var3 + 17, var4 + 17, var5 + 24, BOPBlocks.appleLeavesFruitless.blockID, 4, 2);
			var1.setBlock(var3 + 17, var4 + 18, var5 + 9, BOPBlocks.appleLeavesFruitless.blockID, 4, 2);
			var1.setBlock(var3 + 17, var4 + 18, var5 + 13, BOPBlocks.appleLeaves.blockID, 4, 2);
			var1.setBlock(var3 + 17, var4 + 18, var5 + 15, BOPBlocks.appleLeavesFruitless.blockID, 4, 2);
			var1.setBlock(var3 + 17, var4 + 18, var5 + 17, BOPBlocks.appleLeavesFruitless.blockID, 4, 2);
			var1.setBlock(var3 + 17, var4 + 18, var5 + 20, BOPBlocks.appleLeavesFruitless.blockID, 4, 2);
			var1.setBlock(var3 + 17, var4 + 19, var5 + 10, BOPBlocks.appleLeaves.blockID, 4, 2);
			var1.setBlock(var3 + 17, var4 + 19, var5 + 24, BOPBlocks.appleLeavesFruitless.blockID, 4, 2);
			var1.setBlock(var3 + 17, var4 + 19, var5 + 25, BOPBlocks.appleLeavesFruitless.blockID, 4, 2);
			var1.setBlock(var3 + 17, var4 + 20, var5 + 8, BOPBlocks.appleLeavesFruitless.blockID, 4, 2);
			var1.setBlock(var3 + 17, var4 + 20, var5 + 9, BOPBlocks.appleLeavesFruitless.blockID, 4, 2);
			var1.setBlock(var3 + 17, var4 + 20, var5 + 15, BOPBlocks.appleLeavesFruitless.blockID, 4, 2);
			var1.setBlock(var3 + 17, var4 + 21, var5 + 9, BOPBlocks.appleLeavesFruitless.blockID, 4, 2);
			var1.setBlock(var3 + 17, var4 + 22, var5 + 6, BOPBlocks.appleLeavesFruitless.blockID, 4, 2);
			var1.setBlock(var3 + 18, var4 + 10, var5 + 4, BOPBlocks.appleLeavesFruitless.blockID, 4, 2);
			var1.setBlock(var3 + 18, var4 + 10, var5 + 6, BOPBlocks.appleLeavesFruitless.blockID, 4, 2);
			var1.setBlock(var3 + 18, var4 + 10, var5 + 22, BOPBlocks.appleLeavesFruitless.blockID, 4, 2);
			var1.setBlock(var3 + 18, var4 + 10, var5 + 26, BOPBlocks.appleLeavesFruitless.blockID, 4, 2);
			var1.setBlock(var3 + 18, var4 + 10, var5 + 28, BOPBlocks.appleLeaves.blockID, 4, 2);
			var1.setBlock(var3 + 18, var4 + 11, var5 + 17, BOPBlocks.appleLeavesFruitless.blockID, 4, 2);
			var1.setBlock(var3 + 18, var4 + 11, var5 + 18, BOPBlocks.appleLeaves.blockID, 4, 2);
			var1.setBlock(var3 + 18, var4 + 11, var5 + 19, BOPBlocks.appleLeavesFruitless.blockID, 4, 2);
			var1.setBlock(var3 + 18, var4 + 11, var5 + 20, BOPBlocks.appleLeavesFruitless.blockID, 4, 2);
			var1.setBlock(var3 + 18, var4 + 11, var5 + 21, BOPBlocks.appleLeavesFruitless.blockID, 4, 2);
			var1.setBlock(var3 + 18, var4 + 11, var5 + 23, BOPBlocks.appleLeavesFruitless.blockID, 4, 2);
			var1.setBlock(var3 + 18, var4 + 12, var5 + 6, BOPBlocks.appleLeavesFruitless.blockID, 4, 2);
			var1.setBlock(var3 + 18, var4 + 12, var5 + 7, BOPBlocks.appleLeavesFruitless.blockID, 4, 2);
			var1.setBlock(var3 + 18, var4 + 12, var5 + 8, BOPBlocks.appleLeavesFruitless.blockID, 4, 2);
			var1.setBlock(var3 + 18, var4 + 12, var5 + 14, BOPBlocks.appleLeavesFruitless.blockID, 4, 2);
			var1.setBlock(var3 + 18, var4 + 12, var5 + 17, BOPBlocks.appleLeavesFruitless.blockID, 4, 2);
			var1.setBlock(var3 + 18, var4 + 12, var5 + 20, BOPBlocks.appleLeaves.blockID, 4, 2);
			var1.setBlock(var3 + 18, var4 + 12, var5 + 21, BOPBlocks.appleLeavesFruitless.blockID, 4, 2);
			var1.setBlock(var3 + 18, var4 + 13, var5 + 1, BOPBlocks.appleLeavesFruitless.blockID, 4, 2);
			var1.setBlock(var3 + 18, var4 + 13, var5 + 10, BOPBlocks.appleLeavesFruitless.blockID, 4, 2);
			var1.setBlock(var3 + 18, var4 + 13, var5 + 20, BOPBlocks.appleLeavesFruitless.blockID, 4, 2);
			var1.setBlock(var3 + 18, var4 + 13, var5 + 22, BOPBlocks.appleLeavesFruitless.blockID, 4, 2);
			var1.setBlock(var3 + 18, var4 + 13, var5 + 28, BOPBlocks.appleLeaves.blockID, 4, 2);
			var1.setBlock(var3 + 18, var4 + 14, var5 + 3, BOPBlocks.appleLeavesFruitless.blockID, 4, 2);
			var1.setBlock(var3 + 18, var4 + 14, var5 + 10, Block.wood.blockID, 12, 2);
			var1.setBlock(var3 + 18, var4 + 14, var5 + 28, BOPBlocks.appleLeavesFruitless.blockID, 4, 2);
			var1.setBlock(var3 + 18, var4 + 15, var5 + 0, BOPBlocks.appleLeaves.blockID, 4, 2);
			var1.setBlock(var3 + 18, var4 + 15, var5 + 5, BOPBlocks.appleLeaves.blockID, 4, 2);
			var1.setBlock(var3 + 18, var4 + 15, var5 + 12, BOPBlocks.appleLeavesFruitless.blockID, 4, 2);
			var1.setBlock(var3 + 18, var4 + 15, var5 + 13, BOPBlocks.appleLeavesFruitless.blockID, 4, 2);
			var1.setBlock(var3 + 18, var4 + 15, var5 + 14, BOPBlocks.appleLeavesFruitless.blockID, 4, 2);
			var1.setBlock(var3 + 18, var4 + 15, var5 + 16, BOPBlocks.appleLeavesFruitless.blockID, 4, 2);
			var1.setBlock(var3 + 18, var4 + 16, var5 + 6, BOPBlocks.appleLeavesFruitless.blockID, 4, 2);
			var1.setBlock(var3 + 18, var4 + 16, var5 + 13, BOPBlocks.appleLeavesFruitless.blockID, 4, 2);
			var1.setBlock(var3 + 18, var4 + 16, var5 + 15, BOPBlocks.appleLeavesFruitless.blockID, 4, 2);
			var1.setBlock(var3 + 18, var4 + 16, var5 + 19, BOPBlocks.appleLeaves.blockID, 4, 2);
			var1.setBlock(var3 + 18, var4 + 17, var5 + 2, BOPBlocks.appleLeavesFruitless.blockID, 4, 2);
			var1.setBlock(var3 + 18, var4 + 17, var5 + 3, BOPBlocks.appleLeavesFruitless.blockID, 4, 2);
			var1.setBlock(var3 + 18, var4 + 17, var5 + 7, BOPBlocks.appleLeavesFruitless.blockID, 4, 2);
			var1.setBlock(var3 + 18, var4 + 17, var5 + 8, BOPBlocks.appleLeavesFruitless.blockID, 4, 2);
			var1.setBlock(var3 + 18, var4 + 17, var5 + 10, BOPBlocks.appleLeavesFruitless.blockID, 4, 2);
			var1.setBlock(var3 + 18, var4 + 17, var5 + 13, BOPBlocks.appleLeavesFruitless.blockID, 4, 2);
			var1.setBlock(var3 + 18, var4 + 18, var5 + 3, BOPBlocks.appleLeavesFruitless.blockID, 4, 2);
			var1.setBlock(var3 + 18, var4 + 18, var5 + 10, BOPBlocks.appleLeavesFruitless.blockID, 4, 2);
			var1.setBlock(var3 + 18, var4 + 19, var5 + 13, BOPBlocks.appleLeavesFruitless.blockID, 4, 2);
			var1.setBlock(var3 + 18, var4 + 19, var5 + 25, BOPBlocks.appleLeavesFruitless.blockID, 4, 2);
			var1.setBlock(var3 + 18, var4 + 22, var5 + 9, BOPBlocks.appleLeavesFruitless.blockID, 4, 2);
			var1.setBlock(var3 + 19, var4 + 6, var5 + 13, BOPBlocks.appleLeaves.blockID, 4, 2);
			var1.setBlock(var3 + 19, var4 + 7, var5 + 2, BOPBlocks.appleLeavesFruitless.blockID, 4, 2);
			var1.setBlock(var3 + 19, var4 + 8, var5 + 1, BOPBlocks.appleLeaves.blockID, 4, 2);
			var1.setBlock(var3 + 19, var4 + 8, var5 + 12, BOPBlocks.appleLeavesFruitless.blockID, 4, 2);
			var1.setBlock(var3 + 19, var4 + 9, var5 + 2, BOPBlocks.appleLeavesFruitless.blockID, 4, 2);
			var1.setBlock(var3 + 19, var4 + 9, var5 + 13, BOPBlocks.appleLeavesFruitless.blockID, 4, 2);
			var1.setBlock(var3 + 19, var4 + 10, var5 + 0, BOPBlocks.appleLeavesFruitless.blockID, 4, 2);
			var1.setBlock(var3 + 19, var4 + 10, var5 + 6, BOPBlocks.appleLeavesFruitless.blockID, 4, 2);
			var1.setBlock(var3 + 19, var4 + 10, var5 + 17, BOPBlocks.appleLeavesFruitless.blockID, 4, 2);
			var1.setBlock(var3 + 19, var4 + 11, var5 + 1, BOPBlocks.appleLeavesFruitless.blockID, 4, 2);
			var1.setBlock(var3 + 19, var4 + 11, var5 + 4, BOPBlocks.appleLeavesFruitless.blockID, 4, 2);
			var1.setBlock(var3 + 19, var4 + 11, var5 + 6, BOPBlocks.appleLeavesFruitless.blockID, 4, 2);
			var1.setBlock(var3 + 19, var4 + 11, var5 + 22, BOPBlocks.appleLeavesFruitless.blockID, 4, 2);
			var1.setBlock(var3 + 19, var4 + 11, var5 + 26, BOPBlocks.appleLeavesFruitless.blockID, 4, 2);
			var1.setBlock(var3 + 19, var4 + 12, var5 + 3, BOPBlocks.appleLeaves.blockID, 4, 2);
			var1.setBlock(var3 + 19, var4 + 12, var5 + 8, BOPBlocks.appleLeaves.blockID, 4, 2);
			var1.setBlock(var3 + 19, var4 + 12, var5 + 13, BOPBlocks.appleLeaves.blockID, 4, 2);
			var1.setBlock(var3 + 19, var4 + 12, var5 + 14, BOPBlocks.appleLeavesFruitless.blockID, 4, 2);
			var1.setBlock(var3 + 19, var4 + 12, var5 + 26, BOPBlocks.appleLeavesFruitless.blockID, 4, 2);
			var1.setBlock(var3 + 19, var4 + 13, var5 + 3, BOPBlocks.appleLeavesFruitless.blockID, 4, 2);
			var1.setBlock(var3 + 19, var4 + 13, var5 + 9, BOPBlocks.appleLeaves.blockID, 4, 2);
			var1.setBlock(var3 + 19, var4 + 13, var5 + 18, BOPBlocks.appleLeavesFruitless.blockID, 4, 2);
			var1.setBlock(var3 + 19, var4 + 13, var5 + 20, BOPBlocks.appleLeavesFruitless.blockID, 4, 2);
			var1.setBlock(var3 + 19, var4 + 14, var5 + 1, BOPBlocks.appleLeavesFruitless.blockID, 4, 2);
			var1.setBlock(var3 + 19, var4 + 14, var5 + 3, BOPBlocks.appleLeavesFruitless.blockID, 4, 2);
			var1.setBlock(var3 + 19, var4 + 15, var5 + 1, BOPBlocks.appleLeavesFruitless.blockID, 4, 2);
			var1.setBlock(var3 + 19, var4 + 15, var5 + 3, BOPBlocks.appleLeaves.blockID, 4, 2);
			var1.setBlock(var3 + 19, var4 + 15, var5 + 7, BOPBlocks.appleLeavesFruitless.blockID, 4, 2);
			var1.setBlock(var3 + 19, var4 + 15, var5 + 9, Block.wood.blockID, 12, 2);
			var1.setBlock(var3 + 19, var4 + 15, var5 + 12, BOPBlocks.appleLeavesFruitless.blockID, 4, 2);
			var1.setBlock(var3 + 19, var4 + 16, var5 + 5, BOPBlocks.appleLeaves.blockID, 4, 2);
			var1.setBlock(var3 + 19, var4 + 16, var5 + 11, BOPBlocks.appleLeavesFruitless.blockID, 4, 2);
			var1.setBlock(var3 + 19, var4 + 17, var5 + 3, BOPBlocks.appleLeavesFruitless.blockID, 4, 2);
			var1.setBlock(var3 + 19, var4 + 17, var5 + 16, BOPBlocks.appleLeavesFruitless.blockID, 4, 2);
			var1.setBlock(var3 + 19, var4 + 18, var5 + 13, BOPBlocks.appleLeavesFruitless.blockID, 4, 2);
			var1.setBlock(var3 + 19, var4 + 18, var5 + 14, BOPBlocks.appleLeavesFruitless.blockID, 4, 2);
			var1.setBlock(var3 + 19, var4 + 19, var5 + 8, BOPBlocks.appleLeavesFruitless.blockID, 4, 2);
			var1.setBlock(var3 + 19, var4 + 21, var5 + 7, BOPBlocks.appleLeavesFruitless.blockID, 4, 2);
			var1.setBlock(var3 + 20, var4 + 6, var5 + 12, BOPBlocks.appleLeavesFruitless.blockID, 4, 2);
			var1.setBlock(var3 + 20, var4 + 7, var5 + 14, BOPBlocks.appleLeavesFruitless.blockID, 4, 2);
			var1.setBlock(var3 + 20, var4 + 7, var5 + 15, BOPBlocks.appleLeavesFruitless.blockID, 4, 2);
			var1.setBlock(var3 + 20, var4 + 7, var5 + 16, BOPBlocks.appleLeavesFruitless.blockID, 4, 2);
			var1.setBlock(var3 + 20, var4 + 8, var5 + 10, BOPBlocks.appleLeavesFruitless.blockID, 4, 2);
			var1.setBlock(var3 + 20, var4 + 8, var5 + 14, BOPBlocks.appleLeavesFruitless.blockID, 4, 2);
			var1.setBlock(var3 + 20, var4 + 8, var5 + 16, BOPBlocks.appleLeaves.blockID, 4, 2);
			var1.setBlock(var3 + 20, var4 + 9, var5 + 0, BOPBlocks.appleLeavesFruitless.blockID, 4, 2);
			var1.setBlock(var3 + 20, var4 + 9, var5 + 1, BOPBlocks.appleLeavesFruitless.blockID, 4, 2);
			var1.setBlock(var3 + 20, var4 + 9, var5 + 3, BOPBlocks.appleLeavesFruitless.blockID, 4, 2);
			var1.setBlock(var3 + 20, var4 + 9, var5 + 10, BOPBlocks.appleLeavesFruitless.blockID, 4, 2);
			var1.setBlock(var3 + 20, var4 + 9, var5 + 13, BOPBlocks.appleLeavesFruitless.blockID, 4, 2);
			var1.setBlock(var3 + 20, var4 + 9, var5 + 14, BOPBlocks.appleLeavesFruitless.blockID, 4, 2);
			var1.setBlock(var3 + 20, var4 + 9, var5 + 15, BOPBlocks.appleLeaves.blockID, 4, 2);
			var1.setBlock(var3 + 20, var4 + 9, var5 + 18, BOPBlocks.appleLeavesFruitless.blockID, 4, 2);
			var1.setBlock(var3 + 20, var4 + 10, var5 + 0, BOPBlocks.appleLeavesFruitless.blockID, 4, 2);
			var1.setBlock(var3 + 20, var4 + 10, var5 + 3, BOPBlocks.appleLeavesFruitless.blockID, 4, 2);
			var1.setBlock(var3 + 20, var4 + 10, var5 + 7, BOPBlocks.appleLeavesFruitless.blockID, 4, 2);
			var1.setBlock(var3 + 20, var4 + 10, var5 + 11, BOPBlocks.appleLeavesFruitless.blockID, 4, 2);
			var1.setBlock(var3 + 20, var4 + 11, var5 + 2, BOPBlocks.appleLeavesFruitless.blockID, 4, 2);
			var1.setBlock(var3 + 20, var4 + 12, var5 + 11, BOPBlocks.appleLeavesFruitless.blockID, 4, 2);
			var1.setBlock(var3 + 20, var4 + 13, var5 + 2, BOPBlocks.appleLeaves.blockID, 4, 2);
			var1.setBlock(var3 + 20, var4 + 13, var5 + 3, BOPBlocks.appleLeavesFruitless.blockID, 4, 2);
			var1.setBlock(var3 + 20, var4 + 13, var5 + 5, BOPBlocks.appleLeaves.blockID, 4, 2);
			var1.setBlock(var3 + 20, var4 + 13, var5 + 9, BOPBlocks.appleLeavesFruitless.blockID, 4, 2);
			var1.setBlock(var3 + 20, var4 + 13, var5 + 13, BOPBlocks.appleLeavesFruitless.blockID, 4, 2);
			var1.setBlock(var3 + 20, var4 + 14, var5 + 5, BOPBlocks.appleLeavesFruitless.blockID, 4, 2);
			var1.setBlock(var3 + 20, var4 + 14, var5 + 10, BOPBlocks.appleLeavesFruitless.blockID, 4, 2);
			var1.setBlock(var3 + 20, var4 + 14, var5 + 12, BOPBlocks.appleLeavesFruitless.blockID, 4, 2);
			var1.setBlock(var3 + 20, var4 + 15, var5 + 2, BOPBlocks.appleLeaves.blockID, 4, 2);
			var1.setBlock(var3 + 20, var4 + 16, var5 + 9, Block.wood.blockID, 12, 2);
			var1.setBlock(var3 + 20, var4 + 16, var5 + 11, BOPBlocks.appleLeavesFruitless.blockID, 4, 2);
			var1.setBlock(var3 + 20, var4 + 17, var5 + 6, BOPBlocks.appleLeavesFruitless.blockID, 4, 2);
			var1.setBlock(var3 + 20, var4 + 17, var5 + 7, BOPBlocks.appleLeavesFruitless.blockID, 4, 2);
			var1.setBlock(var3 + 20, var4 + 17, var5 + 9, Block.wood.blockID, 12, 2);
			var1.setBlock(var3 + 20, var4 + 17, var5 + 10, BOPBlocks.appleLeavesFruitless.blockID, 4, 2);
			var1.setBlock(var3 + 20, var4 + 17, var5 + 11, BOPBlocks.appleLeavesFruitless.blockID, 4, 2);
			var1.setBlock(var3 + 20, var4 + 18, var5 + 7, BOPBlocks.appleLeavesFruitless.blockID, 4, 2);
			var1.setBlock(var3 + 20, var4 + 19, var5 + 9, BOPBlocks.appleLeavesFruitless.blockID, 4, 2);
			var1.setBlock(var3 + 20, var4 + 20, var5 + 9, BOPBlocks.appleLeavesFruitless.blockID, 4, 2);
			var1.setBlock(var3 + 21, var4 + 7, var5 + 15, BOPBlocks.appleLeaves.blockID, 4, 2);
			var1.setBlock(var3 + 21, var4 + 8, var5 + 4, BOPBlocks.appleLeavesFruitless.blockID, 4, 2);
			var1.setBlock(var3 + 21, var4 + 8, var5 + 11, BOPBlocks.appleLeavesFruitless.blockID, 4, 2);
			var1.setBlock(var3 + 21, var4 + 9, var5 + 3, BOPBlocks.appleLeavesFruitless.blockID, 4, 2);
			var1.setBlock(var3 + 21, var4 + 9, var5 + 14, BOPBlocks.appleLeavesFruitless.blockID, 4, 2);
			var1.setBlock(var3 + 21, var4 + 10, var5 + 1, BOPBlocks.appleLeavesFruitless.blockID, 4, 2);
			var1.setBlock(var3 + 21, var4 + 10, var5 + 2, BOPBlocks.appleLeavesFruitless.blockID, 4, 2);
			var1.setBlock(var3 + 21, var4 + 10, var5 + 4, BOPBlocks.appleLeavesFruitless.blockID, 4, 2);
			var1.setBlock(var3 + 21, var4 + 11, var5 + 6, BOPBlocks.appleLeaves.blockID, 4, 2);
			var1.setBlock(var3 + 21, var4 + 11, var5 + 10, BOPBlocks.appleLeavesFruitless.blockID, 4, 2);
			var1.setBlock(var3 + 21, var4 + 12, var5 + 4, BOPBlocks.appleLeavesFruitless.blockID, 4, 2);
			var1.setBlock(var3 + 21, var4 + 12, var5 + 5, BOPBlocks.appleLeaves.blockID, 4, 2);
			var1.setBlock(var3 + 21, var4 + 12, var5 + 8, BOPBlocks.appleLeavesFruitless.blockID, 4, 2);
			var1.setBlock(var3 + 21, var4 + 12, var5 + 11, BOPBlocks.appleLeavesFruitless.blockID, 4, 2);
			var1.setBlock(var3 + 21, var4 + 13, var5 + 8, BOPBlocks.appleLeavesFruitless.blockID, 4, 2);
			var1.setBlock(var3 + 21, var4 + 13, var5 + 9, BOPBlocks.appleLeaves.blockID, 4, 2);
			var1.setBlock(var3 + 21, var4 + 13, var5 + 11, BOPBlocks.appleLeavesFruitless.blockID, 4, 2);
			var1.setBlock(var3 + 21, var4 + 15, var5 + 2, BOPBlocks.appleLeavesFruitless.blockID, 4, 2);
			var1.setBlock(var3 + 21, var4 + 18, var5 + 12, BOPBlocks.appleLeavesFruitless.blockID, 4, 2);
			var1.setBlock(var3 + 21, var4 + 19, var5 + 7, BOPBlocks.appleLeavesFruitless.blockID, 4, 2);
			var1.setBlock(var3 + 21, var4 + 19, var5 + 12, BOPBlocks.appleLeavesFruitless.blockID, 4, 2);
			var1.setBlock(var3 + 22, var4 + 8, var5 + 11, BOPBlocks.appleLeavesFruitless.blockID, 4, 2);
			var1.setBlock(var3 + 22, var4 + 8, var5 + 12, BOPBlocks.appleLeavesFruitless.blockID, 4, 2);
			var1.setBlock(var3 + 22, var4 + 8, var5 + 13, BOPBlocks.appleLeavesFruitless.blockID, 4, 2);
			var1.setBlock(var3 + 22, var4 + 9, var5 + 3, BOPBlocks.appleLeavesFruitless.blockID, 4, 2);
			var1.setBlock(var3 + 22, var4 + 9, var5 + 11, BOPBlocks.appleLeavesFruitless.blockID, 4, 2);
			var1.setBlock(var3 + 22, var4 + 9, var5 + 12, BOPBlocks.appleLeavesFruitless.blockID, 4, 2);
			var1.setBlock(var3 + 22, var4 + 10, var5 + 4, BOPBlocks.appleLeaves.blockID, 4, 2);
			var1.setBlock(var3 + 22, var4 + 10, var5 + 9, BOPBlocks.appleLeavesFruitless.blockID, 4, 2);
			var1.setBlock(var3 + 22, var4 + 10, var5 + 12, BOPBlocks.appleLeavesFruitless.blockID, 4, 2);
			var1.setBlock(var3 + 22, var4 + 10, var5 + 13, BOPBlocks.appleLeavesFruitless.blockID, 4, 2);
			var1.setBlock(var3 + 22, var4 + 12, var5 + 7, BOPBlocks.appleLeavesFruitless.blockID, 4, 2);
			var1.setBlock(var3 + 22, var4 + 12, var5 + 8, BOPBlocks.appleLeavesFruitless.blockID, 4, 2);
			var1.setBlock(var3 + 22, var4 + 12, var5 + 9, BOPBlocks.appleLeavesFruitless.blockID, 4, 2);
			var1.setBlock(var3 + 22, var4 + 12, var5 + 11, BOPBlocks.appleLeaves.blockID, 4, 2);
			var1.setBlock(var3 + 22, var4 + 13, var5 + 6, BOPBlocks.appleLeavesFruitless.blockID, 4, 2);
			var1.setBlock(var3 + 22, var4 + 15, var5 + 9, BOPBlocks.appleLeavesFruitless.blockID, 4, 2);
			var1.setBlock(var3 + 22, var4 + 17, var5 + 10, BOPBlocks.appleLeaves.blockID, 4, 2);
			var1.setBlock(var3 + 22, var4 + 19, var5 + 8, BOPBlocks.appleLeavesFruitless.blockID, 4, 2);
			var1.setBlock(var3 + 23, var4 + 9, var5 + 10, BOPBlocks.appleLeavesFruitless.blockID, 4, 2);
			var1.setBlock(var3 + 23, var4 + 12, var5 + 6, BOPBlocks.appleLeavesFruitless.blockID, 4, 2);
			var1.setBlock(var3 + 23, var4 + 12, var5 + 9, BOPBlocks.appleLeavesFruitless.blockID, 4, 2);
			var1.setBlock(var3 + 23, var4 + 12, var5 + 10, BOPBlocks.appleLeaves.blockID, 4, 2);
			var1.setBlock(var3 + 23, var4 + 13, var5 + 6, BOPBlocks.appleLeavesFruitless.blockID, 4, 2);
			var1.setBlock(var3 + 23, var4 + 15, var5 + 9, BOPBlocks.appleLeavesFruitless.blockID, 4, 2);
			var1.setBlock(var3 + 23, var4 + 17, var5 + 8, BOPBlocks.appleLeavesFruitless.blockID, 4, 2);
			var1.setBlock(var3 + 23, var4 + 17, var5 + 9, BOPBlocks.appleLeavesFruitless.blockID, 4, 2);
			var1.setBlock(var3 + 23, var4 + 18, var5 + 8, BOPBlocks.appleLeavesFruitless.blockID, 4, 2);
			var1.setBlock(var3 + 24, var4 + 10, var5 + 9, BOPBlocks.appleLeavesFruitless.blockID, 4, 2);
			var1.setBlock(var3 + 24, var4 + 11, var5 + 8, BOPBlocks.appleLeavesFruitless.blockID, 4, 2);
			var1.setBlock(var3 + 24, var4 + 12, var5 + 9, BOPBlocks.appleLeavesFruitless.blockID, 4, 2);
			var1.setBlock(var3 + 24, var4 + 12, var5 + 10, BOPBlocks.appleLeaves.blockID, 4, 2);
			var1.setBlock(var3 + 24, var4 + 13, var5 + 9, BOPBlocks.appleLeavesFruitless.blockID, 4, 2);
			var1.setBlock(var3 + 25, var4 + 11, var5 + 9, BOPBlocks.appleLeavesFruitless.blockID, 4, 2);
			var1.setBlock(var3 + 25, var4 + 11, var5 + 10, BOPBlocks.appleLeavesFruitless.blockID, 4, 2);
			var1.setBlock(var3 + 25, var4 + 13, var5 + 9, BOPBlocks.appleLeaves.blockID, 4, 2);
            return true;
        }
    }
}
