package biomesoplenty.worldgen;

import java.util.Random;

import net.minecraft.block.Block;
import net.minecraft.world.World;
import net.minecraft.world.gen.feature.WorldGenerator;

public class WorldGenRealMagic extends WorldGenerator
{

	@Override
	public boolean generate(World world, Random rand, int i, int j, int k) 
	{	
		world.setBlock(i + 4, j + 22, k + 47, Block.leaves.blockID, 12, 2);
		world.setBlock(i + 5, j + 20, k + 45, Block.leaves.blockID, 12, 2);
		world.setBlock(i + 5, j + 21, k + 46, Block.leaves.blockID, 12, 2);
		world.setBlock(i + 5, j + 22, k + 47, Block.leaves.blockID, 12, 2);
		world.setBlock(i + 5, j + 23, k + 47, Block.leaves.blockID, 12, 2);
		world.setBlock(i + 5, j + 24, k + 47, Block.leaves.blockID, 12, 2);
		world.setBlock(i + 6, j + 20, k + 44, Block.leaves.blockID, 12, 2);
		world.setBlock(i + 6, j + 20, k + 45, Block.leaves.blockID, 12, 2);
		world.setBlock(i + 6, j + 21, k + 46, Block.leaves.blockID, 12, 2);
		world.setBlock(i + 6, j + 21, k + 47, Block.leaves.blockID, 12, 2);
		world.setBlock(i + 6, j + 21, k + 49, Block.leaves.blockID, 12, 2);
		world.setBlock(i + 6, j + 21, k + 50, Block.leaves.blockID, 12, 2);
		world.setBlock(i + 6, j + 22, k + 47, Block.leaves.blockID, 12, 2);
		world.setBlock(i + 6, j + 22, k + 48, Block.leaves.blockID, 12, 2);
		world.setBlock(i + 6, j + 23, k + 47, Block.leaves.blockID, 12, 2);
		world.setBlock(i + 6, j + 24, k + 47, Block.leaves.blockID, 12, 2);
		world.setBlock(i + 6, j + 24, k + 49, Block.leaves.blockID, 12, 2);
		world.setBlock(i + 6, j + 25, k + 49, Block.leaves.blockID, 12, 2);
		world.setBlock(i + 6, j + 26, k + 49, Block.leaves.blockID, 12, 2);
		world.setBlock(i + 6, j + 27, k + 49, Block.leaves.blockID, 12, 2);
		world.setBlock(i + 6, j + 28, k + 36, Block.leaves.blockID, 12, 2);
		world.setBlock(i + 6, j + 28, k + 37, Block.leaves.blockID, 12, 2);
		world.setBlock(i + 6, j + 28, k + 38, Block.leaves.blockID, 12, 2);
		world.setBlock(i + 6, j + 29, k + 34, Block.leaves.blockID, 12, 2);
		world.setBlock(i + 6, j + 29, k + 35, Block.leaves.blockID, 12, 2);
		world.setBlock(i + 6, j + 29, k + 36, Block.leaves.blockID, 12, 2);
		world.setBlock(i + 7, j + 19, k + 44, Block.leaves.blockID, 12, 2);
		world.setBlock(i + 7, j + 20, k + 44, Block.leaves.blockID, 12, 2);
		world.setBlock(i + 7, j + 20, k + 45, Block.leaves.blockID, 12, 2);
		world.setBlock(i + 7, j + 21, k + 46, Block.leaves.blockID, 12, 2);
		world.setBlock(i + 7, j + 21, k + 47, Block.leaves.blockID, 12, 2);
		world.setBlock(i + 7, j + 21, k + 48, Block.leaves.blockID, 12, 2);
		world.setBlock(i + 7, j + 21, k + 49, Block.leaves.blockID, 12, 2);
		world.setBlock(i + 7, j + 21, k + 50, Block.leaves.blockID, 12, 2);
		world.setBlock(i + 7, j + 22, k + 47, Block.leaves.blockID, 12, 2);
		world.setBlock(i + 7, j + 23, k + 47, Block.leaves.blockID, 12, 2);
		world.setBlock(i + 7, j + 23, k + 49, Block.wood.blockID, 12, 2);
		world.setBlock(i + 7, j + 24, k + 47, Block.leaves.blockID, 12, 2);
		world.setBlock(i + 7, j + 24, k + 48, Block.leaves.blockID, 12, 2);
		world.setBlock(i + 7, j + 25, k + 48, Block.leaves.blockID, 12, 2);
		world.setBlock(i + 7, j + 25, k + 49, Block.leaves.blockID, 12, 2);
		world.setBlock(i + 7, j + 26, k + 49, Block.leaves.blockID, 12, 2);
		world.setBlock(i + 7, j + 27, k + 38, Block.leaves.blockID, 12, 2);
		world.setBlock(i + 7, j + 27, k + 39, Block.leaves.blockID, 12, 2);
		world.setBlock(i + 7, j + 27, k + 49, Block.leaves.blockID, 12, 2);
		world.setBlock(i + 7, j + 28, k + 33, Block.leaves.blockID, 12, 2);
		world.setBlock(i + 7, j + 28, k + 34, Block.leaves.blockID, 12, 2);
		world.setBlock(i + 7, j + 28, k + 35, Block.leaves.blockID, 12, 2);
		world.setBlock(i + 7, j + 28, k + 36, Block.leaves.blockID, 12, 2);
		world.setBlock(i + 7, j + 28, k + 37, Block.leaves.blockID, 12, 2);
		world.setBlock(i + 7, j + 29, k + 35, Block.leaves.blockID, 12, 2);
		world.setBlock(i + 7, j + 29, k + 36, Block.leaves.blockID, 12, 2);
		world.setBlock(i + 8, j + 19, k + 44, Block.leaves.blockID, 12, 2);
		world.setBlock(i + 8, j + 20, k + 44, Block.leaves.blockID, 12, 2);
		world.setBlock(i + 8, j + 20, k + 45, Block.leaves.blockID, 12, 2);
		world.setBlock(i + 8, j + 21, k + 46, Block.leaves.blockID, 12, 2);
		world.setBlock(i + 8, j + 21, k + 47, Block.leaves.blockID, 12, 2);
		world.setBlock(i + 8, j + 21, k + 48, Block.leaves.blockID, 12, 2);
		world.setBlock(i + 8, j + 21, k + 49, Block.leaves.blockID, 12, 2);
		world.setBlock(i + 8, j + 21, k + 50, Block.leaves.blockID, 12, 2);
		world.setBlock(i + 8, j + 22, k + 47, Block.leaves.blockID, 12, 2);
		world.setBlock(i + 8, j + 23, k + 46, Block.leaves.blockID, 12, 2);
		world.setBlock(i + 8, j + 23, k + 47, Block.leaves.blockID, 12, 2);
		world.setBlock(i + 8, j + 23, k + 48, Block.wood.blockID, 12, 2);
		world.setBlock(i + 8, j + 23, k + 49, Block.wood.blockID, 12, 2);
		world.setBlock(i + 8, j + 24, k + 41, Block.leaves.blockID, 12, 2);
		world.setBlock(i + 8, j + 24, k + 42, Block.leaves.blockID, 12, 2);
		world.setBlock(i + 8, j + 24, k + 44, Block.leaves.blockID, 12, 2);
		world.setBlock(i + 8, j + 24, k + 45, Block.leaves.blockID, 12, 2);
		world.setBlock(i + 8, j + 24, k + 46, Block.leaves.blockID, 12, 2);
		world.setBlock(i + 8, j + 24, k + 47, Block.leaves.blockID, 12, 2);
		world.setBlock(i + 8, j + 24, k + 48, Block.leaves.blockID, 12, 2);
		world.setBlock(i + 8, j + 25, k + 41, Block.leaves.blockID, 12, 2);
		world.setBlock(i + 8, j + 25, k + 42, Block.leaves.blockID, 12, 2);
		world.setBlock(i + 8, j + 25, k + 43, Block.leaves.blockID, 12, 2);
		world.setBlock(i + 8, j + 25, k + 48, Block.leaves.blockID, 12, 2);
		world.setBlock(i + 8, j + 26, k + 39, Block.leaves.blockID, 12, 2);
		world.setBlock(i + 8, j + 26, k + 43, Block.leaves.blockID, 12, 2);
		world.setBlock(i + 8, j + 26, k + 48, Block.leaves.blockID, 12, 2);
		world.setBlock(i + 8, j + 27, k + 33, Block.leaves.blockID, 12, 2);
		world.setBlock(i + 8, j + 27, k + 34, Block.leaves.blockID, 12, 2);
		world.setBlock(i + 8, j + 27, k + 37, Block.leaves.blockID, 12, 2);
		world.setBlock(i + 8, j + 27, k + 38, Block.leaves.blockID, 12, 2);
		world.setBlock(i + 8, j + 27, k + 39, Block.leaves.blockID, 12, 2);
		world.setBlock(i + 8, j + 27, k + 48, Block.leaves.blockID, 12, 2);
		world.setBlock(i + 8, j + 28, k + 34, Block.leaves.blockID, 12, 2);
		world.setBlock(i + 8, j + 28, k + 35, Block.leaves.blockID, 12, 2);
		world.setBlock(i + 8, j + 28, k + 36, Block.leaves.blockID, 12, 2);
		world.setBlock(i + 8, j + 28, k + 37, Block.leaves.blockID, 12, 2);
		world.setBlock(i + 8, j + 28, k + 47, Block.leaves.blockID, 12, 2);
		world.setBlock(i + 8, j + 28, k + 48, Block.leaves.blockID, 12, 2);
		world.setBlock(i + 8, j + 28, k + 49, Block.leaves.blockID, 12, 2);
		world.setBlock(i + 8, j + 29, k + 36, Block.leaves.blockID, 12, 2);
		world.setBlock(i + 8, j + 29, k + 47, Block.leaves.blockID, 12, 2);
		world.setBlock(i + 8, j + 29, k + 48, Block.leaves.blockID, 12, 2);
		world.setBlock(i + 8, j + 30, k + 36, Block.leaves.blockID, 12, 2);
		world.setBlock(i + 9, j + 19, k + 44, Block.leaves.blockID, 12, 2);
		world.setBlock(i + 9, j + 20, k + 44, Block.leaves.blockID, 12, 2);
		world.setBlock(i + 9, j + 20, k + 45, Block.leaves.blockID, 12, 2);
		world.setBlock(i + 9, j + 21, k + 46, Block.leaves.blockID, 12, 2);
		world.setBlock(i + 9, j + 21, k + 47, Block.leaves.blockID, 12, 2);
		world.setBlock(i + 9, j + 21, k + 48, Block.leaves.blockID, 12, 2);
		world.setBlock(i + 9, j + 21, k + 49, Block.leaves.blockID, 12, 2);
		world.setBlock(i + 9, j + 21, k + 50, Block.leaves.blockID, 12, 2);
		world.setBlock(i + 9, j + 22, k + 46, Block.leaves.blockID, 12, 2);
		world.setBlock(i + 9, j + 22, k + 47, Block.leaves.blockID, 12, 2);
		world.setBlock(i + 9, j + 22, k + 48, Block.wood.blockID, 12, 2);
		world.setBlock(i + 9, j + 23, k + 41, Block.leaves.blockID, 12, 2);
		world.setBlock(i + 9, j + 23, k + 45, Block.leaves.blockID, 12, 2);
		world.setBlock(i + 9, j + 23, k + 46, Block.leaves.blockID, 12, 2);
		world.setBlock(i + 9, j + 23, k + 47, Block.leaves.blockID, 12, 2);
		world.setBlock(i + 9, j + 23, k + 48, Block.wood.blockID, 12, 2);
		world.setBlock(i + 9, j + 24, k + 41, Block.leaves.blockID, 12, 2);
		world.setBlock(i + 9, j + 24, k + 42, Block.leaves.blockID, 12, 2);
		world.setBlock(i + 9, j + 24, k + 43, Block.leaves.blockID, 12, 2);
		world.setBlock(i + 9, j + 24, k + 44, Block.leaves.blockID, 12, 2);
		world.setBlock(i + 9, j + 24, k + 48, Block.leaves.blockID, 12, 2);
		world.setBlock(i + 9, j + 25, k + 38, Block.leaves.blockID, 12, 2);
		world.setBlock(i + 9, j + 25, k + 39, Block.leaves.blockID, 12, 2);
		world.setBlock(i + 9, j + 25, k + 40, Block.leaves.blockID, 12, 2);
		world.setBlock(i + 9, j + 25, k + 41, Block.leaves.blockID, 12, 2);
		world.setBlock(i + 9, j + 25, k + 43, Block.leaves.blockID, 12, 2);
		world.setBlock(i + 9, j + 25, k + 48, Block.leaves.blockID, 12, 2);
		world.setBlock(i + 9, j + 26, k + 39, Block.leaves.blockID, 12, 2);
		world.setBlock(i + 9, j + 26, k + 40, Block.leaves.blockID, 12, 2);
		world.setBlock(i + 9, j + 26, k + 42, Block.leaves.blockID, 12, 2);
		world.setBlock(i + 9, j + 26, k + 43, Block.leaves.blockID, 12, 2);
		world.setBlock(i + 9, j + 26, k + 47, Block.leaves.blockID, 12, 2);
		world.setBlock(i + 9, j + 26, k + 48, Block.leaves.blockID, 12, 2);
		world.setBlock(i + 9, j + 27, k + 33, Block.leaves.blockID, 12, 2);
		world.setBlock(i + 9, j + 27, k + 34, Block.leaves.blockID, 12, 2);
		world.setBlock(i + 9, j + 27, k + 35, Block.leaves.blockID, 12, 2);
		world.setBlock(i + 9, j + 27, k + 37, Block.leaves.blockID, 12, 2);
		world.setBlock(i + 9, j + 27, k + 38, Block.leaves.blockID, 12, 2);
		world.setBlock(i + 9, j + 27, k + 39, Block.leaves.blockID, 12, 2);
		world.setBlock(i + 9, j + 27, k + 40, Block.leaves.blockID, 12, 2);
		world.setBlock(i + 9, j + 27, k + 45, Block.leaves.blockID, 12, 2);
		world.setBlock(i + 9, j + 27, k + 46, Block.leaves.blockID, 12, 2);
		world.setBlock(i + 9, j + 27, k + 47, Block.leaves.blockID, 12, 2);
		world.setBlock(i + 9, j + 27, k + 48, Block.leaves.blockID, 12, 2);
		world.setBlock(i + 9, j + 27, k + 49, Block.leaves.blockID, 12, 2);
		world.setBlock(i + 9, j + 28, k + 35, Block.leaves.blockID, 12, 2);
		world.setBlock(i + 9, j + 28, k + 36, Block.leaves.blockID, 12, 2);
		world.setBlock(i + 9, j + 28, k + 45, Block.leaves.blockID, 12, 2);
		world.setBlock(i + 9, j + 28, k + 46, Block.leaves.blockID, 12, 2);
		world.setBlock(i + 9, j + 28, k + 47, Block.leaves.blockID, 12, 2);
		world.setBlock(i + 9, j + 28, k + 49, Block.leaves.blockID, 12, 2);
		world.setBlock(i + 9, j + 28, k + 50, Block.leaves.blockID, 12, 2);
		world.setBlock(i + 9, j + 29, k + 36, Block.leaves.blockID, 12, 2);
		world.setBlock(i + 9, j + 29, k + 50, Block.leaves.blockID, 12, 2);
		world.setBlock(i + 9, j + 30, k + 36, Block.leaves.blockID, 12, 2);
		world.setBlock(i + 10, j + 20, k + 44, Block.leaves.blockID, 12, 2);
		world.setBlock(i + 10, j + 20, k + 45, Block.leaves.blockID, 12, 2);
		world.setBlock(i + 10, j + 21, k + 46, Block.leaves.blockID, 12, 2);
		world.setBlock(i + 10, j + 21, k + 47, Block.leaves.blockID, 12, 2);
		world.setBlock(i + 10, j + 21, k + 48, Block.leaves.blockID, 12, 2);
		world.setBlock(i + 10, j + 21, k + 49, Block.leaves.blockID, 12, 2);
		world.setBlock(i + 10, j + 22, k + 41, Block.leaves.blockID, 12, 2);
		world.setBlock(i + 10, j + 22, k + 45, Block.leaves.blockID, 12, 2);
		world.setBlock(i + 10, j + 22, k + 46, Block.leaves.blockID, 12, 2);
		world.setBlock(i + 10, j + 22, k + 47, Block.leaves.blockID, 12, 2);
		world.setBlock(i + 10, j + 22, k + 48, Block.wood.blockID, 12, 2);
		world.setBlock(i + 10, j + 22, k + 49, Block.leaves.blockID, 12, 2);
		world.setBlock(i + 10, j + 22, k + 50, Block.leaves.blockID, 12, 2);
		world.setBlock(i + 10, j + 23, k + 41, Block.leaves.blockID, 12, 2);
		world.setBlock(i + 10, j + 23, k + 42, Block.leaves.blockID, 12, 2);
		world.setBlock(i + 10, j + 23, k + 43, Block.leaves.blockID, 12, 2);
		world.setBlock(i + 10, j + 23, k + 44, Block.leaves.blockID, 12, 2);
		world.setBlock(i + 10, j + 23, k + 45, Block.leaves.blockID, 12, 2);
		world.setBlock(i + 10, j + 23, k + 47, Block.leaves.blockID, 12, 2);
		world.setBlock(i + 10, j + 23, k + 50, Block.leaves.blockID, 12, 2);
		world.setBlock(i + 10, j + 23, k + 51, Block.leaves.blockID, 12, 2);
		world.setBlock(i + 10, j + 24, k + 40, Block.leaves.blockID, 12, 2);
		world.setBlock(i + 10, j + 24, k + 43, Block.leaves.blockID, 12, 2);
		world.setBlock(i + 10, j + 24, k + 44, Block.leaves.blockID, 12, 2);
		world.setBlock(i + 10, j + 24, k + 47, Block.leaves.blockID, 12, 2);
		world.setBlock(i + 10, j + 25, k + 38, Block.leaves.blockID, 12, 2);
		world.setBlock(i + 10, j + 25, k + 39, Block.leaves.blockID, 12, 2);
		world.setBlock(i + 10, j + 25, k + 40, Block.leaves.blockID, 12, 2);
		world.setBlock(i + 10, j + 25, k + 41, Block.leaves.blockID, 12, 2);
		world.setBlock(i + 10, j + 25, k + 42, Block.leaves.blockID, 12, 2);
		world.setBlock(i + 10, j + 25, k + 43, Block.leaves.blockID, 12, 2);
		world.setBlock(i + 10, j + 25, k + 44, Block.leaves.blockID, 12, 2);
		world.setBlock(i + 10, j + 25, k + 45, Block.leaves.blockID, 12, 2);
		world.setBlock(i + 10, j + 25, k + 46, Block.leaves.blockID, 12, 2);
		world.setBlock(i + 10, j + 25, k + 47, Block.leaves.blockID, 12, 2);
		world.setBlock(i + 10, j + 25, k + 48, Block.leaves.blockID, 12, 2);
		world.setBlock(i + 10, j + 26, k + 31, Block.leaves.blockID, 4, 2);
		world.setBlock(i + 10, j + 26, k + 33, Block.leaves.blockID, 12, 2);
		world.setBlock(i + 10, j + 26, k + 34, Block.leaves.blockID, 12, 2);
		world.setBlock(i + 10, j + 26, k + 38, Block.leaves.blockID, 12, 2);
		world.setBlock(i + 10, j + 26, k + 39, Block.leaves.blockID, 12, 2);
		world.setBlock(i + 10, j + 26, k + 40, Block.leaves.blockID, 12, 2);
		world.setBlock(i + 10, j + 26, k + 41, Block.leaves.blockID, 12, 2);
		world.setBlock(i + 10, j + 26, k + 42, Block.leaves.blockID, 12, 2);
		world.setBlock(i + 10, j + 26, k + 43, Block.leaves.blockID, 12, 2);
		world.setBlock(i + 10, j + 26, k + 44, Block.leaves.blockID, 12, 2);
		world.setBlock(i + 10, j + 26, k + 45, Block.leaves.blockID, 12, 2);
		world.setBlock(i + 10, j + 26, k + 46, Block.leaves.blockID, 12, 2);
		world.setBlock(i + 10, j + 26, k + 47, Block.leaves.blockID, 12, 2);
		world.setBlock(i + 10, j + 26, k + 48, Block.leaves.blockID, 12, 2);
		world.setBlock(i + 10, j + 26, k + 49, Block.leaves.blockID, 12, 2);
		world.setBlock(i + 10, j + 27, k + 30, Block.leaves.blockID, 4, 2);
		world.setBlock(i + 10, j + 27, k + 34, Block.leaves.blockID, 12, 2);
		world.setBlock(i + 10, j + 27, k + 35, Block.leaves.blockID, 12, 2);
		world.setBlock(i + 10, j + 27, k + 36, Block.leaves.blockID, 12, 2);
		world.setBlock(i + 10, j + 27, k + 37, Block.leaves.blockID, 12, 2);
		world.setBlock(i + 10, j + 27, k + 38, Block.leaves.blockID, 12, 2);
		world.setBlock(i + 10, j + 27, k + 39, Block.leaves.blockID, 12, 2);
		world.setBlock(i + 10, j + 27, k + 40, Block.leaves.blockID, 12, 2);
		world.setBlock(i + 10, j + 27, k + 41, Block.leaves.blockID, 12, 2);
		world.setBlock(i + 10, j + 27, k + 44, Block.leaves.blockID, 12, 2);
		world.setBlock(i + 10, j + 27, k + 45, Block.leaves.blockID, 12, 2);
		world.setBlock(i + 10, j + 27, k + 49, Block.leaves.blockID, 12, 2);
		world.setBlock(i + 10, j + 27, k + 50, Block.leaves.blockID, 12, 2);
		world.setBlock(i + 10, j + 28, k + 36, Block.leaves.blockID, 12, 2);
		world.setBlock(i + 10, j + 28, k + 37, Block.leaves.blockID, 12, 2);
		world.setBlock(i + 10, j + 28, k + 50, Block.leaves.blockID, 12, 2);
		world.setBlock(i + 10, j + 29, k + 36, Block.leaves.blockID, 12, 2);
		world.setBlock(i + 10, j + 29, k + 37, Block.wood.blockID, 12, 2);
		world.setBlock(i + 10, j + 30, k + 37, Block.leaves.blockID, 12, 2);
		world.setBlock(i + 10, j + 40, k + 45, Block.wood.blockID);
		world.setBlock(i + 11, j + 20, k + 45, Block.leaves.blockID, 12, 2);
		world.setBlock(i + 11, j + 21, k + 46, Block.leaves.blockID, 12, 2);
		world.setBlock(i + 11, j + 21, k + 47, Block.wood.blockID, 12, 2);
		world.setBlock(i + 11, j + 21, k + 48, Block.leaves.blockID, 12, 2);
		world.setBlock(i + 11, j + 22, k + 39, Block.leaves.blockID, 12, 2);
		world.setBlock(i + 11, j + 22, k + 41, Block.leaves.blockID, 12, 2);
		world.setBlock(i + 11, j + 22, k + 42, Block.leaves.blockID, 12, 2);
		world.setBlock(i + 11, j + 22, k + 43, Block.leaves.blockID, 12, 2);
		world.setBlock(i + 11, j + 22, k + 44, Block.leaves.blockID, 12, 2);
		world.setBlock(i + 11, j + 22, k + 45, Block.leaves.blockID, 12, 2);
		world.setBlock(i + 11, j + 22, k + 46, Block.leaves.blockID, 12, 2);
		world.setBlock(i + 11, j + 22, k + 47, Block.leaves.blockID, 12, 2);
		world.setBlock(i + 11, j + 22, k + 48, Block.leaves.blockID, 12, 2);
		world.setBlock(i + 11, j + 22, k + 49, Block.leaves.blockID, 12, 2);
		world.setBlock(i + 11, j + 23, k + 41, Block.leaves.blockID, 12, 2);
		world.setBlock(i + 11, j + 23, k + 42, Block.leaves.blockID, 12, 2);
		world.setBlock(i + 11, j + 23, k + 43, Block.leaves.blockID, 12, 2);
		world.setBlock(i + 11, j + 23, k + 44, Block.leaves.blockID, 12, 2);
		world.setBlock(i + 11, j + 23, k + 46, Block.leaves.blockID, 12, 2);
		world.setBlock(i + 11, j + 23, k + 47, Block.leaves.blockID, 12, 2);
		world.setBlock(i + 11, j + 23, k + 50, Block.leaves.blockID, 12, 2);
		world.setBlock(i + 11, j + 23, k + 51, Block.leaves.blockID, 12, 2);
		world.setBlock(i + 11, j + 24, k + 39, Block.leaves.blockID, 12, 2);
		world.setBlock(i + 11, j + 24, k + 44, Block.leaves.blockID, 12, 2);
		world.setBlock(i + 11, j + 24, k + 45, Block.leaves.blockID, 12, 2);
		world.setBlock(i + 11, j + 24, k + 46, Block.leaves.blockID, 12, 2);
		world.setBlock(i + 11, j + 24, k + 47, Block.leaves.blockID, 12, 2);
		world.setBlock(i + 11, j + 24, k + 48, Block.leaves.blockID, 12, 2);
		world.setBlock(i + 11, j + 25, k + 32, Block.leaves.blockID, 4, 2);
		world.setBlock(i + 11, j + 25, k + 37, Block.leaves.blockID, 12, 2);
		world.setBlock(i + 11, j + 25, k + 38, Block.leaves.blockID, 12, 2);
		world.setBlock(i + 11, j + 25, k + 39, Block.leaves.blockID, 12, 2);
		world.setBlock(i + 11, j + 25, k + 41, Block.leaves.blockID, 12, 2);
		world.setBlock(i + 11, j + 25, k + 42, Block.leaves.blockID, 12, 2);
		world.setBlock(i + 11, j + 25, k + 43, Block.leaves.blockID, 12, 2);
		world.setBlock(i + 11, j + 25, k + 44, Block.leaves.blockID, 12, 2);
		world.setBlock(i + 11, j + 25, k + 45, Block.leaves.blockID, 12, 2);
		world.setBlock(i + 11, j + 25, k + 46, Block.leaves.blockID, 12, 2);
		world.setBlock(i + 11, j + 25, k + 48, Block.leaves.blockID, 12, 2);
		world.setBlock(i + 11, j + 25, k + 49, Block.leaves.blockID, 12, 2);
		world.setBlock(i + 11, j + 26, k + 27, Block.leaves.blockID, 12, 2);
		world.setBlock(i + 11, j + 26, k + 28, Block.leaves.blockID, 12, 2);
		world.setBlock(i + 11, j + 26, k + 31, Block.leaves.blockID, 4, 2);
		world.setBlock(i + 11, j + 26, k + 32, Block.leaves.blockID, 4, 2);
		world.setBlock(i + 11, j + 26, k + 33, Block.leaves.blockID, 12, 2);
		world.setBlock(i + 11, j + 26, k + 34, Block.leaves.blockID, 12, 2);
		world.setBlock(i + 11, j + 26, k + 35, Block.leaves.blockID, 12, 2);
		world.setBlock(i + 11, j + 26, k + 36, Block.leaves.blockID, 12, 2);
		world.setBlock(i + 11, j + 26, k + 38, Block.leaves.blockID, 12, 2);
		world.setBlock(i + 11, j + 26, k + 39, Block.leaves.blockID, 12, 2);
		world.setBlock(i + 11, j + 26, k + 41, Block.leaves.blockID, 12, 2);
		world.setBlock(i + 11, j + 26, k + 42, Block.leaves.blockID, 12, 2);
		world.setBlock(i + 11, j + 26, k + 43, Block.leaves.blockID, 12, 2);
		world.setBlock(i + 11, j + 26, k + 44, Block.leaves.blockID, 12, 2);
		world.setBlock(i + 11, j + 26, k + 47, Block.wood.blockID, 12, 2);
		world.setBlock(i + 11, j + 26, k + 49, Block.leaves.blockID, 12, 2);
		world.setBlock(i + 11, j + 27, k + 28, Block.leaves.blockID, 12, 2);
		world.setBlock(i + 11, j + 27, k + 29, Block.leaves.blockID, 12, 2);
		world.setBlock(i + 11, j + 27, k + 30, Block.leaves.blockID, 4, 2);
		world.setBlock(i + 11, j + 27, k + 35, Block.leaves.blockID, 12, 2);
		world.setBlock(i + 11, j + 27, k + 36, Block.leaves.blockID, 12, 2);
		world.setBlock(i + 11, j + 27, k + 37, Block.leaves.blockID, 12, 2);
		world.setBlock(i + 11, j + 27, k + 38, Block.leaves.blockID, 12, 2);
		world.setBlock(i + 11, j + 27, k + 39, Block.leaves.blockID, 12, 2);
		world.setBlock(i + 11, j + 27, k + 50, Block.leaves.blockID, 12, 2);
		world.setBlock(i + 11, j + 28, k + 30, Block.leaves.blockID, 4, 2);
		world.setBlock(i + 11, j + 28, k + 35, Block.leaves.blockID, 12, 2);
		world.setBlock(i + 11, j + 28, k + 37, Block.wood.blockID, 12, 2);
		world.setBlock(i + 11, j + 28, k + 50, Block.leaves.blockID, 12, 2);
		world.setBlock(i + 11, j + 28, k + 51, Block.leaves.blockID, 12, 2);
		world.setBlock(i + 11, j + 29, k + 35, Block.leaves.blockID, 12, 2);
		world.setBlock(i + 11, j + 29, k + 37, Block.leaves.blockID, 12, 2);
		world.setBlock(i + 11, j + 30, k + 35, Block.leaves.blockID, 12, 2);
		world.setBlock(i + 11, j + 30, k + 37, Block.leaves.blockID, 12, 2);
		world.setBlock(i + 11, j + 36, k + 45, Block.leaves.blockID, 12, 2);
		world.setBlock(i + 11, j + 40, k + 45, Block.wood.blockID);
		world.setBlock(i + 11, j + 42, k + 44, Block.leaves.blockID, 12, 2);
		world.setBlock(i + 11, j + 43, k + 45, Block.leaves.blockID, 12, 2);
		world.setBlock(i + 11, j + 44, k + 45, Block.leaves.blockID, 4, 2);
		world.setBlock(i + 11, j + 45, k + 45, Block.leaves.blockID, 4, 2);
		world.setBlock(i + 11, j + 46, k + 45, Block.leaves.blockID, 4, 2);
		world.setBlock(i + 12, j + 18, k + 45, Block.leaves.blockID, 12, 2);
		world.setBlock(i + 12, j + 18, k + 46, Block.leaves.blockID, 12, 2);
		world.setBlock(i + 12, j + 19, k + 43, Block.leaves.blockID, 12, 2);
		world.setBlock(i + 12, j + 19, k + 47, Block.leaves.blockID, 12, 2);
		world.setBlock(i + 12, j + 20, k + 49, Block.leaves.blockID, 12, 2);
		world.setBlock(i + 12, j + 20, k + 50, Block.leaves.blockID, 12, 2);
		world.setBlock(i + 12, j + 21, k + 40, Block.leaves.blockID, 12, 2);
		world.setBlock(i + 12, j + 21, k + 41, Block.leaves.blockID, 12, 2);
		world.setBlock(i + 12, j + 21, k + 42, Block.leaves.blockID, 12, 2);
		world.setBlock(i + 12, j + 21, k + 45, Block.leaves.blockID, 12, 2);
		world.setBlock(i + 12, j + 21, k + 46, Block.leaves.blockID, 12, 2);
		world.setBlock(i + 12, j + 21, k + 47, Block.wood.blockID, 12, 2);
		world.setBlock(i + 12, j + 21, k + 48, Block.leaves.blockID, 12, 2);
		world.setBlock(i + 12, j + 21, k + 51, Block.leaves.blockID, 12, 2);
		world.setBlock(i + 12, j + 21, k + 52, Block.leaves.blockID, 12, 2);
		world.setBlock(i + 12, j + 22, k + 39, Block.leaves.blockID, 12, 2);
		world.setBlock(i + 12, j + 22, k + 40, Block.leaves.blockID, 12, 2);
		world.setBlock(i + 12, j + 22, k + 41, Block.leaves.blockID, 12, 2);
		world.setBlock(i + 12, j + 22, k + 42, Block.leaves.blockID, 12, 2);
		world.setBlock(i + 12, j + 22, k + 43, Block.leaves.blockID, 12, 2);
		world.setBlock(i + 12, j + 22, k + 44, Block.leaves.blockID, 12, 2);
		world.setBlock(i + 12, j + 22, k + 45, Block.leaves.blockID, 12, 2);
		world.setBlock(i + 12, j + 22, k + 46, Block.leaves.blockID, 12, 2);
		world.setBlock(i + 12, j + 22, k + 47, Block.leaves.blockID, 12, 2);
		world.setBlock(i + 12, j + 22, k + 48, Block.leaves.blockID, 12, 2);
		world.setBlock(i + 12, j + 22, k + 49, Block.leaves.blockID, 12, 2);
		world.setBlock(i + 12, j + 23, k + 32, Block.leaves.blockID, 4, 2);
		world.setBlock(i + 12, j + 23, k + 38, Block.leaves.blockID, 12, 2);
		world.setBlock(i + 12, j + 23, k + 40, Block.leaves.blockID, 12, 2);
		world.setBlock(i + 12, j + 23, k + 44, Block.leaves.blockID, 12, 2);
		world.setBlock(i + 12, j + 23, k + 46, Block.leaves.blockID, 12, 2);
		world.setBlock(i + 12, j + 23, k + 47, Block.leaves.blockID, 12, 2);
		world.setBlock(i + 12, j + 23, k + 48, Block.leaves.blockID, 12, 2);
		world.setBlock(i + 12, j + 23, k + 49, Block.leaves.blockID, 12, 2);
		world.setBlock(i + 12, j + 23, k + 50, Block.leaves.blockID, 12, 2);
		world.setBlock(i + 12, j + 24, k + 38, Block.leaves.blockID, 12, 2);
		world.setBlock(i + 12, j + 24, k + 39, Block.leaves.blockID, 12, 2);
		world.setBlock(i + 12, j + 24, k + 40, Block.leaves.blockID, 12, 2);
		world.setBlock(i + 12, j + 24, k + 41, Block.leaves.blockID, 12, 2);
		world.setBlock(i + 12, j + 24, k + 44, Block.leaves.blockID, 12, 2);
		world.setBlock(i + 12, j + 24, k + 48, Block.leaves.blockID, 12, 2);
		world.setBlock(i + 12, j + 24, k + 49, Block.leaves.blockID, 12, 2);
		world.setBlock(i + 12, j + 24, k + 50, Block.leaves.blockID, 12, 2);
		world.setBlock(i + 12, j + 24, k + 51, Block.leaves.blockID, 12, 2);
		world.setBlock(i + 12, j + 25, k + 31, Block.leaves.blockID, 12, 2);
		world.setBlock(i + 12, j + 25, k + 32, Block.leaves.blockID, 4, 2);
		world.setBlock(i + 12, j + 25, k + 34, Block.leaves.blockID, 12, 2);
		world.setBlock(i + 12, j + 25, k + 37, Block.leaves.blockID, 12, 2);
		world.setBlock(i + 12, j + 25, k + 38, Block.leaves.blockID, 12, 2);
		world.setBlock(i + 12, j + 25, k + 39, Block.leaves.blockID, 12, 2);
		world.setBlock(i + 12, j + 25, k + 40, Block.leaves.blockID, 12, 2);
		world.setBlock(i + 12, j + 25, k + 41, Block.leaves.blockID, 12, 2);
		world.setBlock(i + 12, j + 25, k + 42, Block.leaves.blockID, 12, 2);
		world.setBlock(i + 12, j + 25, k + 44, Block.leaves.blockID, 12, 2);
		world.setBlock(i + 12, j + 25, k + 49, Block.leaves.blockID, 12, 2);
		world.setBlock(i + 12, j + 25, k + 50, Block.leaves.blockID, 12, 2);
		world.setBlock(i + 12, j + 25, k + 51, Block.leaves.blockID, 12, 2);
		world.setBlock(i + 12, j + 26, k + 27, Block.leaves.blockID, 12, 2);
		world.setBlock(i + 12, j + 26, k + 28, Block.leaves.blockID, 12, 2);
		world.setBlock(i + 12, j + 26, k + 29, Block.leaves.blockID, 12, 2);
		world.setBlock(i + 12, j + 26, k + 30, Block.leaves.blockID, 12, 2);
		world.setBlock(i + 12, j + 26, k + 31, Block.leaves.blockID, 12, 2);
		world.setBlock(i + 12, j + 26, k + 34, Block.leaves.blockID, 12, 2);
		world.setBlock(i + 12, j + 26, k + 35, Block.leaves.blockID, 12, 2);
		world.setBlock(i + 12, j + 26, k + 36, Block.leaves.blockID, 12, 2);
		world.setBlock(i + 12, j + 26, k + 37, Block.wood.blockID, 12, 2);
		world.setBlock(i + 12, j + 26, k + 38, Block.leaves.blockID, 12, 2);
		world.setBlock(i + 12, j + 26, k + 39, Block.leaves.blockID, 12, 2);
		world.setBlock(i + 12, j + 26, k + 40, Block.leaves.blockID, 12, 2);
		world.setBlock(i + 12, j + 26, k + 41, Block.leaves.blockID, 12, 2);
		world.setBlock(i + 12, j + 26, k + 42, Block.leaves.blockID, 12, 2);
		world.setBlock(i + 12, j + 26, k + 44, Block.leaves.blockID, 12, 2);
		world.setBlock(i + 12, j + 26, k + 46, Block.wood.blockID, 12, 2);
		world.setBlock(i + 12, j + 26, k + 47, Block.wood.blockID, 12, 2);
		world.setBlock(i + 12, j + 26, k + 49, Block.leaves.blockID, 12, 2);
		world.setBlock(i + 12, j + 26, k + 50, Block.leaves.blockID, 12, 2);
		world.setBlock(i + 12, j + 27, k + 30, Block.leaves.blockID, 12, 2);
		world.setBlock(i + 12, j + 27, k + 36, Block.leaves.blockID, 12, 2);
		world.setBlock(i + 12, j + 27, k + 37, Block.wood.blockID, 12, 2);
		world.setBlock(i + 12, j + 27, k + 39, Block.leaves.blockID, 12, 2);
		world.setBlock(i + 12, j + 27, k + 40, Block.leaves.blockID, 12, 2);
		world.setBlock(i + 12, j + 27, k + 46, Block.leaves.blockID, 12, 2);
		world.setBlock(i + 12, j + 27, k + 50, Block.leaves.blockID, 12, 2);
		world.setBlock(i + 12, j + 27, k + 51, Block.leaves.blockID, 12, 2);
		world.setBlock(i + 12, j + 28, k + 30, Block.leaves.blockID, 12, 2);
		world.setBlock(i + 12, j + 28, k + 36, Block.leaves.blockID, 12, 2);
		world.setBlock(i + 12, j + 28, k + 37, Block.leaves.blockID, 12, 2);
		world.setBlock(i + 12, j + 28, k + 45, Block.leaves.blockID, 12, 2);
		world.setBlock(i + 12, j + 28, k + 46, Block.leaves.blockID, 12, 2);
		world.setBlock(i + 12, j + 29, k + 35, Block.leaves.blockID, 12, 2);
		world.setBlock(i + 12, j + 29, k + 36, Block.leaves.blockID, 12, 2);
		world.setBlock(i + 12, j + 29, k + 37, Block.leaves.blockID, 12, 2);
		world.setBlock(i + 12, j + 29, k + 45, Block.leaves.blockID, 12, 2);
		world.setBlock(i + 12, j + 30, k + 35, Block.leaves.blockID, 12, 2);
		world.setBlock(i + 12, j + 30, k + 37, Block.leaves.blockID, 12, 2);
		world.setBlock(i + 12, j + 35, k + 46, Block.leaves.blockID, 12, 2);
		world.setBlock(i + 12, j + 35, k + 47, Block.leaves.blockID, 12, 2);
		world.setBlock(i + 12, j + 36, k + 40, Block.leaves.blockID, 4, 2);
		world.setBlock(i + 12, j + 36, k + 41, Block.leaves.blockID, 4, 2);
		world.setBlock(i + 12, j + 36, k + 44, Block.leaves.blockID, 12, 2);
		world.setBlock(i + 12, j + 36, k + 45, Block.leaves.blockID, 12, 2);
		world.setBlock(i + 12, j + 36, k + 46, Block.leaves.blockID, 12, 2);
		world.setBlock(i + 12, j + 37, k + 41, Block.leaves.blockID, 4, 2);
		world.setBlock(i + 12, j + 37, k + 42, Block.leaves.blockID, 12, 2);
		world.setBlock(i + 12, j + 39, k + 41, Block.leaves.blockID, 4, 2);
		world.setBlock(i + 12, j + 39, k + 46, Block.wood.blockID, 12, 2);
		world.setBlock(i + 12, j + 40, k + 41, Block.leaves.blockID, 4, 2);
		world.setBlock(i + 12, j + 41, k + 44, Block.leaves.blockID, 12, 2);
		world.setBlock(i + 12, j + 41, k + 45, Block.leaves.blockID, 12, 2);
		world.setBlock(i + 12, j + 42, k + 45, Block.leaves.blockID, 12, 2);
		world.setBlock(i + 12, j + 43, k + 45, Block.leaves.blockID, 12, 2);
		world.setBlock(i + 12, j + 44, k + 45, Block.leaves.blockID, 4, 2);
		world.setBlock(i + 12, j + 45, k + 45, Block.leaves.blockID, 4, 2);
		world.setBlock(i + 12, j + 46, k + 45, Block.leaves.blockID, 4, 2);
		world.setBlock(i + 13, j + 18, k + 42, Block.leaves.blockID, 12, 2);
		world.setBlock(i + 13, j + 18, k + 45, Block.leaves.blockID, 12, 2);
		world.setBlock(i + 13, j + 19, k + 43, Block.leaves.blockID, 12, 2);
		world.setBlock(i + 13, j + 19, k + 46, Block.leaves.blockID, 12, 2);
		world.setBlock(i + 13, j + 19, k + 47, Block.leaves.blockID, 12, 2);
		world.setBlock(i + 13, j + 20, k + 43, Block.leaves.blockID, 12, 2);
		world.setBlock(i + 13, j + 20, k + 46, Block.leaves.blockID, 12, 2);
		world.setBlock(i + 13, j + 20, k + 47, Block.leaves.blockID, 12, 2);
		world.setBlock(i + 13, j + 20, k + 48, Block.leaves.blockID, 12, 2);
		world.setBlock(i + 13, j + 20, k + 49, Block.leaves.blockID, 12, 2);
		world.setBlock(i + 13, j + 20, k + 50, Block.leaves.blockID, 12, 2);
		world.setBlock(i + 13, j + 21, k + 40, Block.leaves.blockID, 12, 2);
		world.setBlock(i + 13, j + 21, k + 41, Block.leaves.blockID, 12, 2);
		world.setBlock(i + 13, j + 21, k + 42, Block.leaves.blockID, 12, 2);
		world.setBlock(i + 13, j + 21, k + 43, Block.leaves.blockID, 12, 2);
		world.setBlock(i + 13, j + 21, k + 45, Block.leaves.blockID, 12, 2);
		world.setBlock(i + 13, j + 21, k + 46, Block.wood.blockID, 12, 2);
		world.setBlock(i + 13, j + 21, k + 47, Block.leaves.blockID, 12, 2);
		world.setBlock(i + 13, j + 21, k + 50, Block.leaves.blockID, 12, 2);
		world.setBlock(i + 13, j + 21, k + 51, Block.leaves.blockID, 12, 2);
		world.setBlock(i + 13, j + 21, k + 52, Block.leaves.blockID, 12, 2);
		world.setBlock(i + 13, j + 22, k + 33, Block.leaves.blockID, 12, 2);
		world.setBlock(i + 13, j + 22, k + 34, Block.leaves.blockID, 12, 2);
		world.setBlock(i + 13, j + 22, k + 35, Block.leaves.blockID, 12, 2);
		world.setBlock(i + 13, j + 22, k + 36, Block.leaves.blockID, 12, 2);
		world.setBlock(i + 13, j + 22, k + 37, Block.leaves.blockID, 12, 2);
		world.setBlock(i + 13, j + 22, k + 38, Block.leaves.blockID, 12, 2);
		world.setBlock(i + 13, j + 22, k + 39, Block.leaves.blockID, 12, 2);
		world.setBlock(i + 13, j + 22, k + 40, Block.leaves.blockID, 12, 2);
		world.setBlock(i + 13, j + 22, k + 41, Block.leaves.blockID, 12, 2);
		world.setBlock(i + 13, j + 22, k + 42, Block.leaves.blockID, 12, 2);
		world.setBlock(i + 13, j + 22, k + 45, Block.leaves.blockID, 12, 2);
		world.setBlock(i + 13, j + 22, k + 48, Block.leaves.blockID, 12, 2);
		world.setBlock(i + 13, j + 22, k + 49, Block.leaves.blockID, 12, 2);
		world.setBlock(i + 13, j + 22, k + 52, Block.leaves.blockID, 12, 2);
		world.setBlock(i + 13, j + 22, k + 53, Block.leaves.blockID, 4, 2);
		world.setBlock(i + 13, j + 22, k + 54, Block.leaves.blockID, 4, 2);
		world.setBlock(i + 13, j + 23, k + 32, Block.leaves.blockID, 12, 2);
		world.setBlock(i + 13, j + 23, k + 33, Block.leaves.blockID, 12, 2);
		world.setBlock(i + 13, j + 23, k + 34, Block.leaves.blockID, 12, 2);
		world.setBlock(i + 13, j + 23, k + 38, Block.leaves.blockID, 12, 2);
		world.setBlock(i + 13, j + 23, k + 39, Block.leaves.blockID, 12, 2);
		world.setBlock(i + 13, j + 23, k + 40, Block.leaves.blockID, 12, 2);
		world.setBlock(i + 13, j + 23, k + 48, Block.leaves.blockID, 12, 2);
		world.setBlock(i + 13, j + 23, k + 49, Block.leaves.blockID, 12, 2);
		world.setBlock(i + 13, j + 23, k + 50, Block.leaves.blockID, 12, 2);
		world.setBlock(i + 13, j + 23, k + 51, Block.leaves.blockID, 12, 2);
		world.setBlock(i + 13, j + 24, k + 32, Block.leaves.blockID, 12, 2);
		world.setBlock(i + 13, j + 24, k + 33, Block.leaves.blockID, 12, 2);
		world.setBlock(i + 13, j + 24, k + 34, Block.leaves.blockID, 12, 2);
		world.setBlock(i + 13, j + 24, k + 38, Block.leaves.blockID, 12, 2);
		world.setBlock(i + 13, j + 24, k + 39, Block.leaves.blockID, 12, 2);
		world.setBlock(i + 13, j + 24, k + 40, Block.leaves.blockID, 12, 2);
		world.setBlock(i + 13, j + 24, k + 41, Block.leaves.blockID, 12, 2);
		world.setBlock(i + 13, j + 24, k + 48, Block.leaves.blockID, 12, 2);
		world.setBlock(i + 13, j + 24, k + 49, Block.leaves.blockID, 12, 2);
		world.setBlock(i + 13, j + 24, k + 50, Block.leaves.blockID, 12, 2);
		world.setBlock(i + 13, j + 24, k + 51, Block.leaves.blockID, 12, 2);
		world.setBlock(i + 13, j + 24, k + 52, Block.leaves.blockID, 12, 2);
		world.setBlock(i + 13, j + 25, k + 27, Block.leaves.blockID, 12, 2);
		world.setBlock(i + 13, j + 25, k + 28, Block.leaves.blockID, 12, 2);
		world.setBlock(i + 13, j + 25, k + 31, Block.leaves.blockID, 12, 2);
		world.setBlock(i + 13, j + 25, k + 32, Block.leaves.blockID, 12, 2);
		world.setBlock(i + 13, j + 25, k + 34, Block.leaves.blockID, 12, 2);
		world.setBlock(i + 13, j + 25, k + 35, Block.leaves.blockID, 12, 2);
		world.setBlock(i + 13, j + 25, k + 36, Block.leaves.blockID, 12, 2);
		world.setBlock(i + 13, j + 25, k + 37, Block.leaves.blockID, 12, 2);
		world.setBlock(i + 13, j + 25, k + 39, Block.leaves.blockID, 12, 2);
		world.setBlock(i + 13, j + 25, k + 40, Block.leaves.blockID, 12, 2);
		world.setBlock(i + 13, j + 25, k + 41, Block.leaves.blockID, 12, 2);
		world.setBlock(i + 13, j + 25, k + 42, Block.leaves.blockID, 12, 2);
		world.setBlock(i + 13, j + 25, k + 46, Block.wood.blockID, 12, 2);
		world.setBlock(i + 13, j + 25, k + 48, Block.leaves.blockID, 12, 2);
		world.setBlock(i + 13, j + 25, k + 49, Block.leaves.blockID, 12, 2);
		world.setBlock(i + 13, j + 25, k + 50, Block.leaves.blockID, 12, 2);
		world.setBlock(i + 13, j + 26, k + 28, Block.leaves.blockID, 12, 2);
		world.setBlock(i + 13, j + 26, k + 29, Block.leaves.blockID, 12, 2);
		world.setBlock(i + 13, j + 26, k + 30, Block.leaves.blockID, 12, 2);
		world.setBlock(i + 13, j + 26, k + 37, Block.wood.blockID, 12, 2);
		world.setBlock(i + 13, j + 26, k + 38, Block.leaves.blockID, 12, 2);
		world.setBlock(i + 13, j + 26, k + 39, Block.leaves.blockID, 12, 2);
		world.setBlock(i + 13, j + 26, k + 40, Block.leaves.blockID, 12, 2);
		world.setBlock(i + 13, j + 26, k + 46, Block.wood.blockID, 12, 2);
		world.setBlock(i + 13, j + 26, k + 49, Block.leaves.blockID, 12, 2);
		world.setBlock(i + 13, j + 26, k + 50, Block.leaves.blockID, 12, 2);
		world.setBlock(i + 13, j + 26, k + 51, Block.leaves.blockID, 12, 2);
		world.setBlock(i + 13, j + 27, k + 30, Block.leaves.blockID, 12, 2);
		world.setBlock(i + 13, j + 27, k + 36, Block.leaves.blockID, 12, 2);
		world.setBlock(i + 13, j + 27, k + 37, Block.leaves.blockID, 12, 2);
		world.setBlock(i + 13, j + 27, k + 38, Block.leaves.blockID, 12, 2);
		world.setBlock(i + 13, j + 27, k + 39, Block.leaves.blockID, 12, 2);
		world.setBlock(i + 13, j + 27, k + 45, Block.leaves.blockID, 12, 2);
		world.setBlock(i + 13, j + 27, k + 51, Block.leaves.blockID, 12, 2);
		world.setBlock(i + 13, j + 28, k + 30, Block.leaves.blockID, 12, 2);
		world.setBlock(i + 13, j + 28, k + 36, Block.leaves.blockID, 12, 2);
		world.setBlock(i + 13, j + 28, k + 45, Block.leaves.blockID, 12, 2);
		world.setBlock(i + 13, j + 28, k + 48, Block.leaves.blockID, 12, 2);
		world.setBlock(i + 13, j + 29, k + 36, Block.leaves.blockID, 12, 2);
		world.setBlock(i + 13, j + 29, k + 45, Block.leaves.blockID, 12, 2);
		world.setBlock(i + 13, j + 29, k + 49, Block.leaves.blockID, 12, 2);
		world.setBlock(i + 13, j + 30, k + 36, Block.leaves.blockID, 12, 2);
		world.setBlock(i + 13, j + 30, k + 49, Block.leaves.blockID, 12, 2);
		world.setBlock(i + 13, j + 31, k + 35, Block.leaves.blockID, 12, 2);
		world.setBlock(i + 13, j + 31, k + 36, Block.leaves.blockID, 12, 2);
		world.setBlock(i + 13, j + 31, k + 37, Block.leaves.blockID, 12, 2);
		world.setBlock(i + 13, j + 31, k + 38, Block.leaves.blockID, 12, 2);
		world.setBlock(i + 13, j + 31, k + 39, Block.leaves.blockID, 12, 2);
		world.setBlock(i + 13, j + 32, k + 36, Block.leaves.blockID, 12, 2);
		world.setBlock(i + 13, j + 32, k + 37, Block.leaves.blockID, 12, 2);
		world.setBlock(i + 13, j + 32, k + 38, Block.leaves.blockID, 12, 2);
		world.setBlock(i + 13, j + 32, k + 39, Block.leaves.blockID, 12, 2);
		world.setBlock(i + 13, j + 35, k + 39, Block.leaves.blockID, 4, 2);
		world.setBlock(i + 13, j + 35, k + 40, Block.leaves.blockID, 4, 2);
		world.setBlock(i + 13, j + 35, k + 46, Block.leaves.blockID, 12, 2);
		world.setBlock(i + 13, j + 35, k + 47, Block.leaves.blockID, 12, 2);
		world.setBlock(i + 13, j + 35, k + 48, Block.leaves.blockID, 12, 2);
		world.setBlock(i + 13, j + 36, k + 40, Block.leaves.blockID, 4, 2);
		world.setBlock(i + 13, j + 36, k + 41, Block.leaves.blockID, 4, 2);
		world.setBlock(i + 13, j + 36, k + 42, Block.leaves.blockID, 12, 2);
		world.setBlock(i + 13, j + 36, k + 43, Block.leaves.blockID, 12, 2);
		world.setBlock(i + 13, j + 36, k + 45, Block.leaves.blockID, 12, 2);
		world.setBlock(i + 13, j + 37, k + 42, Block.leaves.blockID, 12, 2);
		world.setBlock(i + 13, j + 38, k + 42, Block.leaves.blockID, 12, 2);
		world.setBlock(i + 13, j + 39, k + 42, Block.leaves.blockID, 12, 2);
		world.setBlock(i + 13, j + 39, k + 46, Block.wood.blockID, 12, 2);
		world.setBlock(i + 13, j + 40, k + 41, Block.leaves.blockID, 4, 2);
		world.setBlock(i + 13, j + 40, k + 42, Block.leaves.blockID, 12, 2);
		world.setBlock(i + 13, j + 40, k + 45, Block.leaves.blockID, 12, 2);
		world.setBlock(i + 13, j + 41, k + 45, Block.leaves.blockID, 12, 2);
		world.setBlock(i + 13, j + 42, k + 45, Block.leaves.blockID, 12, 2);
		world.setBlock(i + 13, j + 43, k + 45, Block.leaves.blockID, 12, 2);
		world.setBlock(i + 13, j + 44, k + 45, Block.leaves.blockID, 4, 2);
		world.setBlock(i + 13, j + 45, k + 45, Block.leaves.blockID, 4, 2);
		world.setBlock(i + 13, j + 46, k + 45, Block.leaves.blockID, 4, 2);
		world.setBlock(i + 14, j + 17, k + 42, Block.leaves.blockID, 12, 2);
		world.setBlock(i + 14, j + 18, k + 42, Block.leaves.blockID, 12, 2);
		world.setBlock(i + 14, j + 18, k + 43, Block.leaves.blockID, 12, 2);
		world.setBlock(i + 14, j + 18, k + 44, Block.leaves.blockID, 12, 2);
		world.setBlock(i + 14, j + 18, k + 48, Block.leaves.blockID, 12, 2);
		world.setBlock(i + 14, j + 19, k + 42, Block.leaves.blockID, 12, 2);
		world.setBlock(i + 14, j + 19, k + 43, Block.leaves.blockID, 12, 2);
		world.setBlock(i + 14, j + 19, k + 45, Block.leaves.blockID, 12, 2);
		world.setBlock(i + 14, j + 19, k + 46, Block.leaves.blockID, 12, 2);
		world.setBlock(i + 14, j + 19, k + 47, Block.leaves.blockID, 12, 2);
		world.setBlock(i + 14, j + 20, k + 42, Block.leaves.blockID, 12, 2);
		world.setBlock(i + 14, j + 20, k + 43, Block.leaves.blockID, 12, 2);
		world.setBlock(i + 14, j + 20, k + 44, Block.leaves.blockID, 12, 2);
		world.setBlock(i + 14, j + 20, k + 45, Block.wood.blockID, 12, 2);
		world.setBlock(i + 14, j + 20, k + 46, Block.leaves.blockID, 12, 2);
		world.setBlock(i + 14, j + 20, k + 47, Block.leaves.blockID, 12, 2);
		world.setBlock(i + 14, j + 20, k + 48, Block.leaves.blockID, 12, 2);
		world.setBlock(i + 14, j + 20, k + 49, Block.leaves.blockID, 12, 2);
		world.setBlock(i + 14, j + 21, k + 28, Block.leaves.blockID, 12, 2);
		world.setBlock(i + 14, j + 21, k + 29, Block.leaves.blockID, 12, 2);
		world.setBlock(i + 14, j + 21, k + 30, Block.leaves.blockID, 12, 2);
		world.setBlock(i + 14, j + 21, k + 35, Block.leaves.blockID, 12, 2);
		world.setBlock(i + 14, j + 21, k + 36, Block.leaves.blockID, 12, 2);
		world.setBlock(i + 14, j + 21, k + 37, Block.leaves.blockID, 12, 2);
		world.setBlock(i + 14, j + 21, k + 40, Block.leaves.blockID, 12, 2);
		world.setBlock(i + 14, j + 21, k + 41, Block.leaves.blockID, 12, 2);
		world.setBlock(i + 14, j + 21, k + 42, Block.leaves.blockID, 12, 2);
		world.setBlock(i + 14, j + 21, k + 43, Block.leaves.blockID, 12, 2);
		world.setBlock(i + 14, j + 21, k + 44, Block.leaves.blockID, 12, 2);
		world.setBlock(i + 14, j + 21, k + 45, Block.leaves.blockID, 12, 2);
		world.setBlock(i + 14, j + 21, k + 46, Block.leaves.blockID, 12, 2);
		world.setBlock(i + 14, j + 21, k + 47, Block.leaves.blockID, 12, 2);
		world.setBlock(i + 14, j + 21, k + 49, Block.leaves.blockID, 12, 2);
		world.setBlock(i + 14, j + 21, k + 50, Block.leaves.blockID, 12, 2);
		world.setBlock(i + 14, j + 21, k + 51, Block.leaves.blockID, 12, 2);
		world.setBlock(i + 14, j + 22, k + 27, Block.leaves.blockID, 12, 2);
		world.setBlock(i + 14, j + 22, k + 28, Block.leaves.blockID, 12, 2);
		world.setBlock(i + 14, j + 22, k + 34, Block.leaves.blockID, 12, 2);
		world.setBlock(i + 14, j + 22, k + 35, Block.leaves.blockID, 12, 2);
		world.setBlock(i + 14, j + 22, k + 37, Block.leaves.blockID, 12, 2);
		world.setBlock(i + 14, j + 22, k + 38, Block.leaves.blockID, 12, 2);
		world.setBlock(i + 14, j + 22, k + 39, Block.leaves.blockID, 12, 2);
		world.setBlock(i + 14, j + 22, k + 40, Block.leaves.blockID, 12, 2);
		world.setBlock(i + 14, j + 22, k + 41, Block.leaves.blockID, 12, 2);
		world.setBlock(i + 14, j + 22, k + 44, Block.leaves.blockID, 12, 2);
		world.setBlock(i + 14, j + 22, k + 45, Block.leaves.blockID, 12, 2);
		world.setBlock(i + 14, j + 22, k + 46, Block.leaves.blockID, 12, 2);
		world.setBlock(i + 14, j + 22, k + 47, Block.leaves.blockID, 12, 2);
		world.setBlock(i + 14, j + 22, k + 48, Block.leaves.blockID, 12, 2);
		world.setBlock(i + 14, j + 22, k + 49, Block.leaves.blockID, 12, 2);
		world.setBlock(i + 14, j + 22, k + 50, Block.leaves.blockID, 12, 2);
		world.setBlock(i + 14, j + 22, k + 51, Block.leaves.blockID, 12, 2);
		world.setBlock(i + 14, j + 22, k + 52, Block.leaves.blockID, 12, 2);
		world.setBlock(i + 14, j + 22, k + 53, Block.leaves.blockID, 4, 2);
		world.setBlock(i + 14, j + 23, k + 33, Block.leaves.blockID, 12, 2);
		world.setBlock(i + 14, j + 23, k + 34, Block.leaves.blockID, 12, 2);
		world.setBlock(i + 14, j + 23, k + 39, Block.leaves.blockID, 12, 2);
		world.setBlock(i + 14, j + 23, k + 40, Block.leaves.blockID, 12, 2);
		world.setBlock(i + 14, j + 23, k + 44, Block.leaves.blockID, 12, 2);
		world.setBlock(i + 14, j + 23, k + 46, Block.leaves.blockID, 12, 2);
		world.setBlock(i + 14, j + 23, k + 47, Block.leaves.blockID, 12, 2);
		world.setBlock(i + 14, j + 23, k + 48, Block.leaves.blockID, 12, 2);
		world.setBlock(i + 14, j + 23, k + 50, Block.leaves.blockID, 12, 2);
		world.setBlock(i + 14, j + 23, k + 51, Block.leaves.blockID, 12, 2);
		world.setBlock(i + 14, j + 23, k + 52, Block.leaves.blockID, 12, 2);
		world.setBlock(i + 14, j + 23, k + 53, Block.leaves.blockID, 4, 2);
		world.setBlock(i + 14, j + 24, k + 31, Block.leaves.blockID, 12, 2);
		world.setBlock(i + 14, j + 24, k + 32, Block.leaves.blockID, 12, 2);
		world.setBlock(i + 14, j + 24, k + 33, Block.leaves.blockID, 12, 2);
		world.setBlock(i + 14, j + 24, k + 34, Block.leaves.blockID, 12, 2);
		world.setBlock(i + 14, j + 24, k + 35, Block.leaves.blockID, 12, 2);
		world.setBlock(i + 14, j + 24, k + 36, Block.leaves.blockID, 12, 2);
		world.setBlock(i + 14, j + 24, k + 38, Block.leaves.blockID, 12, 2);
		world.setBlock(i + 14, j + 24, k + 39, Block.leaves.blockID, 12, 2);
		world.setBlock(i + 14, j + 24, k + 40, Block.leaves.blockID, 12, 2);
		world.setBlock(i + 14, j + 24, k + 41, Block.leaves.blockID, 12, 2);
		world.setBlock(i + 14, j + 24, k + 44, Block.leaves.blockID, 12, 2);
		world.setBlock(i + 14, j + 24, k + 45, Block.wood.blockID, 12, 2);
		world.setBlock(i + 14, j + 24, k + 46, Block.leaves.blockID, 12, 2);
		world.setBlock(i + 14, j + 24, k + 47, Block.leaves.blockID, 12, 2);
		world.setBlock(i + 14, j + 24, k + 48, Block.leaves.blockID, 12, 2);
		world.setBlock(i + 14, j + 24, k + 53, Block.leaves.blockID, 4, 2);
		world.setBlock(i + 14, j + 25, k + 27, Block.leaves.blockID, 12, 2);
		world.setBlock(i + 14, j + 25, k + 28, Block.leaves.blockID, 12, 2);
		world.setBlock(i + 14, j + 25, k + 29, Block.leaves.blockID, 12, 2);
		world.setBlock(i + 14, j + 25, k + 30, Block.leaves.blockID, 12, 2);
		world.setBlock(i + 14, j + 25, k + 31, Block.leaves.blockID, 12, 2);
		world.setBlock(i + 14, j + 25, k + 36, Block.leaves.blockID, 12, 2);
		world.setBlock(i + 14, j + 25, k + 37, Block.leaves.blockID, 12, 2);
		world.setBlock(i + 14, j + 25, k + 39, Block.leaves.blockID, 12, 2);
		world.setBlock(i + 14, j + 25, k + 40, Block.leaves.blockID, 12, 2);
		world.setBlock(i + 14, j + 25, k + 41, Block.leaves.blockID, 12, 2);
		world.setBlock(i + 14, j + 25, k + 42, Block.leaves.blockID, 12, 2);
		world.setBlock(i + 14, j + 25, k + 45, Block.leaves.blockID, 12, 2);
		world.setBlock(i + 14, j + 25, k + 46, Block.wood.blockID, 12, 2);
		world.setBlock(i + 14, j + 25, k + 47, Block.leaves.blockID, 12, 2);
		world.setBlock(i + 14, j + 25, k + 50, Block.leaves.blockID, 12, 2);
		world.setBlock(i + 14, j + 26, k + 29, Block.leaves.blockID, 12, 2);
		world.setBlock(i + 14, j + 26, k + 30, Block.leaves.blockID, 12, 2);
		world.setBlock(i + 14, j + 26, k + 37, Block.wood.blockID, 12, 2);
		world.setBlock(i + 14, j + 26, k + 38, Block.wood.blockID, 12, 2);
		world.setBlock(i + 14, j + 26, k + 39, Block.leaves.blockID, 12, 2);
		world.setBlock(i + 14, j + 26, k + 45, Block.leaves.blockID, 12, 2);
		world.setBlock(i + 14, j + 27, k + 22, Block.wood.blockID, 12, 2);
		world.setBlock(i + 14, j + 27, k + 30, Block.leaves.blockID, 12, 2);
		world.setBlock(i + 14, j + 27, k + 37, Block.leaves.blockID, 12, 2);
		world.setBlock(i + 14, j + 27, k + 38, Block.leaves.blockID, 12, 2);
		world.setBlock(i + 14, j + 27, k + 45, Block.leaves.blockID, 12, 2);
		world.setBlock(i + 14, j + 27, k + 48, Block.leaves.blockID, 12, 2);
		world.setBlock(i + 14, j + 28, k + 22, Block.wood.blockID, 12, 2);
		world.setBlock(i + 14, j + 28, k + 30, Block.leaves.blockID, 12, 2);
		world.setBlock(i + 14, j + 28, k + 37, Block.leaves.blockID, 12, 2);
		world.setBlock(i + 14, j + 28, k + 45, Block.leaves.blockID, 12, 2);
		world.setBlock(i + 14, j + 28, k + 48, Block.leaves.blockID, 12, 2);
		world.setBlock(i + 14, j + 29, k + 29, Block.leaves.blockID, 12, 2);
		world.setBlock(i + 14, j + 29, k + 36, Block.leaves.blockID, 12, 2);
		world.setBlock(i + 14, j + 29, k + 37, Block.leaves.blockID, 12, 2);
		world.setBlock(i + 14, j + 29, k + 38, Block.leaves.blockID, 12, 2);
		world.setBlock(i + 14, j + 29, k + 39, Block.leaves.blockID, 12, 2);
		world.setBlock(i + 14, j + 29, k + 44, Block.leaves.blockID, 12, 2);
		world.setBlock(i + 14, j + 29, k + 45, Block.leaves.blockID, 12, 2);
		world.setBlock(i + 14, j + 29, k + 48, Block.leaves.blockID, 12, 2);
		world.setBlock(i + 14, j + 29, k + 49, Block.leaves.blockID, 12, 2);
		world.setBlock(i + 14, j + 30, k + 27, Block.leaves.blockID, 12, 2);
		world.setBlock(i + 14, j + 30, k + 28, Block.leaves.blockID, 12, 2);
		world.setBlock(i + 14, j + 30, k + 36, Block.leaves.blockID, 12, 2);
		world.setBlock(i + 14, j + 30, k + 37, Block.leaves.blockID, 12, 2);
		world.setBlock(i + 14, j + 30, k + 38, Block.leaves.blockID, 12, 2);
		world.setBlock(i + 14, j + 30, k + 39, Block.leaves.blockID, 12, 2);
		world.setBlock(i + 14, j + 30, k + 40, Block.leaves.blockID, 12, 2);
		world.setBlock(i + 14, j + 30, k + 49, Block.leaves.blockID, 12, 2);
		world.setBlock(i + 14, j + 31, k + 27, Block.leaves.blockID, 12, 2);
		world.setBlock(i + 14, j + 31, k + 35, Block.leaves.blockID, 12, 2);
		world.setBlock(i + 14, j + 31, k + 38, Block.leaves.blockID, 12, 2);
		world.setBlock(i + 14, j + 31, k + 39, Block.leaves.blockID, 12, 2);
		world.setBlock(i + 14, j + 31, k + 40, Block.leaves.blockID, 12, 2);
		world.setBlock(i + 14, j + 32, k + 29, Block.leaves.blockID, 4, 2);
		world.setBlock(i + 14, j + 32, k + 34, Block.leaves.blockID, 12, 2);
		world.setBlock(i + 14, j + 32, k + 35, Block.leaves.blockID, 12, 2);
		world.setBlock(i + 14, j + 32, k + 49, Block.leaves.blockID, 12, 2);
		world.setBlock(i + 14, j + 32, k + 50, Block.leaves.blockID, 12, 2);
		world.setBlock(i + 14, j + 33, k + 34, Block.leaves.blockID, 12, 2);
		world.setBlock(i + 14, j + 33, k + 42, Block.leaves.blockID, 12, 2);
		world.setBlock(i + 14, j + 34, k + 38, Block.leaves.blockID, 4, 2);
		world.setBlock(i + 14, j + 34, k + 39, Block.leaves.blockID, 4, 2);
		world.setBlock(i + 14, j + 35, k + 39, Block.leaves.blockID, 4, 2);
		world.setBlock(i + 14, j + 35, k + 40, Block.leaves.blockID, 4, 2);
		world.setBlock(i + 14, j + 35, k + 41, Block.leaves.blockID, 4, 2);
		world.setBlock(i + 14, j + 35, k + 46, Block.leaves.blockID, 12, 2);
		world.setBlock(i + 14, j + 35, k + 47, Block.leaves.blockID, 12, 2);
		world.setBlock(i + 14, j + 35, k + 48, Block.leaves.blockID, 12, 2);
		world.setBlock(i + 14, j + 36, k + 41, Block.leaves.blockID, 4, 2);
		world.setBlock(i + 14, j + 36, k + 42, Block.leaves.blockID, 12, 2);
		world.setBlock(i + 14, j + 36, k + 43, Block.leaves.blockID, 12, 2);
		world.setBlock(i + 14, j + 36, k + 44, Block.leaves.blockID, 12, 2);
		world.setBlock(i + 14, j + 36, k + 45, Block.leaves.blockID, 12, 2);
		world.setBlock(i + 14, j + 37, k + 42, Block.leaves.blockID, 12, 2);
		world.setBlock(i + 14, j + 38, k + 42, Block.leaves.blockID, 12, 2);
		world.setBlock(i + 14, j + 39, k + 42, Block.leaves.blockID, 12, 2);
		world.setBlock(i + 14, j + 39, k + 45, Block.leaves.blockID, 12, 2);
		world.setBlock(i + 14, j + 39, k + 46, Block.wood.blockID, 12, 2);
		world.setBlock(i + 14, j + 40, k + 42, Block.leaves.blockID, 12, 2);
		world.setBlock(i + 14, j + 40, k + 45, Block.leaves.blockID, 12, 2);
		world.setBlock(i + 14, j + 41, k + 45, Block.leaves.blockID, 12, 2);
		world.setBlock(i + 14, j + 42, k + 45, Block.leaves.blockID, 12, 2);
		world.setBlock(i + 14, j + 43, k + 45, Block.leaves.blockID, 12, 2);
		world.setBlock(i + 14, j + 44, k + 45, Block.leaves.blockID, 4, 2);
		world.setBlock(i + 14, j + 44, k + 46, Block.leaves.blockID, 4, 2);
		world.setBlock(i + 14, j + 45, k + 45, Block.leaves.blockID, 4, 2);
		world.setBlock(i + 14, j + 45, k + 46, Block.leaves.blockID, 4, 2);
		world.setBlock(i + 15, j + 17, k + 42, Block.leaves.blockID, 12, 2);
		world.setBlock(i + 15, j + 18, k + 42, Block.leaves.blockID, 12, 2);
		world.setBlock(i + 15, j + 18, k + 43, Block.leaves.blockID, 12, 2);
		world.setBlock(i + 15, j + 18, k + 44, Block.leaves.blockID, 12, 2);
		world.setBlock(i + 15, j + 18, k + 45, Block.leaves.blockID, 12, 2);
		world.setBlock(i + 15, j + 18, k + 47, Block.leaves.blockID, 12, 2);
		world.setBlock(i + 15, j + 18, k + 48, Block.leaves.blockID, 12, 2);
		world.setBlock(i + 15, j + 19, k + 42, Block.leaves.blockID, 12, 2);
		world.setBlock(i + 15, j + 19, k + 44, Block.leaves.blockID, 12, 2);
		world.setBlock(i + 15, j + 19, k + 45, Block.leaves.blockID, 12, 2);
		world.setBlock(i + 15, j + 19, k + 46, Block.leaves.blockID, 12, 2);
		world.setBlock(i + 15, j + 19, k + 47, Block.leaves.blockID, 12, 2);
		world.setBlock(i + 15, j + 20, k + 41, Block.leaves.blockID, 12, 2);
		world.setBlock(i + 15, j + 20, k + 42, Block.leaves.blockID, 12, 2);
		world.setBlock(i + 15, j + 20, k + 43, Block.leaves.blockID, 12, 2);
		world.setBlock(i + 15, j + 20, k + 44, Block.leaves.blockID, 12, 2);
		world.setBlock(i + 15, j + 20, k + 45, Block.wood.blockID, 12, 2);
		world.setBlock(i + 15, j + 20, k + 46, Block.leaves.blockID, 12, 2);
		world.setBlock(i + 15, j + 20, k + 47, Block.leaves.blockID, 12, 2);
		world.setBlock(i + 15, j + 20, k + 48, Block.leaves.blockID, 12, 2);
		world.setBlock(i + 15, j + 21, k + 29, Block.leaves.blockID, 12, 2);
		world.setBlock(i + 15, j + 21, k + 30, Block.leaves.blockID, 12, 2);
		world.setBlock(i + 15, j + 21, k + 35, Block.leaves.blockID, 12, 2);
		world.setBlock(i + 15, j + 21, k + 36, Block.leaves.blockID, 12, 2);
		world.setBlock(i + 15, j + 21, k + 37, Block.leaves.blockID, 12, 2);
		world.setBlock(i + 15, j + 21, k + 38, Block.leaves.blockID, 12, 2);
		world.setBlock(i + 15, j + 21, k + 39, Block.leaves.blockID, 12, 2);
		world.setBlock(i + 15, j + 21, k + 40, Block.leaves.blockID, 12, 2);
		world.setBlock(i + 15, j + 21, k + 41, Block.leaves.blockID, 12, 2);
		world.setBlock(i + 15, j + 21, k + 42, Block.leaves.blockID, 12, 2);
		world.setBlock(i + 15, j + 21, k + 43, Block.leaves.blockID, 12, 2);
		world.setBlock(i + 15, j + 21, k + 44, Block.leaves.blockID, 12, 2);
		world.setBlock(i + 15, j + 21, k + 45, Block.leaves.blockID, 12, 2);
		world.setBlock(i + 15, j + 21, k + 46, Block.leaves.blockID, 12, 2);
		world.setBlock(i + 15, j + 21, k + 47, Block.leaves.blockID, 12, 2);
		world.setBlock(i + 15, j + 21, k + 48, Block.leaves.blockID, 12, 2);
		world.setBlock(i + 15, j + 21, k + 49, Block.leaves.blockID, 12, 2);
		world.setBlock(i + 15, j + 21, k + 50, Block.leaves.blockID, 12, 2);
		world.setBlock(i + 15, j + 22, k + 27, Block.leaves.blockID, 12, 2);
		world.setBlock(i + 15, j + 22, k + 28, Block.leaves.blockID, 12, 2);
		world.setBlock(i + 15, j + 22, k + 32, Block.leaves.blockID, 12, 2);
		world.setBlock(i + 15, j + 22, k + 33, Block.leaves.blockID, 12, 2);
		world.setBlock(i + 15, j + 22, k + 34, Block.leaves.blockID, 12, 2);
		world.setBlock(i + 15, j + 22, k + 35, Block.leaves.blockID, 12, 2);
		world.setBlock(i + 15, j + 22, k + 36, Block.leaves.blockID, 12, 2);
		world.setBlock(i + 15, j + 22, k + 38, Block.leaves.blockID, 12, 2);
		world.setBlock(i + 15, j + 22, k + 39, Block.leaves.blockID, 12, 2);
		world.setBlock(i + 15, j + 22, k + 40, Block.leaves.blockID, 12, 2);
		world.setBlock(i + 15, j + 22, k + 41, Block.leaves.blockID, 12, 2);
		world.setBlock(i + 15, j + 22, k + 45, Block.leaves.blockID, 12, 2);
		world.setBlock(i + 15, j + 22, k + 46, Block.leaves.blockID, 12, 2);
		world.setBlock(i + 15, j + 22, k + 47, Block.leaves.blockID, 12, 2);
		world.setBlock(i + 15, j + 22, k + 49, Block.leaves.blockID, 12, 2);
		world.setBlock(i + 15, j + 22, k + 50, Block.leaves.blockID, 12, 2);
		world.setBlock(i + 15, j + 22, k + 51, Block.leaves.blockID, 12, 2);
		world.setBlock(i + 15, j + 22, k + 52, Block.leaves.blockID, 4, 2);
		world.setBlock(i + 15, j + 22, k + 53, Block.leaves.blockID, 4, 2);
		world.setBlock(i + 15, j + 23, k + 26, Block.leaves.blockID, 12, 2);
		world.setBlock(i + 15, j + 23, k + 33, Block.leaves.blockID, 12, 2);
		world.setBlock(i + 15, j + 23, k + 34, Block.leaves.blockID, 12, 2);
		world.setBlock(i + 15, j + 23, k + 35, Block.leaves.blockID, 12, 2);
		world.setBlock(i + 15, j + 23, k + 36, Block.leaves.blockID, 12, 2);
		world.setBlock(i + 15, j + 23, k + 39, Block.leaves.blockID, 12, 2);
		world.setBlock(i + 15, j + 23, k + 40, Block.leaves.blockID, 12, 2);
		world.setBlock(i + 15, j + 23, k + 45, Block.leaves.blockID, 12, 2);
		world.setBlock(i + 15, j + 23, k + 46, Block.leaves.blockID, 12, 2);
		world.setBlock(i + 15, j + 23, k + 50, Block.leaves.blockID, 12, 2);
		world.setBlock(i + 15, j + 23, k + 51, Block.leaves.blockID, 12, 2);
		world.setBlock(i + 15, j + 23, k + 52, Block.leaves.blockID, 4, 2);
		world.setBlock(i + 15, j + 24, k + 32, Block.leaves.blockID, 12, 2);
		world.setBlock(i + 15, j + 24, k + 33, Block.leaves.blockID, 12, 2);
		world.setBlock(i + 15, j + 24, k + 34, Block.leaves.blockID, 12, 2);
		world.setBlock(i + 15, j + 24, k + 35, Block.leaves.blockID, 12, 2);
		world.setBlock(i + 15, j + 24, k + 36, Block.leaves.blockID, 12, 2);
		world.setBlock(i + 15, j + 24, k + 37, Block.leaves.blockID, 12, 2);
		world.setBlock(i + 15, j + 24, k + 39, Block.leaves.blockID, 12, 2);
		world.setBlock(i + 15, j + 24, k + 40, Block.leaves.blockID, 12, 2);
		world.setBlock(i + 15, j + 24, k + 45, Block.leaves.blockID, 12, 2);
		world.setBlock(i + 15, j + 24, k + 46, Block.leaves.blockID, 12, 2);
		world.setBlock(i + 15, j + 24, k + 50, Block.leaves.blockID, 12, 2);
		world.setBlock(i + 15, j + 24, k + 51, Block.leaves.blockID, 12, 2);
		world.setBlock(i + 15, j + 24, k + 52, Block.leaves.blockID, 4, 2);
		world.setBlock(i + 15, j + 25, k + 25, Block.wood.blockID, 12, 2);
		world.setBlock(i + 15, j + 25, k + 28, Block.leaves.blockID, 12, 2);
		world.setBlock(i + 15, j + 25, k + 29, Block.leaves.blockID, 12, 2);
		world.setBlock(i + 15, j + 25, k + 30, Block.leaves.blockID, 12, 2);
		world.setBlock(i + 15, j + 25, k + 38, Block.wood.blockID, 12, 2);
		world.setBlock(i + 15, j + 25, k + 39, Block.leaves.blockID, 12, 2);
		world.setBlock(i + 15, j + 25, k + 40, Block.leaves.blockID, 12, 2);
		world.setBlock(i + 15, j + 25, k + 45, Block.leaves.blockID, 12, 2);
		world.setBlock(i + 15, j + 25, k + 49, Block.leaves.blockID, 12, 2);
		world.setBlock(i + 15, j + 25, k + 50, Block.leaves.blockID, 12, 2);
		world.setBlock(i + 15, j + 25, k + 51, Block.leaves.blockID, 12, 2);
		world.setBlock(i + 15, j + 25, k + 52, Block.leaves.blockID, 4, 2);
		world.setBlock(i + 15, j + 26, k + 24, Block.wood.blockID, 12, 2);
		world.setBlock(i + 15, j + 26, k + 30, Block.leaves.blockID, 12, 2);
		world.setBlock(i + 15, j + 26, k + 38, Block.wood.blockID, 12, 2);
		world.setBlock(i + 15, j + 26, k + 39, Block.wood.blockID, 12, 2);
		world.setBlock(i + 15, j + 26, k + 44, Block.leaves.blockID, 12, 2);
		world.setBlock(i + 15, j + 26, k + 45, Block.leaves.blockID, 12, 2);
		world.setBlock(i + 15, j + 27, k + 23, Block.wood.blockID, 12, 2);
		world.setBlock(i + 15, j + 27, k + 24, Block.wood.blockID, 12, 2);
		world.setBlock(i + 15, j + 27, k + 30, Block.leaves.blockID, 12, 2);
		world.setBlock(i + 15, j + 27, k + 37, Block.leaves.blockID, 12, 2);
		world.setBlock(i + 15, j + 27, k + 38, Block.leaves.blockID, 12, 2);
		world.setBlock(i + 15, j + 27, k + 39, Block.leaves.blockID, 12, 2);
		world.setBlock(i + 15, j + 27, k + 44, Block.leaves.blockID, 12, 2);
		world.setBlock(i + 15, j + 27, k + 47, Block.leaves.blockID, 12, 2);
		world.setBlock(i + 15, j + 27, k + 48, Block.leaves.blockID, 12, 2);
		world.setBlock(i + 15, j + 28, k + 24, Block.leaves.blockID, 12, 2);
		world.setBlock(i + 15, j + 28, k + 25, Block.leaves.blockID, 12, 2);
		world.setBlock(i + 15, j + 28, k + 28, Block.leaves.blockID, 12, 2);
		world.setBlock(i + 15, j + 28, k + 29, Block.leaves.blockID, 12, 2);
		world.setBlock(i + 15, j + 28, k + 30, Block.leaves.blockID, 12, 2);
		world.setBlock(i + 15, j + 28, k + 37, Block.leaves.blockID, 12, 2);
		world.setBlock(i + 15, j + 28, k + 38, Block.leaves.blockID, 12, 2);
		world.setBlock(i + 15, j + 28, k + 39, Block.leaves.blockID, 12, 2);
		world.setBlock(i + 15, j + 28, k + 40, Block.leaves.blockID, 12, 2);
		world.setBlock(i + 15, j + 28, k + 43, Block.leaves.blockID, 12, 2);
		world.setBlock(i + 15, j + 28, k + 44, Block.leaves.blockID, 12, 2);
		world.setBlock(i + 15, j + 28, k + 48, Block.leaves.blockID, 12, 2);
		world.setBlock(i + 15, j + 29, k + 24, Block.leaves.blockID, 12, 2);
		world.setBlock(i + 15, j + 29, k + 25, Block.leaves.blockID, 12, 2);
		world.setBlock(i + 15, j + 29, k + 26, Block.leaves.blockID, 12, 2);
		world.setBlock(i + 15, j + 29, k + 27, Block.leaves.blockID, 12, 2);
		world.setBlock(i + 15, j + 29, k + 28, Block.leaves.blockID, 12, 2);
		world.setBlock(i + 15, j + 29, k + 29, Block.leaves.blockID, 12, 2);
		world.setBlock(i + 15, j + 29, k + 36, Block.leaves.blockID, 12, 2);
		world.setBlock(i + 15, j + 29, k + 37, Block.leaves.blockID, 12, 2);
		world.setBlock(i + 15, j + 29, k + 38, Block.leaves.blockID, 12, 2);
		world.setBlock(i + 15, j + 29, k + 39, Block.leaves.blockID, 12, 2);
		world.setBlock(i + 15, j + 29, k + 40, Block.leaves.blockID, 12, 2);
		world.setBlock(i + 15, j + 29, k + 41, Block.leaves.blockID, 12, 2);
		world.setBlock(i + 15, j + 29, k + 42, Block.leaves.blockID, 12, 2);
		world.setBlock(i + 15, j + 29, k + 43, Block.leaves.blockID, 12, 2);
		world.setBlock(i + 15, j + 29, k + 44, Block.leaves.blockID, 12, 2);
		world.setBlock(i + 15, j + 29, k + 48, Block.leaves.blockID, 12, 2);
		world.setBlock(i + 15, j + 29, k + 49, Block.leaves.blockID, 12, 2);
		world.setBlock(i + 15, j + 30, k + 25, Block.leaves.blockID, 12, 2);
		world.setBlock(i + 15, j + 30, k + 26, Block.leaves.blockID, 12, 2);
		world.setBlock(i + 15, j + 30, k + 27, Block.leaves.blockID, 12, 2);
		world.setBlock(i + 15, j + 30, k + 35, Block.leaves.blockID, 12, 2);
		world.setBlock(i + 15, j + 30, k + 36, Block.leaves.blockID, 12, 2);
		world.setBlock(i + 15, j + 30, k + 41, Block.leaves.blockID, 12, 2);
		world.setBlock(i + 15, j + 30, k + 42, Block.leaves.blockID, 12, 2);
		world.setBlock(i + 15, j + 30, k + 43, Block.leaves.blockID, 12, 2);
		world.setBlock(i + 15, j + 30, k + 44, Block.leaves.blockID, 12, 2);
		world.setBlock(i + 15, j + 30, k + 49, Block.leaves.blockID, 12, 2);
		world.setBlock(i + 15, j + 31, k + 26, Block.leaves.blockID, 12, 2);
		world.setBlock(i + 15, j + 31, k + 30, Block.leaves.blockID, 12, 2);
		world.setBlock(i + 15, j + 31, k + 34, Block.leaves.blockID, 12, 2);
		world.setBlock(i + 15, j + 31, k + 35, Block.leaves.blockID, 12, 2);
		world.setBlock(i + 15, j + 31, k + 49, Block.leaves.blockID, 4, 2);
		world.setBlock(i + 15, j + 31, k + 50, Block.leaves.blockID, 4, 2);
		world.setBlock(i + 15, j + 31, k + 51, Block.leaves.blockID, 4, 2);
		world.setBlock(i + 15, j + 32, k + 28, Block.leaves.blockID, 12, 2);
		world.setBlock(i + 15, j + 32, k + 29, Block.leaves.blockID, 12, 2);
		world.setBlock(i + 15, j + 32, k + 30, Block.leaves.blockID, 12, 2);
		world.setBlock(i + 15, j + 32, k + 34, Block.leaves.blockID, 12, 2);
		world.setBlock(i + 15, j + 32, k + 43, Block.leaves.blockID, 12, 2);
		world.setBlock(i + 15, j + 32, k + 48, Block.leaves.blockID, 12, 2);
		world.setBlock(i + 15, j + 32, k + 49, Block.leaves.blockID, 12, 2);
		world.setBlock(i + 15, j + 32, k + 51, Block.leaves.blockID, 12, 2);
		world.setBlock(i + 15, j + 33, k + 33, Block.leaves.blockID, 12, 2);
		world.setBlock(i + 15, j + 33, k + 34, Block.leaves.blockID, 12, 2);
		world.setBlock(i + 15, j + 33, k + 38, Block.leaves.blockID, 4, 2);
		world.setBlock(i + 15, j + 33, k + 41, Block.leaves.blockID, 4, 2);
		world.setBlock(i + 15, j + 33, k + 42, Block.leaves.blockID, 12, 2);
		world.setBlock(i + 15, j + 33, k + 43, Block.leaves.blockID, 12, 2);
		world.setBlock(i + 15, j + 34, k + 38, Block.leaves.blockID, 4, 2);
		world.setBlock(i + 15, j + 34, k + 39, Block.leaves.blockID, 4, 2);
		world.setBlock(i + 15, j + 34, k + 40, Block.leaves.blockID, 4, 2);
		world.setBlock(i + 15, j + 34, k + 41, Block.leaves.blockID, 4, 2);
		world.setBlock(i + 15, j + 34, k + 49, Block.leaves.blockID, 12, 2);
		world.setBlock(i + 15, j + 35, k + 40, Block.leaves.blockID, 4, 2);
		world.setBlock(i + 15, j + 35, k + 41, Block.leaves.blockID, 4, 2);
		world.setBlock(i + 15, j + 35, k + 46, Block.leaves.blockID, 12, 2);
		world.setBlock(i + 15, j + 35, k + 47, Block.leaves.blockID, 12, 2);
		world.setBlock(i + 15, j + 35, k + 48, Block.leaves.blockID, 12, 2);
		world.setBlock(i + 15, j + 36, k + 42, Block.leaves.blockID, 12, 2);
		world.setBlock(i + 15, j + 36, k + 43, Block.leaves.blockID, 12, 2);
		world.setBlock(i + 15, j + 36, k + 44, Block.leaves.blockID, 12, 2);
		world.setBlock(i + 15, j + 36, k + 45, Block.leaves.blockID, 12, 2);
		world.setBlock(i + 15, j + 37, k + 43, Block.leaves.blockID, 12, 2);
		world.setBlock(i + 15, j + 38, k + 43, Block.leaves.blockID, 12, 2);
		world.setBlock(i + 15, j + 38, k + 46, Block.wood.blockID, 12, 2);
		world.setBlock(i + 15, j + 39, k + 42, Block.leaves.blockID, 12, 2);
		world.setBlock(i + 15, j + 39, k + 43, Block.leaves.blockID, 12, 2);
		world.setBlock(i + 15, j + 39, k + 46, Block.wood.blockID, 12, 2);
		world.setBlock(i + 15, j + 39, k + 51, Block.leaves.blockID, 12, 2);
		world.setBlock(i + 15, j + 40, k + 42, Block.leaves.blockID, 12, 2);
		world.setBlock(i + 15, j + 40, k + 45, Block.leaves.blockID, 12, 2);
		world.setBlock(i + 15, j + 41, k + 42, Block.leaves.blockID, 12, 2);
		world.setBlock(i + 15, j + 41, k + 45, Block.leaves.blockID, 12, 2);
		world.setBlock(i + 15, j + 42, k + 45, Block.leaves.blockID, 12, 2);
		world.setBlock(i + 15, j + 42, k + 46, Block.leaves.blockID, 12, 2);
		world.setBlock(i + 15, j + 43, k + 45, Block.leaves.blockID, 12, 2);
		world.setBlock(i + 15, j + 43, k + 46, Block.leaves.blockID, 12, 2);
		world.setBlock(i + 15, j + 44, k + 46, Block.leaves.blockID, 4, 2);
		world.setBlock(i + 15, j + 45, k + 46, Block.leaves.blockID, 4, 2);
		world.setBlock(i + 15, j + 46, k + 46, Block.leaves.blockID, 4, 2);
		world.setBlock(i + 15, j + 47, k + 46, Block.leaves.blockID, 4, 2);
		world.setBlock(i + 15, j + 47, k + 47, Block.leaves.blockID, 4, 2);
		world.setBlock(i + 15, j + 48, k + 46, Block.leaves.blockID, 4, 2);
		world.setBlock(i + 15, j + 48, k + 47, Block.leaves.blockID, 4, 2);
		world.setBlock(i + 15, j + 48, k + 48, Block.leaves.blockID, 4, 2);
		world.setBlock(i + 15, j + 49, k + 48, Block.leaves.blockID, 4, 2);
		world.setBlock(i + 15, j + 49, k + 49, Block.leaves.blockID, 4, 2);
		world.setBlock(i + 16, j + 17, k + 34, Block.leaves.blockID, 12, 2);
		world.setBlock(i + 16, j + 17, k + 42, Block.leaves.blockID, 12, 2);
		world.setBlock(i + 16, j + 18, k + 33, Block.leaves.blockID, 12, 2);
		world.setBlock(i + 16, j + 18, k + 42, Block.leaves.blockID, 12, 2);
		world.setBlock(i + 16, j + 18, k + 43, Block.leaves.blockID, 12, 2);
		world.setBlock(i + 16, j + 18, k + 44, Block.leaves.blockID, 12, 2);
		world.setBlock(i + 16, j + 18, k + 45, Block.leaves.blockID, 12, 2);
		world.setBlock(i + 16, j + 18, k + 46, Block.leaves.blockID, 12, 2);
		world.setBlock(i + 16, j + 18, k + 47, Block.leaves.blockID, 12, 2);
		world.setBlock(i + 16, j + 19, k + 42, Block.leaves.blockID, 12, 2);
		world.setBlock(i + 16, j + 19, k + 43, Block.leaves.blockID, 12, 2);
		world.setBlock(i + 16, j + 19, k + 44, Block.leaves.blockID, 12, 2);
		world.setBlock(i + 16, j + 19, k + 45, Block.leaves.blockID, 12, 2);
		world.setBlock(i + 16, j + 19, k + 46, Block.leaves.blockID, 12, 2);
		world.setBlock(i + 16, j + 20, k + 31, Block.leaves.blockID, 12, 2);
		world.setBlock(i + 16, j + 20, k + 36, Block.leaves.blockID, 12, 2);
		world.setBlock(i + 16, j + 20, k + 41, Block.leaves.blockID, 12, 2);
		world.setBlock(i + 16, j + 20, k + 42, Block.leaves.blockID, 12, 2);
		world.setBlock(i + 16, j + 20, k + 43, Block.leaves.blockID, 12, 2);
		world.setBlock(i + 16, j + 20, k + 44, Block.wood.blockID, 12, 2);
		world.setBlock(i + 16, j + 20, k + 45, Block.leaves.blockID, 12, 2);
		world.setBlock(i + 16, j + 20, k + 46, Block.leaves.blockID, 12, 2);
		world.setBlock(i + 16, j + 20, k + 47, Block.leaves.blockID, 12, 2);
		world.setBlock(i + 16, j + 21, k + 29, Block.leaves.blockID, 12, 2);
		world.setBlock(i + 16, j + 21, k + 30, Block.leaves.blockID, 12, 2);
		world.setBlock(i + 16, j + 21, k + 31, Block.leaves.blockID, 12, 2);
		world.setBlock(i + 16, j + 21, k + 35, Block.leaves.blockID, 12, 2);
		world.setBlock(i + 16, j + 21, k + 36, Block.leaves.blockID, 12, 2);
		world.setBlock(i + 16, j + 21, k + 37, Block.leaves.blockID, 12, 2);
		world.setBlock(i + 16, j + 21, k + 38, Block.leaves.blockID, 12, 2);
		world.setBlock(i + 16, j + 21, k + 39, Block.leaves.blockID, 12, 2);
		world.setBlock(i + 16, j + 21, k + 40, Block.leaves.blockID, 12, 2);
		world.setBlock(i + 16, j + 21, k + 41, Block.leaves.blockID, 12, 2);
		world.setBlock(i + 16, j + 21, k + 43, Block.leaves.blockID, 12, 2);
		world.setBlock(i + 16, j + 21, k + 44, Block.leaves.blockID, 12, 2);
		world.setBlock(i + 16, j + 21, k + 45, Block.leaves.blockID, 12, 2);
		world.setBlock(i + 16, j + 21, k + 46, Block.leaves.blockID, 12, 2);
		world.setBlock(i + 16, j + 21, k + 47, Block.leaves.blockID, 12, 2);
		world.setBlock(i + 16, j + 21, k + 48, Block.leaves.blockID, 12, 2);
		world.setBlock(i + 16, j + 21, k + 49, Block.leaves.blockID, 12, 2);
		world.setBlock(i + 16, j + 21, k + 50, Block.leaves.blockID, 12, 2);
		world.setBlock(i + 16, j + 21, k + 51, Block.leaves.blockID, 12, 2);
		world.setBlock(i + 16, j + 21, k + 52, Block.leaves.blockID, 4, 2);
		world.setBlock(i + 16, j + 21, k + 53, Block.leaves.blockID, 4, 2);
		world.setBlock(i + 16, j + 22, k + 26, Block.leaves.blockID, 12, 2);
		world.setBlock(i + 16, j + 22, k + 27, Block.leaves.blockID, 12, 2);
		world.setBlock(i + 16, j + 22, k + 28, Block.leaves.blockID, 12, 2);
		world.setBlock(i + 16, j + 22, k + 29, Block.leaves.blockID, 12, 2);
		world.setBlock(i + 16, j + 22, k + 31, Block.leaves.blockID, 12, 2);
		world.setBlock(i + 16, j + 22, k + 32, Block.leaves.blockID, 12, 2);
		world.setBlock(i + 16, j + 22, k + 33, Block.leaves.blockID, 12, 2);
		world.setBlock(i + 16, j + 22, k + 34, Block.leaves.blockID, 12, 2);
		world.setBlock(i + 16, j + 22, k + 36, Block.leaves.blockID, 12, 2);
		world.setBlock(i + 16, j + 22, k + 37, Block.leaves.blockID, 12, 2);
		world.setBlock(i + 16, j + 22, k + 39, Block.leaves.blockID, 12, 2);
		world.setBlock(i + 16, j + 22, k + 40, Block.leaves.blockID, 12, 2);
		world.setBlock(i + 16, j + 22, k + 44, Block.wood.blockID, 12, 2);
		world.setBlock(i + 16, j + 22, k + 45, Block.leaves.blockID, 12, 2);
		world.setBlock(i + 16, j + 22, k + 46, Block.leaves.blockID, 12, 2);
		world.setBlock(i + 16, j + 22, k + 47, Block.leaves.blockID, 12, 2);
		world.setBlock(i + 16, j + 22, k + 48, Block.leaves.blockID, 12, 2);
		world.setBlock(i + 16, j + 22, k + 49, Block.leaves.blockID, 12, 2);
		world.setBlock(i + 16, j + 22, k + 50, Block.leaves.blockID, 12, 2);
		world.setBlock(i + 16, j + 22, k + 51, Block.leaves.blockID, 12, 2);
		world.setBlock(i + 16, j + 22, k + 52, Block.leaves.blockID, 4, 2);
		world.setBlock(i + 16, j + 23, k + 27, Block.leaves.blockID, 12, 2);
		world.setBlock(i + 16, j + 23, k + 28, Block.leaves.blockID, 12, 2);
		world.setBlock(i + 16, j + 23, k + 34, Block.leaves.blockID, 12, 2);
		world.setBlock(i + 16, j + 23, k + 35, Block.leaves.blockID, 12, 2);
		world.setBlock(i + 16, j + 23, k + 36, Block.leaves.blockID, 12, 2);
		world.setBlock(i + 16, j + 23, k + 37, Block.leaves.blockID, 12, 2);
		world.setBlock(i + 16, j + 23, k + 38, Block.wood.blockID, 12, 2);
		world.setBlock(i + 16, j + 23, k + 39, Block.leaves.blockID, 12, 2);
		world.setBlock(i + 16, j + 23, k + 44, Block.wood.blockID, 12, 2);
		world.setBlock(i + 16, j + 23, k + 45, Block.leaves.blockID, 12, 2);
		world.setBlock(i + 16, j + 23, k + 47, Block.leaves.blockID, 12, 2);
		world.setBlock(i + 16, j + 23, k + 48, Block.leaves.blockID, 12, 2);
		world.setBlock(i + 16, j + 23, k + 49, Block.leaves.blockID, 12, 2);
		world.setBlock(i + 16, j + 24, k + 27, Block.leaves.blockID, 12, 2);
		world.setBlock(i + 16, j + 24, k + 28, Block.leaves.blockID, 12, 2);
		world.setBlock(i + 16, j + 24, k + 29, Block.leaves.blockID, 12, 2);
		world.setBlock(i + 16, j + 24, k + 30, Block.leaves.blockID, 12, 2);
		world.setBlock(i + 16, j + 24, k + 31, Block.leaves.blockID, 12, 2);
		world.setBlock(i + 16, j + 24, k + 32, Block.leaves.blockID, 12, 2);
		world.setBlock(i + 16, j + 24, k + 33, Block.leaves.blockID, 12, 2);
		world.setBlock(i + 16, j + 24, k + 34, Block.leaves.blockID, 12, 2);
		world.setBlock(i + 16, j + 24, k + 38, Block.wood.blockID, 12, 2);
		world.setBlock(i + 16, j + 24, k + 39, Block.wood.blockID, 12, 2);
		world.setBlock(i + 16, j + 24, k + 44, Block.leaves.blockID, 12, 2);
		world.setBlock(i + 16, j + 24, k + 45, Block.leaves.blockID, 12, 2);
		world.setBlock(i + 16, j + 24, k + 47, Block.leaves.blockID, 12, 2);
		world.setBlock(i + 16, j + 24, k + 48, Block.leaves.blockID, 12, 2);
		world.setBlock(i + 16, j + 24, k + 49, Block.leaves.blockID, 12, 2);
		world.setBlock(i + 16, j + 24, k + 50, Block.leaves.blockID, 12, 2);
		world.setBlock(i + 16, j + 25, k + 26, Block.wood.blockID, 12, 2);
		world.setBlock(i + 16, j + 25, k + 27, Block.wood.blockID, 12, 2);
		world.setBlock(i + 16, j + 25, k + 29, Block.leaves.blockID, 12, 2);
		world.setBlock(i + 16, j + 25, k + 30, Block.leaves.blockID, 12, 2);
		world.setBlock(i + 16, j + 25, k + 38, Block.wood.blockID, 12, 2);
		world.setBlock(i + 16, j + 25, k + 39, Block.wood.blockID, 12, 2);
		world.setBlock(i + 16, j + 25, k + 43, Block.leaves.blockID, 12, 2);
		world.setBlock(i + 16, j + 25, k + 44, Block.leaves.blockID, 12, 2);
		world.setBlock(i + 16, j + 25, k + 45, Block.leaves.blockID, 12, 2);
		world.setBlock(i + 16, j + 25, k + 48, Block.leaves.blockID, 12, 2);
		world.setBlock(i + 16, j + 25, k + 49, Block.leaves.blockID, 12, 2);
		world.setBlock(i + 16, j + 25, k + 50, Block.leaves.blockID, 12, 2);
		world.setBlock(i + 16, j + 25, k + 51, Block.leaves.blockID, 12, 2);
		world.setBlock(i + 16, j + 25, k + 52, Block.leaves.blockID, 12, 2);
		world.setBlock(i + 16, j + 26, k + 30, Block.leaves.blockID, 12, 2);
		world.setBlock(i + 16, j + 26, k + 38, Block.leaves.blockID, 12, 2);
		world.setBlock(i + 16, j + 26, k + 39, Block.wood.blockID, 12, 2);
		world.setBlock(i + 16, j + 26, k + 40, Block.leaves.blockID, 12, 2);
		world.setBlock(i + 16, j + 26, k + 41, Block.leaves.blockID, 12, 2);
		world.setBlock(i + 16, j + 26, k + 42, Block.leaves.blockID, 12, 2);
		world.setBlock(i + 16, j + 26, k + 43, Block.leaves.blockID, 12, 2);
		world.setBlock(i + 16, j + 26, k + 44, Block.leaves.blockID, 12, 2);
		world.setBlock(i + 16, j + 26, k + 45, Block.leaves.blockID, 12, 2);
		world.setBlock(i + 16, j + 26, k + 52, Block.leaves.blockID, 12, 2);
		world.setBlock(i + 16, j + 26, k + 53, Block.leaves.blockID, 12, 2);
		world.setBlock(i + 16, j + 27, k + 27, Block.leaves.blockID, 12, 2);
		world.setBlock(i + 16, j + 27, k + 28, Block.leaves.blockID, 12, 2);
		world.setBlock(i + 16, j + 27, k + 30, Block.leaves.blockID, 12, 2);
		world.setBlock(i + 16, j + 27, k + 37, Block.leaves.blockID, 12, 2);
		world.setBlock(i + 16, j + 27, k + 38, Block.leaves.blockID, 12, 2);
		world.setBlock(i + 16, j + 27, k + 39, Block.leaves.blockID, 12, 2);
		world.setBlock(i + 16, j + 27, k + 40, Block.leaves.blockID, 12, 2);
		world.setBlock(i + 16, j + 27, k + 41, Block.leaves.blockID, 12, 2);
		world.setBlock(i + 16, j + 27, k + 42, Block.leaves.blockID, 12, 2);
		world.setBlock(i + 16, j + 27, k + 43, Block.leaves.blockID, 12, 2);
		world.setBlock(i + 16, j + 27, k + 44, Block.leaves.blockID, 12, 2);
		world.setBlock(i + 16, j + 27, k + 45, Block.leaves.blockID, 12, 2);
		world.setBlock(i + 16, j + 27, k + 48, Block.leaves.blockID, 12, 2);
		world.setBlock(i + 16, j + 28, k + 26, Block.leaves.blockID, 12, 2);
		world.setBlock(i + 16, j + 28, k + 27, Block.leaves.blockID, 12, 2);
		world.setBlock(i + 16, j + 28, k + 28, Block.leaves.blockID, 12, 2);
		world.setBlock(i + 16, j + 28, k + 30, Block.leaves.blockID, 12, 2);
		world.setBlock(i + 16, j + 28, k + 36, Block.leaves.blockID, 12, 2);
		world.setBlock(i + 16, j + 28, k + 37, Block.leaves.blockID, 12, 2);
		world.setBlock(i + 16, j + 28, k + 41, Block.leaves.blockID, 12, 2);
		world.setBlock(i + 16, j + 28, k + 42, Block.leaves.blockID, 12, 2);
		world.setBlock(i + 16, j + 28, k + 43, Block.leaves.blockID, 12, 2);
		world.setBlock(i + 16, j + 28, k + 44, Block.leaves.blockID, 12, 2);
		world.setBlock(i + 16, j + 28, k + 45, Block.leaves.blockID, 12, 2);
		world.setBlock(i + 16, j + 28, k + 48, Block.leaves.blockID, 12, 2);
		world.setBlock(i + 16, j + 29, k + 26, Block.leaves.blockID, 12, 2);
		world.setBlock(i + 16, j + 29, k + 27, Block.leaves.blockID, 12, 2);
		world.setBlock(i + 16, j + 29, k + 35, Block.leaves.blockID, 12, 2);
		world.setBlock(i + 16, j + 29, k + 36, Block.leaves.blockID, 12, 2);
		world.setBlock(i + 16, j + 29, k + 41, Block.leaves.blockID, 12, 2);
		world.setBlock(i + 16, j + 29, k + 44, Block.leaves.blockID, 12, 2);
		world.setBlock(i + 16, j + 29, k + 45, Block.leaves.blockID, 12, 2);
		world.setBlock(i + 16, j + 29, k + 48, Block.leaves.blockID, 12, 2);
		world.setBlock(i + 16, j + 29, k + 49, Block.leaves.blockID, 12, 2);
		world.setBlock(i + 16, j + 30, k + 26, Block.leaves.blockID, 12, 2);
		world.setBlock(i + 16, j + 30, k + 34, Block.leaves.blockID, 12, 2);
		world.setBlock(i + 16, j + 30, k + 35, Block.leaves.blockID, 12, 2);
		world.setBlock(i + 16, j + 30, k + 44, Block.leaves.blockID, 12, 2);
		world.setBlock(i + 16, j + 30, k + 45, Block.leaves.blockID, 12, 2);
		world.setBlock(i + 16, j + 30, k + 49, Block.leaves.blockID, 12, 2);
		world.setBlock(i + 16, j + 30, k + 50, Block.leaves.blockID, 12, 2);
		world.setBlock(i + 16, j + 31, k + 26, Block.leaves.blockID, 12, 2);
		world.setBlock(i + 16, j + 31, k + 30, Block.leaves.blockID, 12, 2);
		world.setBlock(i + 16, j + 31, k + 31, Block.leaves.blockID, 12, 2);
		world.setBlock(i + 16, j + 31, k + 34, Block.leaves.blockID, 12, 2);
		world.setBlock(i + 16, j + 31, k + 44, Block.leaves.blockID, 12, 2);
		world.setBlock(i + 16, j + 31, k + 45, Block.leaves.blockID, 12, 2);
		world.setBlock(i + 16, j + 31, k + 46, Block.leaves.blockID, 12, 2);
		world.setBlock(i + 16, j + 31, k + 48, Block.leaves.blockID, 12, 2);
		world.setBlock(i + 16, j + 31, k + 49, Block.leaves.blockID, 12, 2);
		world.setBlock(i + 16, j + 31, k + 50, Block.leaves.blockID, 12, 2);
		world.setBlock(i + 16, j + 31, k + 51, Block.leaves.blockID, 12, 2);
		world.setBlock(i + 16, j + 31, k + 52, Block.leaves.blockID, 12, 2);
		world.setBlock(i + 16, j + 31, k + 53, Block.leaves.blockID, 12, 2);
		world.setBlock(i + 16, j + 32, k + 28, Block.leaves.blockID, 12, 2);
		world.setBlock(i + 16, j + 32, k + 29, Block.leaves.blockID, 12, 2);
		world.setBlock(i + 16, j + 32, k + 30, Block.leaves.blockID, 12, 2);
		world.setBlock(i + 16, j + 32, k + 31, Block.leaves.blockID, 12, 2);
		world.setBlock(i + 16, j + 32, k + 33, Block.leaves.blockID, 12, 2);
		world.setBlock(i + 16, j + 32, k + 34, Block.leaves.blockID, 12, 2);
		world.setBlock(i + 16, j + 32, k + 36, Block.leaves.blockID, 12, 2);
		world.setBlock(i + 16, j + 32, k + 37, Block.leaves.blockID, 12, 2);
		world.setBlock(i + 16, j + 32, k + 42, Block.leaves.blockID, 12, 2);
		world.setBlock(i + 16, j + 32, k + 43, Block.leaves.blockID, 12, 2);
		world.setBlock(i + 16, j + 32, k + 44, Block.leaves.blockID, 12, 2);
		world.setBlock(i + 16, j + 32, k + 47, Block.leaves.blockID, 12, 2);
		world.setBlock(i + 16, j + 32, k + 48, Block.leaves.blockID, 12, 2);
		world.setBlock(i + 16, j + 33, k + 27, Block.leaves.blockID, 12, 2);
		world.setBlock(i + 16, j + 33, k + 30, Block.leaves.blockID, 12, 2);
		world.setBlock(i + 16, j + 33, k + 31, Block.leaves.blockID, 12, 2);
		world.setBlock(i + 16, j + 33, k + 32, Block.leaves.blockID, 12, 2);
		world.setBlock(i + 16, j + 33, k + 33, Block.leaves.blockID, 12, 2);
		world.setBlock(i + 16, j + 33, k + 37, Block.leaves.blockID, 12, 2);
		world.setBlock(i + 16, j + 33, k + 38, Block.leaves.blockID, 12, 2);
		world.setBlock(i + 16, j + 33, k + 39, Block.leaves.blockID, 12, 2);
		world.setBlock(i + 16, j + 33, k + 40, Block.leaves.blockID, 4, 2);
		world.setBlock(i + 16, j + 33, k + 41, Block.leaves.blockID, 4, 2);
		world.setBlock(i + 16, j + 33, k + 42, Block.leaves.blockID, 12, 2);
		world.setBlock(i + 16, j + 34, k + 33, Block.leaves.blockID, 12, 2);
		world.setBlock(i + 16, j + 34, k + 39, Block.leaves.blockID, 4, 2);
		world.setBlock(i + 16, j + 34, k + 40, Block.leaves.blockID, 4, 2);
		world.setBlock(i + 16, j + 34, k + 41, Block.leaves.blockID, 4, 2);
		world.setBlock(i + 16, j + 34, k + 49, Block.leaves.blockID, 12, 2);
		world.setBlock(i + 16, j + 35, k + 39, Block.leaves.blockID, 4, 2);
		world.setBlock(i + 16, j + 35, k + 41, Block.leaves.blockID, 4, 2);
		world.setBlock(i + 16, j + 35, k + 42, Block.leaves.blockID, 12, 2);
		world.setBlock(i + 16, j + 35, k + 45, Block.leaves.blockID, 12, 2);
		world.setBlock(i + 16, j + 35, k + 46, Block.leaves.blockID, 12, 2);
		world.setBlock(i + 16, j + 35, k + 47, Block.leaves.blockID, 12, 2);
		world.setBlock(i + 16, j + 35, k + 48, Block.leaves.blockID, 12, 2);
		world.setBlock(i + 16, j + 36, k + 43, Block.leaves.blockID, 12, 2);
		world.setBlock(i + 16, j + 36, k + 44, Block.leaves.blockID, 12, 2);
		world.setBlock(i + 16, j + 36, k + 45, Block.leaves.blockID, 12, 2);
		world.setBlock(i + 16, j + 37, k + 43, Block.leaves.blockID, 12, 2);
		world.setBlock(i + 16, j + 38, k + 43, Block.leaves.blockID, 12, 2);
		world.setBlock(i + 16, j + 38, k + 46, Block.wood.blockID, 12, 2);
		world.setBlock(i + 16, j + 38, k + 50, Block.leaves.blockID, 12, 2);
		world.setBlock(i + 16, j + 38, k + 51, Block.leaves.blockID, 12, 2);
		world.setBlock(i + 16, j + 39, k + 43, Block.leaves.blockID, 12, 2);
		world.setBlock(i + 16, j + 39, k + 51, Block.leaves.blockID, 12, 2);
		world.setBlock(i + 16, j + 39, k + 52, Block.leaves.blockID, 4, 2);
		world.setBlock(i + 16, j + 40, k + 43, Block.leaves.blockID, 12, 2);
		world.setBlock(i + 16, j + 40, k + 45, Block.leaves.blockID, 12, 2);
		world.setBlock(i + 16, j + 40, k + 46, Block.leaves.blockID, 12, 2);
		world.setBlock(i + 16, j + 41, k + 46, Block.leaves.blockID, 12, 2);
		world.setBlock(i + 16, j + 42, k + 46, Block.leaves.blockID, 12, 2);
		world.setBlock(i + 16, j + 43, k + 46, Block.leaves.blockID, 12, 2);
		world.setBlock(i + 16, j + 44, k + 46, Block.leaves.blockID, 4, 2);
		world.setBlock(i + 16, j + 45, k + 46, Block.leaves.blockID, 4, 2);
		world.setBlock(i + 16, j + 46, k + 46, Block.leaves.blockID, 4, 2);
		world.setBlock(i + 16, j + 46, k + 47, Block.leaves.blockID, 4, 2);
		world.setBlock(i + 16, j + 47, k + 45, Block.leaves.blockID, 4, 2);
		world.setBlock(i + 16, j + 47, k + 46, Block.leaves.blockID, 4, 2);
		world.setBlock(i + 16, j + 47, k + 47, Block.leaves.blockID, 4, 2);
		world.setBlock(i + 16, j + 47, k + 48, Block.leaves.blockID, 4, 2);
		world.setBlock(i + 16, j + 47, k + 49, Block.leaves.blockID, 4, 2);
		world.setBlock(i + 16, j + 48, k + 45, Block.leaves.blockID, 4, 2);
		world.setBlock(i + 16, j + 48, k + 48, Block.leaves.blockID, 4, 2);
		world.setBlock(i + 16, j + 48, k + 49, Block.leaves.blockID, 4, 2);
		world.setBlock(i + 16, j + 48, k + 50, Block.leaves.blockID, 4, 2);
		world.setBlock(i + 16, j + 49, k + 44, Block.leaves.blockID, 4, 2);
		world.setBlock(i + 16, j + 49, k + 45, Block.leaves.blockID, 4, 2);
		world.setBlock(i + 17, j + 11, k + 44, Block.leaves.blockID, 15, 2);
		world.setBlock(i + 17, j + 12, k + 44, Block.leaves.blockID, 15, 2);
		world.setBlock(i + 17, j + 13, k + 44, Block.leaves.blockID, 15, 2);
		world.setBlock(i + 17, j + 14, k + 44, Block.leaves.blockID, 15, 2);
		world.setBlock(i + 17, j + 15, k + 44, Block.leaves.blockID, 15, 2);
		world.setBlock(i + 17, j + 16, k + 44, Block.leaves.blockID, 15, 2);
		world.setBlock(i + 17, j + 17, k + 34, Block.leaves.blockID, 12, 2);
		world.setBlock(i + 17, j + 17, k + 35, Block.leaves.blockID, 12, 2);
		world.setBlock(i + 17, j + 17, k + 42, Block.leaves.blockID, 12, 2);
		world.setBlock(i + 17, j + 17, k + 44, Block.leaves.blockID, 15, 2);
		world.setBlock(i + 17, j + 18, k + 33, Block.leaves.blockID, 12, 2);
		world.setBlock(i + 17, j + 18, k + 34, Block.leaves.blockID, 12, 2);
		world.setBlock(i + 17, j + 18, k + 42, Block.leaves.blockID, 12, 2);
		world.setBlock(i + 17, j + 18, k + 43, Block.leaves.blockID, 12, 2);
		world.setBlock(i + 17, j + 18, k + 44, Block.leaves.blockID, 12, 2);
		world.setBlock(i + 17, j + 18, k + 45, Block.leaves.blockID, 12, 2);
		world.setBlock(i + 17, j + 18, k + 46, Block.leaves.blockID, 12, 2);
		world.setBlock(i + 17, j + 18, k + 47, Block.leaves.blockID, 12, 2);
		world.setBlock(i + 17, j + 19, k + 28, Block.leaves.blockID, 12, 2);
		world.setBlock(i + 17, j + 19, k + 29, Block.leaves.blockID, 12, 2);
		world.setBlock(i + 17, j + 19, k + 32, Block.leaves.blockID, 12, 2);
		world.setBlock(i + 17, j + 19, k + 33, Block.leaves.blockID, 12, 2);
		world.setBlock(i + 17, j + 19, k + 41, Block.leaves.blockID, 12, 2);
		world.setBlock(i + 17, j + 19, k + 42, Block.leaves.blockID, 12, 2);
		world.setBlock(i + 17, j + 19, k + 43, Block.leaves.blockID, 12, 2);
		world.setBlock(i + 17, j + 19, k + 44, Block.leaves.blockID, 12, 2);
		world.setBlock(i + 17, j + 19, k + 45, Block.leaves.blockID, 12, 2);
		world.setBlock(i + 17, j + 20, k + 32, Block.leaves.blockID, 12, 2);
		world.setBlock(i + 17, j + 20, k + 35, Block.leaves.blockID, 12, 2);
		world.setBlock(i + 17, j + 20, k + 36, Block.leaves.blockID, 12, 2);
		world.setBlock(i + 17, j + 20, k + 40, Block.leaves.blockID, 12, 2);
		world.setBlock(i + 17, j + 20, k + 41, Block.leaves.blockID, 12, 2);
		world.setBlock(i + 17, j + 20, k + 42, Block.leaves.blockID, 12, 2);
		world.setBlock(i + 17, j + 20, k + 43, Block.leaves.blockID, 12, 2);
		world.setBlock(i + 17, j + 20, k + 44, Block.leaves.blockID, 12, 2);
		world.setBlock(i + 17, j + 20, k + 45, Block.leaves.blockID, 12, 2);
		world.setBlock(i + 17, j + 20, k + 46, Block.leaves.blockID, 12, 2);
		world.setBlock(i + 17, j + 20, k + 47, Block.leaves.blockID, 12, 2);
		world.setBlock(i + 17, j + 20, k + 48, Block.leaves.blockID, 12, 2);
		world.setBlock(i + 17, j + 21, k + 26, Block.leaves.blockID, 12, 2);
		world.setBlock(i + 17, j + 21, k + 27, Block.leaves.blockID, 12, 2);
		world.setBlock(i + 17, j + 21, k + 28, Block.leaves.blockID, 12, 2);
		world.setBlock(i + 17, j + 21, k + 29, Block.leaves.blockID, 12, 2);
		world.setBlock(i + 17, j + 21, k + 30, Block.leaves.blockID, 12, 2);
		world.setBlock(i + 17, j + 21, k + 31, Block.leaves.blockID, 12, 2);
		world.setBlock(i + 17, j + 21, k + 32, Block.leaves.blockID, 12, 2);
		world.setBlock(i + 17, j + 21, k + 33, Block.leaves.blockID, 12, 2);
		world.setBlock(i + 17, j + 21, k + 34, Block.leaves.blockID, 12, 2);
		world.setBlock(i + 17, j + 21, k + 35, Block.leaves.blockID, 12, 2);
		world.setBlock(i + 17, j + 21, k + 36, Block.leaves.blockID, 12, 2);
		world.setBlock(i + 17, j + 21, k + 37, Block.leaves.blockID, 12, 2);
		world.setBlock(i + 17, j + 21, k + 38, Block.leaves.blockID, 12, 2);
		world.setBlock(i + 17, j + 21, k + 39, Block.leaves.blockID, 12, 2);
		world.setBlock(i + 17, j + 21, k + 40, Block.leaves.blockID, 12, 2);
		world.setBlock(i + 17, j + 21, k + 41, Block.leaves.blockID, 12, 2);
		world.setBlock(i + 17, j + 21, k + 42, Block.leaves.blockID, 12, 2);
		world.setBlock(i + 17, j + 21, k + 43, Block.leaves.blockID, 12, 2);
		world.setBlock(i + 17, j + 21, k + 44, Block.leaves.blockID, 12, 2);
		world.setBlock(i + 17, j + 21, k + 45, Block.leaves.blockID, 12, 2);
		world.setBlock(i + 17, j + 21, k + 46, Block.leaves.blockID, 12, 2);
		world.setBlock(i + 17, j + 21, k + 47, Block.leaves.blockID, 12, 2);
		world.setBlock(i + 17, j + 21, k + 48, Block.leaves.blockID, 12, 2);
		world.setBlock(i + 17, j + 21, k + 49, Block.leaves.blockID, 12, 2);
		world.setBlock(i + 17, j + 21, k + 50, Block.leaves.blockID, 12, 2);
		world.setBlock(i + 17, j + 21, k + 51, Block.leaves.blockID, 12, 2);
		world.setBlock(i + 17, j + 21, k + 52, Block.leaves.blockID, 12, 2);
		world.setBlock(i + 17, j + 21, k + 53, Block.leaves.blockID, 4, 2);
		world.setBlock(i + 17, j + 21, k + 54, Block.leaves.blockID, 4, 2);
		world.setBlock(i + 17, j + 22, k + 26, Block.leaves.blockID, 12, 2);
		world.setBlock(i + 17, j + 22, k + 27, Block.leaves.blockID, 12, 2);
		world.setBlock(i + 17, j + 22, k + 28, Block.leaves.blockID, 12, 2);
		world.setBlock(i + 17, j + 22, k + 29, Block.leaves.blockID, 12, 2);
		world.setBlock(i + 17, j + 22, k + 30, Block.leaves.blockID, 12, 2);
		world.setBlock(i + 17, j + 22, k + 34, Block.leaves.blockID, 12, 2);
		world.setBlock(i + 17, j + 22, k + 37, Block.leaves.blockID, 12, 2);
		world.setBlock(i + 17, j + 22, k + 38, Block.wood.blockID, 12, 2);
		world.setBlock(i + 17, j + 22, k + 39, Block.wood.blockID, 12, 2);
		world.setBlock(i + 17, j + 22, k + 40, Block.wood.blockID, 12, 2);
		world.setBlock(i + 17, j + 22, k + 44, Block.leaves.blockID, 12, 2);
		world.setBlock(i + 17, j + 22, k + 45, Block.leaves.blockID, 12, 2);
		world.setBlock(i + 17, j + 22, k + 46, Block.leaves.blockID, 12, 2);
		world.setBlock(i + 17, j + 22, k + 47, Block.leaves.blockID, 12, 2);
		world.setBlock(i + 17, j + 23, k + 27, Block.leaves.blockID, 12, 2);
		world.setBlock(i + 17, j + 23, k + 28, Block.leaves.blockID, 12, 2);
		world.setBlock(i + 17, j + 23, k + 29, Block.leaves.blockID, 12, 2);
		world.setBlock(i + 17, j + 23, k + 34, Block.leaves.blockID, 12, 2);
		world.setBlock(i + 17, j + 23, k + 35, Block.leaves.blockID, 12, 2);
		world.setBlock(i + 17, j + 23, k + 36, Block.leaves.blockID, 12, 2);
		world.setBlock(i + 17, j + 23, k + 37, Block.leaves.blockID, 12, 2);
		world.setBlock(i + 17, j + 23, k + 38, Block.wood.blockID, 12, 2);
		world.setBlock(i + 17, j + 23, k + 39, Block.wood.blockID, 12, 2);
		world.setBlock(i + 17, j + 23, k + 44, Block.leaves.blockID, 12, 2);
		world.setBlock(i + 17, j + 23, k + 45, Block.leaves.blockID, 12, 2);
		world.setBlock(i + 17, j + 23, k + 46, Block.leaves.blockID, 12, 2);
		world.setBlock(i + 17, j + 23, k + 47, Block.leaves.blockID, 12, 2);
		world.setBlock(i + 17, j + 23, k + 48, Block.leaves.blockID, 12, 2);
		world.setBlock(i + 17, j + 24, k + 28, Block.leaves.blockID, 12, 2);
		world.setBlock(i + 17, j + 24, k + 29, Block.leaves.blockID, 12, 2);
		world.setBlock(i + 17, j + 24, k + 30, Block.leaves.blockID, 12, 2);
		world.setBlock(i + 17, j + 24, k + 32, Block.leaves.blockID, 12, 2);
		world.setBlock(i + 17, j + 24, k + 33, Block.leaves.blockID, 12, 2);
		world.setBlock(i + 17, j + 24, k + 34, Block.leaves.blockID, 12, 2);
		world.setBlock(i + 17, j + 24, k + 35, Block.leaves.blockID, 12, 2);
		world.setBlock(i + 17, j + 24, k + 38, Block.wood.blockID, 12, 2);
		world.setBlock(i + 17, j + 24, k + 39, Block.wood.blockID, 12, 2);
		world.setBlock(i + 17, j + 24, k + 40, Block.leaves.blockID, 12, 2);
		world.setBlock(i + 17, j + 24, k + 44, Block.leaves.blockID, 12, 2);
		world.setBlock(i + 17, j + 24, k + 46, Block.leaves.blockID, 12, 2);
		world.setBlock(i + 17, j + 24, k + 48, Block.leaves.blockID, 12, 2);
		world.setBlock(i + 17, j + 24, k + 49, Block.leaves.blockID, 12, 2);
		world.setBlock(i + 17, j + 25, k + 25, Block.leaves.blockID, 12, 2);
		world.setBlock(i + 17, j + 25, k + 26, Block.leaves.blockID, 12, 2);
		world.setBlock(i + 17, j + 25, k + 27, Block.leaves.blockID, 12, 2);
		world.setBlock(i + 17, j + 25, k + 28, Block.wood.blockID, 12, 2);
		world.setBlock(i + 17, j + 25, k + 29, Block.leaves.blockID, 12, 2);
		world.setBlock(i + 17, j + 25, k + 30, Block.leaves.blockID, 12, 2);
		world.setBlock(i + 17, j + 25, k + 38, Block.wood.blockID, 12, 2);
		world.setBlock(i + 17, j + 25, k + 39, Block.leaves.blockID, 12, 2);
		world.setBlock(i + 17, j + 25, k + 40, Block.leaves.blockID, 12, 2);
		world.setBlock(i + 17, j + 25, k + 44, Block.leaves.blockID, 12, 2);
		world.setBlock(i + 17, j + 25, k + 45, Block.leaves.blockID, 12, 2);
		world.setBlock(i + 17, j + 25, k + 50, Block.leaves.blockID, 12, 2);
		world.setBlock(i + 17, j + 25, k + 51, Block.leaves.blockID, 12, 2);
		world.setBlock(i + 17, j + 26, k + 24, Block.leaves.blockID, 12, 2);
		world.setBlock(i + 17, j + 26, k + 25, Block.leaves.blockID, 12, 2);
		world.setBlock(i + 17, j + 26, k + 28, Block.wood.blockID, 12, 2);
		world.setBlock(i + 17, j + 26, k + 30, Block.leaves.blockID, 12, 2);
		world.setBlock(i + 17, j + 26, k + 38, Block.leaves.blockID, 12, 2);
		world.setBlock(i + 17, j + 26, k + 39, Block.leaves.blockID, 12, 2);
		world.setBlock(i + 17, j + 26, k + 45, Block.leaves.blockID, 12, 2);
		world.setBlock(i + 17, j + 26, k + 50, Block.leaves.blockID, 12, 2);
		world.setBlock(i + 17, j + 26, k + 51, Block.leaves.blockID, 12, 2);
		world.setBlock(i + 17, j + 26, k + 52, Block.leaves.blockID, 12, 2);
		world.setBlock(i + 17, j + 27, k + 27, Block.leaves.blockID, 12, 2);
		world.setBlock(i + 17, j + 27, k + 28, Block.leaves.blockID, 12, 2);
		world.setBlock(i + 17, j + 27, k + 30, Block.leaves.blockID, 12, 2);
		world.setBlock(i + 17, j + 27, k + 36, Block.leaves.blockID, 12, 2);
		world.setBlock(i + 17, j + 27, k + 37, Block.leaves.blockID, 12, 2);
		world.setBlock(i + 17, j + 27, k + 38, Block.leaves.blockID, 12, 2);
		world.setBlock(i + 17, j + 27, k + 45, Block.leaves.blockID, 12, 2);
		world.setBlock(i + 17, j + 27, k + 48, Block.leaves.blockID, 12, 2);
		world.setBlock(i + 17, j + 27, k + 52, Block.leaves.blockID, 12, 2);
		world.setBlock(i + 17, j + 27, k + 53, Block.leaves.blockID, 12, 2);
		world.setBlock(i + 17, j + 28, k + 27, Block.leaves.blockID, 12, 2);
		world.setBlock(i + 17, j + 28, k + 35, Block.leaves.blockID, 12, 2);
		world.setBlock(i + 17, j + 28, k + 36, Block.leaves.blockID, 12, 2);
		world.setBlock(i + 17, j + 28, k + 45, Block.leaves.blockID, 12, 2);
		world.setBlock(i + 17, j + 28, k + 48, Block.leaves.blockID, 12, 2);
		world.setBlock(i + 17, j + 28, k + 54, Block.leaves.blockID, 12, 2);
		world.setBlock(i + 17, j + 29, k + 26, Block.leaves.blockID, 12, 2);
		world.setBlock(i + 17, j + 29, k + 27, Block.leaves.blockID, 12, 2);
		world.setBlock(i + 17, j + 29, k + 35, Block.leaves.blockID, 12, 2);
		world.setBlock(i + 17, j + 29, k + 44, Block.leaves.blockID, 12, 2);
		world.setBlock(i + 17, j + 29, k + 45, Block.leaves.blockID, 12, 2);
		world.setBlock(i + 17, j + 29, k + 48, Block.leaves.blockID, 12, 2);
		world.setBlock(i + 17, j + 29, k + 49, Block.leaves.blockID, 12, 2);
		world.setBlock(i + 17, j + 29, k + 52, Block.leaves.blockID, 12, 2);
		world.setBlock(i + 17, j + 30, k + 26, Block.leaves.blockID, 12, 2);
		world.setBlock(i + 17, j + 30, k + 34, Block.leaves.blockID, 12, 2);
		world.setBlock(i + 17, j + 30, k + 44, Block.leaves.blockID, 12, 2);
		world.setBlock(i + 17, j + 30, k + 45, Block.leaves.blockID, 12, 2);
		world.setBlock(i + 17, j + 30, k + 48, Block.leaves.blockID, 12, 2);
		world.setBlock(i + 17, j + 30, k + 49, Block.leaves.blockID, 12, 2);
		world.setBlock(i + 17, j + 30, k + 50, Block.leaves.blockID, 12, 2);
		world.setBlock(i + 17, j + 30, k + 51, Block.leaves.blockID, 12, 2);
		world.setBlock(i + 17, j + 30, k + 52, Block.leaves.blockID, 12, 2);
		world.setBlock(i + 17, j + 31, k + 26, Block.leaves.blockID, 12, 2);
		world.setBlock(i + 17, j + 31, k + 27, Block.leaves.blockID, 12, 2);
		world.setBlock(i + 17, j + 31, k + 28, Block.leaves.blockID, 12, 2);
		world.setBlock(i + 17, j + 31, k + 29, Block.leaves.blockID, 12, 2);
		world.setBlock(i + 17, j + 31, k + 30, Block.leaves.blockID, 12, 2);
		world.setBlock(i + 17, j + 31, k + 31, Block.leaves.blockID, 12, 2);
		world.setBlock(i + 17, j + 31, k + 33, Block.leaves.blockID, 12, 2);
		world.setBlock(i + 17, j + 31, k + 34, Block.leaves.blockID, 12, 2);
		world.setBlock(i + 17, j + 31, k + 36, Block.leaves.blockID, 12, 2);
		world.setBlock(i + 17, j + 31, k + 43, Block.leaves.blockID, 12, 2);
		world.setBlock(i + 17, j + 31, k + 44, Block.leaves.blockID, 12, 2);
		world.setBlock(i + 17, j + 31, k + 45, Block.leaves.blockID, 12, 2);
		world.setBlock(i + 17, j + 31, k + 46, Block.leaves.blockID, 12, 2);
		world.setBlock(i + 17, j + 31, k + 47, Block.leaves.blockID, 12, 2);
		world.setBlock(i + 17, j + 31, k + 48, Block.leaves.blockID, 12, 2);
		world.setBlock(i + 17, j + 31, k + 52, Block.leaves.blockID, 12, 2);
		world.setBlock(i + 17, j + 31, k + 53, Block.leaves.blockID, 12, 2);
		world.setBlock(i + 17, j + 32, k + 27, Block.leaves.blockID, 12, 2);
		world.setBlock(i + 17, j + 32, k + 28, Block.leaves.blockID, 12, 2);
		world.setBlock(i + 17, j + 32, k + 29, Block.leaves.blockID, 12, 2);
		world.setBlock(i + 17, j + 32, k + 30, Block.leaves.blockID, 12, 2);
		world.setBlock(i + 17, j + 32, k + 31, Block.leaves.blockID, 12, 2);
		world.setBlock(i + 17, j + 32, k + 32, Block.leaves.blockID, 12, 2);
		world.setBlock(i + 17, j + 32, k + 33, Block.leaves.blockID, 12, 2);
		world.setBlock(i + 17, j + 32, k + 36, Block.leaves.blockID, 12, 2);
		world.setBlock(i + 17, j + 32, k + 37, Block.leaves.blockID, 12, 2);
		world.setBlock(i + 17, j + 32, k + 38, Block.leaves.blockID, 12, 2);
		world.setBlock(i + 17, j + 32, k + 41, Block.leaves.blockID, 12, 2);
		world.setBlock(i + 17, j + 32, k + 42, Block.leaves.blockID, 12, 2);
		world.setBlock(i + 17, j + 32, k + 43, Block.leaves.blockID, 12, 2);
		world.setBlock(i + 17, j + 32, k + 46, Block.leaves.blockID, 12, 2);
		world.setBlock(i + 17, j + 32, k + 47, Block.leaves.blockID, 12, 2);
		world.setBlock(i + 17, j + 32, k + 50, Block.leaves.blockID, 12, 2);
		world.setBlock(i + 17, j + 32, k + 51, Block.leaves.blockID, 12, 2);
		world.setBlock(i + 17, j + 32, k + 56, Block.leaves.blockID, 4, 2);
		world.setBlock(i + 17, j + 33, k + 28, Block.leaves.blockID, 12, 2);
		world.setBlock(i + 17, j + 33, k + 33, Block.leaves.blockID, 12, 2);
		world.setBlock(i + 17, j + 33, k + 38, Block.leaves.blockID, 12, 2);
		world.setBlock(i + 17, j + 33, k + 39, Block.leaves.blockID, 12, 2);
		world.setBlock(i + 17, j + 33, k + 40, Block.leaves.blockID, 12, 2);
		world.setBlock(i + 17, j + 33, k + 41, Block.leaves.blockID, 4, 2);
		world.setBlock(i + 17, j + 33, k + 51, Block.leaves.blockID, 12, 2);
		world.setBlock(i + 17, j + 33, k + 52, Block.leaves.blockID, 12, 2);
		world.setBlock(i + 17, j + 33, k + 53, Block.leaves.blockID, 12, 2);
		world.setBlock(i + 17, j + 34, k + 33, Block.leaves.blockID, 12, 2);
		world.setBlock(i + 17, j + 34, k + 39, Block.leaves.blockID, 4, 2);
		world.setBlock(i + 17, j + 34, k + 40, Block.leaves.blockID, 4, 2);
		world.setBlock(i + 17, j + 34, k + 41, Block.leaves.blockID, 4, 2);
		world.setBlock(i + 17, j + 34, k + 48, Block.leaves.blockID, 12, 2);
		world.setBlock(i + 17, j + 34, k + 49, Block.leaves.blockID, 12, 2);
		world.setBlock(i + 17, j + 35, k + 39, Block.leaves.blockID, 4, 2);
		world.setBlock(i + 17, j + 35, k + 42, Block.leaves.blockID, 12, 2);
		world.setBlock(i + 17, j + 35, k + 43, Block.leaves.blockID, 12, 2);
		world.setBlock(i + 17, j + 35, k + 45, Block.leaves.blockID, 12, 2);
		world.setBlock(i + 17, j + 35, k + 46, Block.leaves.blockID, 12, 2);
		world.setBlock(i + 17, j + 35, k + 47, Block.leaves.blockID, 12, 2);
		world.setBlock(i + 17, j + 35, k + 48, Block.leaves.blockID, 12, 2);
		world.setBlock(i + 17, j + 35, k + 55, Block.leaves.blockID, 4, 2);
		world.setBlock(i + 17, j + 36, k + 43, Block.leaves.blockID, 12, 2);
		world.setBlock(i + 17, j + 36, k + 44, Block.leaves.blockID, 12, 2);
		world.setBlock(i + 17, j + 36, k + 45, Block.leaves.blockID, 12, 2);
		world.setBlock(i + 17, j + 36, k + 48, Block.leaves.blockID, 12, 2);
		world.setBlock(i + 17, j + 36, k + 49, Block.leaves.blockID, 12, 2);
		world.setBlock(i + 17, j + 37, k + 43, Block.leaves.blockID, 12, 2);
		world.setBlock(i + 17, j + 37, k + 44, Block.leaves.blockID, 12, 2);
		world.setBlock(i + 17, j + 37, k + 46, Block.wood.blockID, 12, 2);
		world.setBlock(i + 17, j + 37, k + 47, Block.wood.blockID, 12, 2);
		world.setBlock(i + 17, j + 37, k + 49, Block.leaves.blockID, 12, 2);
		world.setBlock(i + 17, j + 37, k + 50, Block.leaves.blockID, 12, 2);
		world.setBlock(i + 17, j + 38, k + 43, Block.leaves.blockID, 12, 2);
		world.setBlock(i + 17, j + 38, k + 44, Block.leaves.blockID, 12, 2);
		world.setBlock(i + 17, j + 38, k + 46, Block.wood.blockID, 12, 2);
		world.setBlock(i + 17, j + 38, k + 47, Block.wood.blockID, 12, 2);
