package biomesoplenty.common.world.features;

import java.util.Random;

import net.minecraft.block.Block;
import net.minecraft.world.World;
import net.minecraft.world.biome.BiomeGenBase;
import biomesoplenty.api.content.BOPCBlocks;
import biomesoplenty.common.world.decoration.BOPDecorationManager;
import biomesoplenty.common.world.generation.WorldGeneratorBOP;

public class WorldGenWasteland extends WorldGeneratorBOP
{
    @Override
    public boolean generate(World world, Random random, int x, int y, int z)
    {
        //TODO:      isAirBlock()
        while (world.isAirBlock(x, y, z) && y > 2)
        {
            --y;
        }

        //TODO:             getBlock()
        Block block = world.getBlock(x, y, z);

        if (block != BOPCBlocks.driedDirt)
        {
            return false;
        }
        else
        {
            for (int var7 = -2; var7 <= 2; ++var7)
            {
                for (int var8 = -2; var8 <= 2; ++var8)
                {
                    //TODO:  isAirBlock()                                               isAirBlock()                                                isAirBlock()
                    if (world.isAirBlock(x + var7, y - 1, z + var8) && world.isAirBlock(x + var7, y - 2, z + var8) && !world.isAirBlock(x + var7, y, z + var8))
                    {
                        return false;
                    }
                }
            }

            world.setBlock(x, y, z, BOPCBlocks.driedDirt);

            world.setBlock(x - 1, y, z, BOPCBlocks.driedDirt);
            world.setBlock(x + 1, y, z, BOPCBlocks.driedDirt);
            world.setBlock(x, y, z - 1, BOPCBlocks.driedDirt);
            world.setBlock(x, y, z + 1, BOPCBlocks.driedDirt);

            world.setBlock(x - 1, y, z - 1, BOPCBlocks.driedDirt);
            world.setBlock(x + 1, y, z + 1, BOPCBlocks.driedDirt);
            world.setBlock(x - 1, y, z + 1, BOPCBlocks.driedDirt);
            world.setBlock(x + 1, y, z - 1, BOPCBlocks.driedDirt);

            world.setBlock(x - 2, y, z - 1, BOPCBlocks.driedDirt);
            world.setBlock(x - 2, y, z, BOPCBlocks.driedDirt);
            world.setBlock(x - 2, y, z + 1, BOPCBlocks.driedDirt);
            world.setBlock(x + 2, y, z - 1, BOPCBlocks.driedDirt);
            world.setBlock(x + 2, y, z, BOPCBlocks.driedDirt);
            world.setBlock(x + 2, y, z + 1, BOPCBlocks.driedDirt);
            world.setBlock(x - 1, y, z - 2, BOPCBlocks.driedDirt);
            world.setBlock(x, y, z - 2, BOPCBlocks.driedDirt);
            world.setBlock(x + 1, y, z - 2, BOPCBlocks.driedDirt);
            world.setBlock(x - 1, y, z + 2, BOPCBlocks.driedDirt);
            world.setBlock(x, y, z + 2, BOPCBlocks.driedDirt);
            world.setBlock(x + 1, y, z + 2, BOPCBlocks.driedDirt);

            world.setBlock(x, y + 1, z, BOPCBlocks.driedDirt);

            world.setBlock(x - 1, y + 1, z, BOPCBlocks.driedDirt);
            world.setBlock(x + 1, y + 1, z, BOPCBlocks.driedDirt);
            world.setBlock(x, y + 1, z - 1, BOPCBlocks.driedDirt);
            world.setBlock(x, y + 1, z + 1, BOPCBlocks.driedDirt);

            world.setBlock(x - 1, y + 1, z - 1, BOPCBlocks.driedDirt);
            world.setBlock(x + 1, y + 1, z + 1, BOPCBlocks.driedDirt);
            world.setBlock(x - 1, y + 1, z + 1, BOPCBlocks.driedDirt);
            world.setBlock(x + 1, y + 1, z - 1, BOPCBlocks.driedDirt);

            world.setBlock(x - 2, y + 1, z - 1, BOPCBlocks.driedDirt);
            world.setBlock(x - 2, y + 1, z, BOPCBlocks.driedDirt);
            world.setBlock(x - 2, y + 1, z + 1, BOPCBlocks.driedDirt);
            world.setBlock(x + 2, y + 1, z - 1, BOPCBlocks.driedDirt);
            world.setBlock(x + 2, y + 1, z, BOPCBlocks.driedDirt);
            world.setBlock(x + 2, y + 1, z + 1, BOPCBlocks.driedDirt);
            world.setBlock(x - 1, y + 1, z - 2, BOPCBlocks.driedDirt);
            world.setBlock(x, y + 1, z - 2, BOPCBlocks.driedDirt);
            world.setBlock(x + 1, y + 1, z - 2, BOPCBlocks.driedDirt);
            world.setBlock(x - 1, y + 1, z + 2, BOPCBlocks.driedDirt);
            world.setBlock(x, y + 1, z + 2, BOPCBlocks.driedDirt);
            world.setBlock(x + 1, y + 1, z + 2, BOPCBlocks.driedDirt);

            world.setBlock(x - 1, y + 2, z, BOPCBlocks.driedDirt);
            world.setBlock(x + 1, y + 2, z, BOPCBlocks.driedDirt);
            world.setBlock(x, y + 2, z - 1, BOPCBlocks.driedDirt);
            world.setBlock(x, y + 2, z + 1, BOPCBlocks.driedDirt);
            world.setBlock(x - 1, y + 2, z - 1, BOPCBlocks.driedDirt);
            world.setBlock(x + 1, y + 2, z + 1, BOPCBlocks.driedDirt);
            world.setBlock(x - 1, y + 2, z + 1, BOPCBlocks.driedDirt);
            world.setBlock(x + 1, y + 2, z - 1, BOPCBlocks.driedDirt);

            world.setBlock(x, y + 2, z, BOPCBlocks.driedDirt);

            world.setBlock(x - 1, y + 3, z, BOPCBlocks.driedDirt);
            world.setBlock(x + 1, y + 3, z, BOPCBlocks.driedDirt);
            world.setBlock(x, y + 3, z - 1, BOPCBlocks.driedDirt);
            world.setBlock(x, y + 3, z + 1, BOPCBlocks.driedDirt);
            world.setBlock(x - 1, y + 3, z - 1, BOPCBlocks.driedDirt);
            world.setBlock(x + 1, y + 3, z + 1, BOPCBlocks.driedDirt);
            world.setBlock(x - 1, y + 3, z + 1, BOPCBlocks.driedDirt);
            world.setBlock(x + 1, y + 3, z - 1, BOPCBlocks.driedDirt);

            world.setBlock(x, y + 3, z, BOPCBlocks.driedDirt);

            world.setBlock(x - 1, y + 4, z, BOPCBlocks.driedDirt);
            world.setBlock(x + 1, y + 4, z, BOPCBlocks.driedDirt);
            world.setBlock(x, y + 4, z - 1, BOPCBlocks.driedDirt);
            world.setBlock(x, y + 4, z + 1, BOPCBlocks.driedDirt);

            world.setBlock(x, y + 4, z, BOPCBlocks.driedDirt);

            world.setBlock(x - 1, y + 5, z, BOPCBlocks.driedDirt);
            world.setBlock(x + 1, y + 5, z, BOPCBlocks.driedDirt);
            world.setBlock(x, y + 5, z - 1, BOPCBlocks.driedDirt);
            world.setBlock(x, y + 5, z + 1, BOPCBlocks.driedDirt);

            world.setBlock(x, y + 5, z, BOPCBlocks.driedDirt);
            world.setBlock(x, y + 6, z, BOPCBlocks.driedDirt);
            world.setBlock(x, y + 7, z, BOPCBlocks.driedDirt);
            world.setBlock(x, y + 8, z, BOPCBlocks.driedDirt);

            return true;
        }
    }

    @Override
    public void setupGeneration(World world, Random random, BiomeGenBase biome, String featureName, int x, int z)
    {
        for (int i = 0; i < (Integer)BOPDecorationManager.getBiomeFeatures(biome.biomeID).getFeature(featureName); i++)
        {
            int randX = x + random.nextInt(16) + 8;
            int randZ = z + random.nextInt(16) + 8;
            int randY = random.nextInt(world.getHeightValue(randX, randZ) * 2);

            this.generate(world, random, randX, randY, randZ);
        }
    }
}
